var reporting_data = {"lemoncheesecake_version": "1.3.1", "report_version": 1.1, "start_time": "2020-03-14T16:30:06.632Z", "end_time": "2020-03-14T16:30:07.890Z", "generation_time": "2020-03-14T16:30:07.929Z", "nb_threads": 1, "title": "Test Report", "info": [["Command line", "lcc run"]], "suites": [{"start_time": "2020-03-14T16:30:06.635Z", "end_time": "2020-03-14T16:30:06.844Z", "tests": [{"start_time": "2020-03-14T16:30:06.635Z", "end_time": "2020-03-14T16:30:06.636Z", "steps": [{"description": "test1", "start_time": "2020-03-14T16:30:06.635Z", "end_time": "2020-03-14T16:30:06.636Z", "entries": [{"type": "check", "description": "Expect value to be equal to 4.0", "is_successful": true, "details": "Got 4", "time": "2020-03-14T16:30:06.636Z"}]}], "status": "passed", "status_details": null, "name": "test1", "description": "test1", "tags": [], "properties": {}, "links": []}, {"start_time": "2020-03-14T16:30:06.636Z", "end_time": "2020-03-14T16:30:06.636Z", "steps": [], "status": "passed", "status_details": null, "name": "test2", "description": "test2", "tags": [], "properties": {}, "links": []}, {"start_time": "2020-03-14T16:30:06.636Z", "end_time": "2020-03-14T16:30:06.841Z", "steps": [{"description": "test3", "start_time": "2020-03-14T16:30:06.636Z", "end_time": "2020-03-14T16:30:06.841Z", "entries": [{"type": "check", "description": "Expect http code to be equal to 200", "is_successful": true, "details": "Got 200", "time": "2020-03-14T16:30:06.836Z"}, {"type": "log", "level": "error", "message": "Caught unexpected exception while running test: Traceback (most recent call last):\n  File \"c:\\users\\atpc8\\appdata\\local\\programs\\python\\python37\\lib\\site-packages\\lemoncheesecake\\runner.py\", line 188, in run\n    self.test.callback(**test_func_params)\n  File \"C:\\Users\\atpc8\\sdlc\\lemontest\\suites\\firstsuite.py\", line 23, in test3\n    resp = r.json()\n  File \"c:\\users\\atpc8\\appdata\\local\\programs\\python\\python37\\lib\\site-packages\\requests\\models.py\", line 897, in json\n    return complexjson.loads(self.text, **kwargs)\n  File \"c:\\users\\atpc8\\appdata\\local\\programs\\python\\python37\\lib\\json\\__init__.py\", line 348, in loads\n    return _default_decoder.decode(s)\n  File \"c:\\users\\atpc8\\appdata\\local\\programs\\python\\python37\\lib\\json\\decoder.py\", line 337, in decode\n    obj, end = self.raw_decode(s, idx=_w(s, 0).end())\n  File \"c:\\users\\atpc8\\appdata\\local\\programs\\python\\python37\\lib\\json\\decoder.py\", line 355, in raw_decode\n    raise JSONDecodeError(\"Expecting value\", s, err.value) from None\njson.decoder.JSONDecodeError: Expecting value: line 1 column 1 (char 0)\n", "time": "2020-03-14T16:30:06.841Z"}]}], "status": "failed", "status_details": null, "name": "test3", "description": "test3", "tags": [], "properties": {}, "links": []}], "suites": [], "name": "firstsuite", "description": "my_suite", "tags": ["samples", "tutorials"], "properties": {}, "links": []}, {"start_time": "2020-03-14T16:30:06.844Z", "end_time": "2020-03-14T16:30:07.481Z", "tests": [{"start_time": "2020-03-14T16:30:06.845Z", "end_time": "2020-03-14T16:30:07.096Z", "steps": [{"description": "req1", "start_time": "2020-03-14T16:30:06.845Z", "end_time": "2020-03-14T16:30:07.096Z", "entries": [{"type": "url", "description": "This is first shoot in this suite!!!", "url": "http://api.dev.compareking.no/api/application/111", "time": "2020-03-14T16:30:06.845Z"}, {"type": "log", "level": "error", "message": "Caught unexpected exception while running test: Traceback (most recent call last):\n  File \"c:\\users\\atpc8\\appdata\\local\\programs\\python\\python37\\lib\\site-packages\\urllib3\\connection.py\", line 157, in _new_conn\n    (self._dns_host, self.port), self.timeout, **extra_kw\n  File \"c:\\users\\atpc8\\appdata\\local\\programs\\python\\python37\\lib\\site-packages\\urllib3\\util\\connection.py\", line 61, in create_connection\n    for res in socket.getaddrinfo(host, port, family, socket.SOCK_STREAM):\n  File \"c:\\users\\atpc8\\appdata\\local\\programs\\python\\python37\\lib\\socket.py\", line 748, in getaddrinfo\n    for res in _socket.getaddrinfo(host, port, family, type, proto, flags):\nsocket.gaierror: [Errno 11001] getaddrinfo failed\n\nDuring handling of the above exception, another exception occurred:\n\nTraceback (most recent call last):\n  File \"c:\\users\\atpc8\\appdata\\local\\programs\\python\\python37\\lib\\site-packages\\urllib3\\connectionpool.py\", line 672, in urlopen\n    chunked=chunked,\n  File \"c:\\users\\atpc8\\appdata\\local\\programs\\python\\python37\\lib\\site-packages\\urllib3\\connectionpool.py\", line 387, in _make_request\n    conn.request(method, url, **httplib_request_kw)\n  File \"c:\\users\\atpc8\\appdata\\local\\programs\\python\\python37\\lib\\http\\client.py\", line 1229, in request\n    self._send_request(method, url, body, headers, encode_chunked)\n  File \"c:\\users\\atpc8\\appdata\\local\\programs\\python\\python37\\lib\\http\\client.py\", line 1275, in _send_request\n    self.endheaders(body, encode_chunked=encode_chunked)\n  File \"c:\\users\\atpc8\\appdata\\local\\programs\\python\\python37\\lib\\http\\client.py\", line 1224, in endheaders\n    self._send_output(message_body, encode_chunked=encode_chunked)\n  File \"c:\\users\\atpc8\\appdata\\local\\programs\\python\\python37\\lib\\http\\client.py\", line 1016, in _send_output\n    self.send(msg)\n  File \"c:\\users\\atpc8\\appdata\\local\\programs\\python\\python37\\lib\\http\\client.py\", line 956, in send\n    self.connect()\n  File \"c:\\users\\atpc8\\appdata\\local\\programs\\python\\python37\\lib\\site-packages\\urllib3\\connection.py\", line 184, in connect\n    conn = self._new_conn()\n  File \"c:\\users\\atpc8\\appdata\\local\\programs\\python\\python37\\lib\\site-packages\\urllib3\\connection.py\", line 169, in _new_conn\n    self, \"Failed to establish a new connection: %s\" % e\nurllib3.exceptions.NewConnectionError: <urllib3.connection.HTTPConnection object at 0x000001FC4D2143C8>: Failed to establish a new connection: [Errno 11001] getaddrinfo failed\n\nDuring handling of the above exception, another exception occurred:\n\nTraceback (most recent call last):\n  File \"c:\\users\\atpc8\\appdata\\local\\programs\\python\\python37\\lib\\site-packages\\requests\\adapters.py\", line 449, in send\n    timeout=timeout\n  File \"c:\\users\\atpc8\\appdata\\local\\programs\\python\\python37\\lib\\site-packages\\urllib3\\connectionpool.py\", line 720, in urlopen\n    method, url, error=e, _pool=self, _stacktrace=sys.exc_info()[2]\n  File \"c:\\users\\atpc8\\appdata\\local\\programs\\python\\python37\\lib\\site-packages\\urllib3\\util\\retry.py\", line 436, in increment\n    raise MaxRetryError(_pool, url, error or ResponseError(cause))\nurllib3.exceptions.MaxRetryError: HTTPConnectionPool(host='api.dev.compareking.no', port=80): Max retries exceeded with url: /api/application/111 (Caused by NewConnectionError('<urllib3.connection.HTTPConnection object at 0x000001FC4D2143C8>: Failed to establish a new connection: [Errno 11001] getaddrinfo failed'))\n\nDuring handling of the above exception, another exception occurred:\n\nTraceback (most recent call last):\n  File \"c:\\users\\atpc8\\appdata\\local\\programs\\python\\python37\\lib\\site-packages\\lemoncheesecake\\runner.py\", line 188, in run\n    self.test.callback(**test_func_params)\n  File \"C:\\Users\\atpc8\\sdlc\\lemontest\\suites\\secondsuite.py\", line 17, in req1\n    headers=authenticate)\n  File \"c:\\users\\atpc8\\appdata\\local\\programs\\python\\python37\\lib\\site-packages\\requests\\api.py\", line 75, in get\n    return request('get', url, params=params, **kwargs)\n  File \"c:\\users\\atpc8\\appdata\\local\\programs\\python\\python37\\lib\\site-packages\\requests\\api.py\", line 60, in request\n    return session.request(method=method, url=url, **kwargs)\n  File \"c:\\users\\atpc8\\appdata\\local\\programs\\python\\python37\\lib\\site-packages\\requests\\sessions.py\", line 533, in request\n    resp = self.send(prep, **send_kwargs)\n  File \"c:\\users\\atpc8\\appdata\\local\\programs\\python\\python37\\lib\\site-packages\\requests\\sessions.py\", line 646, in send\n    r = adapter.send(request, **kwargs)\n  File \"c:\\users\\atpc8\\appdata\\local\\programs\\python\\python37\\lib\\site-packages\\requests\\adapters.py\", line 516, in send\n    raise ConnectionError(e, request=request)\nrequests.exceptions.ConnectionError: HTTPConnectionPool(host='api.dev.compareking.no', port=80): Max retries exceeded with url: /api/application/111 (Caused by NewConnectionError('<urllib3.connection.HTTPConnection object at 0x000001FC4D2143C8>: Failed to establish a new connection: [Errno 11001] getaddrinfo failed'))\n", "time": "2020-03-14T16:30:07.096Z"}]}], "status": "failed", "status_details": null, "name": "req1", "description": "req1", "tags": [], "properties": {}, "links": []}, {"start_time": "2020-03-14T16:30:07.105Z", "end_time": "2020-03-14T16:30:07.115Z", "steps": [{"description": "req2", "start_time": "2020-03-14T16:30:07.106Z", "end_time": "2020-03-14T16:30:07.115Z", "entries": [{"type": "log", "level": "error", "message": "Caught unexpected exception while running test: Traceback (most recent call last):\n  File \"c:\\users\\atpc8\\appdata\\local\\programs\\python\\python37\\lib\\site-packages\\urllib3\\connection.py\", line 157, in _new_conn\n    (self._dns_host, self.port), self.timeout, **extra_kw\n  File \"c:\\users\\atpc8\\appdata\\local\\programs\\python\\python37\\lib\\site-packages\\urllib3\\util\\connection.py\", line 61, in create_connection\n    for res in socket.getaddrinfo(host, port, family, socket.SOCK_STREAM):\n  File \"c:\\users\\atpc8\\appdata\\local\\programs\\python\\python37\\lib\\socket.py\", line 748, in getaddrinfo\n    for res in _socket.getaddrinfo(host, port, family, type, proto, flags):\nsocket.gaierror: [Errno 11001] getaddrinfo failed\n\nDuring handling of the above exception, another exception occurred:\n\nTraceback (most recent call last):\n  File \"c:\\users\\atpc8\\appdata\\local\\programs\\python\\python37\\lib\\site-packages\\urllib3\\connectionpool.py\", line 672, in urlopen\n    chunked=chunked,\n  File \"c:\\users\\atpc8\\appdata\\local\\programs\\python\\python37\\lib\\site-packages\\urllib3\\connectionpool.py\", line 387, in _make_request\n    conn.request(method, url, **httplib_request_kw)\n  File \"c:\\users\\atpc8\\appdata\\local\\programs\\python\\python37\\lib\\http\\client.py\", line 1229, in request\n    self._send_request(method, url, body, headers, encode_chunked)\n  File \"c:\\users\\atpc8\\appdata\\local\\programs\\python\\python37\\lib\\http\\client.py\", line 1275, in _send_request\n    self.endheaders(body, encode_chunked=encode_chunked)\n  File \"c:\\users\\atpc8\\appdata\\local\\programs\\python\\python37\\lib\\http\\client.py\", line 1224, in endheaders\n    self._send_output(message_body, encode_chunked=encode_chunked)\n  File \"c:\\users\\atpc8\\appdata\\local\\programs\\python\\python37\\lib\\http\\client.py\", line 1016, in _send_output\n    self.send(msg)\n  File \"c:\\users\\atpc8\\appdata\\local\\programs\\python\\python37\\lib\\http\\client.py\", line 956, in send\n    self.connect()\n  File \"c:\\users\\atpc8\\appdata\\local\\programs\\python\\python37\\lib\\site-packages\\urllib3\\connection.py\", line 184, in connect\n    conn = self._new_conn()\n  File \"c:\\users\\atpc8\\appdata\\local\\programs\\python\\python37\\lib\\site-packages\\urllib3\\connection.py\", line 169, in _new_conn\n    self, \"Failed to establish a new connection: %s\" % e\nurllib3.exceptions.NewConnectionError: <urllib3.connection.HTTPConnection object at 0x000001FC4D2846D8>: Failed to establish a new connection: [Errno 11001] getaddrinfo failed\n\nDuring handling of the above exception, another exception occurred:\n\nTraceback (most recent call last):\n  File \"c:\\users\\atpc8\\appdata\\local\\programs\\python\\python37\\lib\\site-packages\\requests\\adapters.py\", line 449, in send\n    timeout=timeout\n  File \"c:\\users\\atpc8\\appdata\\local\\programs\\python\\python37\\lib\\site-packages\\urllib3\\connectionpool.py\", line 720, in urlopen\n    method, url, error=e, _pool=self, _stacktrace=sys.exc_info()[2]\n  File \"c:\\users\\atpc8\\appdata\\local\\programs\\python\\python37\\lib\\site-packages\\urllib3\\util\\retry.py\", line 436, in increment\n    raise MaxRetryError(_pool, url, error or ResponseError(cause))\nurllib3.exceptions.MaxRetryError: HTTPConnectionPool(host='api.dev.compareking.no', port=80): Max retries exceeded with url: /api/application (Caused by NewConnectionError('<urllib3.connection.HTTPConnection object at 0x000001FC4D2846D8>: Failed to establish a new connection: [Errno 11001] getaddrinfo failed'))\n\nDuring handling of the above exception, another exception occurred:\n\nTraceback (most recent call last):\n  File \"c:\\users\\atpc8\\appdata\\local\\programs\\python\\python37\\lib\\site-packages\\lemoncheesecake\\runner.py\", line 188, in run\n    self.test.callback(**test_func_params)\n  File \"C:\\Users\\atpc8\\sdlc\\lemontest\\suites\\secondsuite.py\", line 25, in req2\n    headers=authenticate, data=throughput)\n  File \"c:\\users\\atpc8\\appdata\\local\\programs\\python\\python37\\lib\\site-packages\\requests\\api.py\", line 116, in post\n    return request('post', url, data=data, json=json, **kwargs)\n  File \"c:\\users\\atpc8\\appdata\\local\\programs\\python\\python37\\lib\\site-packages\\requests\\api.py\", line 60, in request\n    return session.request(method=method, url=url, **kwargs)\n  File \"c:\\users\\atpc8\\appdata\\local\\programs\\python\\python37\\lib\\site-packages\\requests\\sessions.py\", line 533, in request\n    resp = self.send(prep, **send_kwargs)\n  File \"c:\\users\\atpc8\\appdata\\local\\programs\\python\\python37\\lib\\site-packages\\requests\\sessions.py\", line 646, in send\n    r = adapter.send(request, **kwargs)\n  File \"c:\\users\\atpc8\\appdata\\local\\programs\\python\\python37\\lib\\site-packages\\requests\\adapters.py\", line 516, in send\n    raise ConnectionError(e, request=request)\nrequests.exceptions.ConnectionError: HTTPConnectionPool(host='api.dev.compareking.no', port=80): Max retries exceeded with url: /api/application (Caused by NewConnectionError('<urllib3.connection.HTTPConnection object at 0x000001FC4D2846D8>: Failed to establish a new connection: [Errno 11001] getaddrinfo failed'))\n", "time": "2020-03-14T16:30:07.114Z"}]}], "status": "failed", "status_details": null, "name": "req2", "description": "req2", "tags": [], "properties": {}, "links": []}, {"start_time": "2020-03-14T16:30:07.115Z", "end_time": "2020-03-14T16:30:07.129Z", "steps": [{"description": "req3", "start_time": "2020-03-14T16:30:07.116Z", "end_time": "2020-03-14T16:30:07.129Z", "entries": [{"type": "log", "level": "error", "message": "Caught unexpected exception while running test: Traceback (most recent call last):\n  File \"c:\\users\\atpc8\\appdata\\local\\programs\\python\\python37\\lib\\site-packages\\urllib3\\connection.py\", line 157, in _new_conn\n    (self._dns_host, self.port), self.timeout, **extra_kw\n  File \"c:\\users\\atpc8\\appdata\\local\\programs\\python\\python37\\lib\\site-packages\\urllib3\\util\\connection.py\", line 61, in create_connection\n    for res in socket.getaddrinfo(host, port, family, socket.SOCK_STREAM):\n  File \"c:\\users\\atpc8\\appdata\\local\\programs\\python\\python37\\lib\\socket.py\", line 748, in getaddrinfo\n    for res in _socket.getaddrinfo(host, port, family, type, proto, flags):\nsocket.gaierror: [Errno 11001] getaddrinfo failed\n\nDuring handling of the above exception, another exception occurred:\n\nTraceback (most recent call last):\n  File \"c:\\users\\atpc8\\appdata\\local\\programs\\python\\python37\\lib\\site-packages\\urllib3\\connectionpool.py\", line 672, in urlopen\n    chunked=chunked,\n  File \"c:\\users\\atpc8\\appdata\\local\\programs\\python\\python37\\lib\\site-packages\\urllib3\\connectionpool.py\", line 387, in _make_request\n    conn.request(method, url, **httplib_request_kw)\n  File \"c:\\users\\atpc8\\appdata\\local\\programs\\python\\python37\\lib\\http\\client.py\", line 1229, in request\n    self._send_request(method, url, body, headers, encode_chunked)\n  File \"c:\\users\\atpc8\\appdata\\local\\programs\\python\\python37\\lib\\http\\client.py\", line 1275, in _send_request\n    self.endheaders(body, encode_chunked=encode_chunked)\n  File \"c:\\users\\atpc8\\appdata\\local\\programs\\python\\python37\\lib\\http\\client.py\", line 1224, in endheaders\n    self._send_output(message_body, encode_chunked=encode_chunked)\n  File \"c:\\users\\atpc8\\appdata\\local\\programs\\python\\python37\\lib\\http\\client.py\", line 1016, in _send_output\n    self.send(msg)\n  File \"c:\\users\\atpc8\\appdata\\local\\programs\\python\\python37\\lib\\http\\client.py\", line 956, in send\n    self.connect()\n  File \"c:\\users\\atpc8\\appdata\\local\\programs\\python\\python37\\lib\\site-packages\\urllib3\\connection.py\", line 184, in connect\n    conn = self._new_conn()\n  File \"c:\\users\\atpc8\\appdata\\local\\programs\\python\\python37\\lib\\site-packages\\urllib3\\connection.py\", line 169, in _new_conn\n    self, \"Failed to establish a new connection: %s\" % e\nurllib3.exceptions.NewConnectionError: <urllib3.connection.HTTPConnection object at 0x000001FC4D2849E8>: Failed to establish a new connection: [Errno 11001] getaddrinfo failed\n\nDuring handling of the above exception, another exception occurred:\n\nTraceback (most recent call last):\n  File \"c:\\users\\atpc8\\appdata\\local\\programs\\python\\python37\\lib\\site-packages\\requests\\adapters.py\", line 449, in send\n    timeout=timeout\n  File \"c:\\users\\atpc8\\appdata\\local\\programs\\python\\python37\\lib\\site-packages\\urllib3\\connectionpool.py\", line 720, in urlopen\n    method, url, error=e, _pool=self, _stacktrace=sys.exc_info()[2]\n  File \"c:\\users\\atpc8\\appdata\\local\\programs\\python\\python37\\lib\\site-packages\\urllib3\\util\\retry.py\", line 436, in increment\n    raise MaxRetryError(_pool, url, error or ResponseError(cause))\nurllib3.exceptions.MaxRetryError: HTTPConnectionPool(host='api.dev.compareking.no', port=80): Max retries exceeded with url: /api/application (Caused by NewConnectionError('<urllib3.connection.HTTPConnection object at 0x000001FC4D2849E8>: Failed to establish a new connection: [Errno 11001] getaddrinfo failed'))\n\nDuring handling of the above exception, another exception occurred:\n\nTraceback (most recent call last):\n  File \"c:\\users\\atpc8\\appdata\\local\\programs\\python\\python37\\lib\\site-packages\\lemoncheesecake\\runner.py\", line 188, in run\n    self.test.callback(**test_func_params)\n  File \"C:\\Users\\atpc8\\sdlc\\lemontest\\suites\\secondsuite.py\", line 33, in req3\n    headers=authenticate, data=throughput)\n  File \"c:\\users\\atpc8\\appdata\\local\\programs\\python\\python37\\lib\\site-packages\\requests\\api.py\", line 116, in post\n    return request('post', url, data=data, json=json, **kwargs)\n  File \"c:\\users\\atpc8\\appdata\\local\\programs\\python\\python37\\lib\\site-packages\\requests\\api.py\", line 60, in request\n    return session.request(method=method, url=url, **kwargs)\n  File \"c:\\users\\atpc8\\appdata\\local\\programs\\python\\python37\\lib\\site-packages\\requests\\sessions.py\", line 533, in request\n    resp = self.send(prep, **send_kwargs)\n  File \"c:\\users\\atpc8\\appdata\\local\\programs\\python\\python37\\lib\\site-packages\\requests\\sessions.py\", line 646, in send\n    r = adapter.send(request, **kwargs)\n  File \"c:\\users\\atpc8\\appdata\\local\\programs\\python\\python37\\lib\\site-packages\\requests\\adapters.py\", line 516, in send\n    raise ConnectionError(e, request=request)\nrequests.exceptions.ConnectionError: HTTPConnectionPool(host='api.dev.compareking.no', port=80): Max retries exceeded with url: /api/application (Caused by NewConnectionError('<urllib3.connection.HTTPConnection object at 0x000001FC4D2849E8>: Failed to establish a new connection: [Errno 11001] getaddrinfo failed'))\n", "time": "2020-03-14T16:30:07.129Z"}]}], "status": "failed", "status_details": null, "name": "req3", "description": "req3", "tags": [], "properties": {}, "links": []}, {"start_time": "2020-03-14T16:30:07.131Z", "end_time": "2020-03-14T16:30:07.140Z", "steps": [{"description": "req4", "start_time": "2020-03-14T16:30:07.131Z", "end_time": "2020-03-14T16:30:07.140Z", "entries": [{"type": "log", "level": "error", "message": "Caught unexpected exception while running test: Traceback (most recent call last):\n  File \"c:\\users\\atpc8\\appdata\\local\\programs\\python\\python37\\lib\\site-packages\\urllib3\\connection.py\", line 157, in _new_conn\n    (self._dns_host, self.port), self.timeout, **extra_kw\n  File \"c:\\users\\atpc8\\appdata\\local\\programs\\python\\python37\\lib\\site-packages\\urllib3\\util\\connection.py\", line 61, in create_connection\n    for res in socket.getaddrinfo(host, port, family, socket.SOCK_STREAM):\n  File \"c:\\users\\atpc8\\appdata\\local\\programs\\python\\python37\\lib\\socket.py\", line 748, in getaddrinfo\n    for res in _socket.getaddrinfo(host, port, family, type, proto, flags):\nsocket.gaierror: [Errno 11001] getaddrinfo failed\n\nDuring handling of the above exception, another exception occurred:\n\nTraceback (most recent call last):\n  File \"c:\\users\\atpc8\\appdata\\local\\programs\\python\\python37\\lib\\site-packages\\urllib3\\connectionpool.py\", line 672, in urlopen\n    chunked=chunked,\n  File \"c:\\users\\atpc8\\appdata\\local\\programs\\python\\python37\\lib\\site-packages\\urllib3\\connectionpool.py\", line 387, in _make_request\n    conn.request(method, url, **httplib_request_kw)\n  File \"c:\\users\\atpc8\\appdata\\local\\programs\\python\\python37\\lib\\http\\client.py\", line 1229, in request\n    self._send_request(method, url, body, headers, encode_chunked)\n  File \"c:\\users\\atpc8\\appdata\\local\\programs\\python\\python37\\lib\\http\\client.py\", line 1275, in _send_request\n    self.endheaders(body, encode_chunked=encode_chunked)\n  File \"c:\\users\\atpc8\\appdata\\local\\programs\\python\\python37\\lib\\http\\client.py\", line 1224, in endheaders\n    self._send_output(message_body, encode_chunked=encode_chunked)\n  File \"c:\\users\\atpc8\\appdata\\local\\programs\\python\\python37\\lib\\http\\client.py\", line 1016, in _send_output\n    self.send(msg)\n  File \"c:\\users\\atpc8\\appdata\\local\\programs\\python\\python37\\lib\\http\\client.py\", line 956, in send\n    self.connect()\n  File \"c:\\users\\atpc8\\appdata\\local\\programs\\python\\python37\\lib\\site-packages\\urllib3\\connection.py\", line 184, in connect\n    conn = self._new_conn()\n  File \"c:\\users\\atpc8\\appdata\\local\\programs\\python\\python37\\lib\\site-packages\\urllib3\\connection.py\", line 169, in _new_conn\n    self, \"Failed to establish a new connection: %s\" % e\nurllib3.exceptions.NewConnectionError: <urllib3.connection.HTTPConnection object at 0x000001FC4D284BE0>: Failed to establish a new connection: [Errno 11001] getaddrinfo failed\n\nDuring handling of the above exception, another exception occurred:\n\nTraceback (most recent call last):\n  File \"c:\\users\\atpc8\\appdata\\local\\programs\\python\\python37\\lib\\site-packages\\requests\\adapters.py\", line 449, in send\n    timeout=timeout\n  File \"c:\\users\\atpc8\\appdata\\local\\programs\\python\\python37\\lib\\site-packages\\urllib3\\connectionpool.py\", line 720, in urlopen\n    method, url, error=e, _pool=self, _stacktrace=sys.exc_info()[2]\n  File \"c:\\users\\atpc8\\appdata\\local\\programs\\python\\python37\\lib\\site-packages\\urllib3\\util\\retry.py\", line 436, in increment\n    raise MaxRetryError(_pool, url, error or ResponseError(cause))\nurllib3.exceptions.MaxRetryError: HTTPConnectionPool(host='api.dev.compareking.no', port=80): Max retries exceeded with url: /api/application (Caused by NewConnectionError('<urllib3.connection.HTTPConnection object at 0x000001FC4D284BE0>: Failed to establish a new connection: [Errno 11001] getaddrinfo failed'))\n\nDuring handling of the above exception, another exception occurred:\n\nTraceback (most recent call last):\n  File \"c:\\users\\atpc8\\appdata\\local\\programs\\python\\python37\\lib\\site-packages\\lemoncheesecake\\runner.py\", line 188, in run\n    self.test.callback(**test_func_params)\n  File \"C:\\Users\\atpc8\\sdlc\\lemontest\\suites\\secondsuite.py\", line 80, in req4\n    headers=authenticate, data=payload)\n  File \"c:\\users\\atpc8\\appdata\\local\\programs\\python\\python37\\lib\\site-packages\\requests\\api.py\", line 116, in post\n    return request('post', url, data=data, json=json, **kwargs)\n  File \"c:\\users\\atpc8\\appdata\\local\\programs\\python\\python37\\lib\\site-packages\\requests\\api.py\", line 60, in request\n    return session.request(method=method, url=url, **kwargs)\n  File \"c:\\users\\atpc8\\appdata\\local\\programs\\python\\python37\\lib\\site-packages\\requests\\sessions.py\", line 533, in request\n    resp = self.send(prep, **send_kwargs)\n  File \"c:\\users\\atpc8\\appdata\\local\\programs\\python\\python37\\lib\\site-packages\\requests\\sessions.py\", line 646, in send\n    r = adapter.send(request, **kwargs)\n  File \"c:\\users\\atpc8\\appdata\\local\\programs\\python\\python37\\lib\\site-packages\\requests\\adapters.py\", line 516, in send\n    raise ConnectionError(e, request=request)\nrequests.exceptions.ConnectionError: HTTPConnectionPool(host='api.dev.compareking.no', port=80): Max retries exceeded with url: /api/application (Caused by NewConnectionError('<urllib3.connection.HTTPConnection object at 0x000001FC4D284BE0>: Failed to establish a new connection: [Errno 11001] getaddrinfo failed'))\n", "time": "2020-03-14T16:30:07.139Z"}]}], "status": "failed", "status_details": null, "name": "req4", "description": "req4", "tags": [], "properties": {}, "links": []}, {"start_time": "2020-03-14T16:30:07.140Z", "end_time": "2020-03-14T16:30:07.150Z", "steps": [{"description": "req5", "start_time": "2020-03-14T16:30:07.141Z", "end_time": "2020-03-14T16:30:07.150Z", "entries": [{"type": "log", "level": "error", "message": "Caught unexpected exception while running test: Traceback (most recent call last):\n  File \"c:\\users\\atpc8\\appdata\\local\\programs\\python\\python37\\lib\\site-packages\\urllib3\\connection.py\", line 157, in _new_conn\n    (self._dns_host, self.port), self.timeout, **extra_kw\n  File \"c:\\users\\atpc8\\appdata\\local\\programs\\python\\python37\\lib\\site-packages\\urllib3\\util\\connection.py\", line 61, in create_connection\n    for res in socket.getaddrinfo(host, port, family, socket.SOCK_STREAM):\n  File \"c:\\users\\atpc8\\appdata\\local\\programs\\python\\python37\\lib\\socket.py\", line 748, in getaddrinfo\n    for res in _socket.getaddrinfo(host, port, family, type, proto, flags):\nsocket.gaierror: [Errno 11001] getaddrinfo failed\n\nDuring handling of the above exception, another exception occurred:\n\nTraceback (most recent call last):\n  File \"c:\\users\\atpc8\\appdata\\local\\programs\\python\\python37\\lib\\site-packages\\urllib3\\connectionpool.py\", line 672, in urlopen\n    chunked=chunked,\n  File \"c:\\users\\atpc8\\appdata\\local\\programs\\python\\python37\\lib\\site-packages\\urllib3\\connectionpool.py\", line 387, in _make_request\n    conn.request(method, url, **httplib_request_kw)\n  File \"c:\\users\\atpc8\\appdata\\local\\programs\\python\\python37\\lib\\http\\client.py\", line 1229, in request\n    self._send_request(method, url, body, headers, encode_chunked)\n  File \"c:\\users\\atpc8\\appdata\\local\\programs\\python\\python37\\lib\\http\\client.py\", line 1275, in _send_request\n    self.endheaders(body, encode_chunked=encode_chunked)\n  File \"c:\\users\\atpc8\\appdata\\local\\programs\\python\\python37\\lib\\http\\client.py\", line 1224, in endheaders\n    self._send_output(message_body, encode_chunked=encode_chunked)\n  File \"c:\\users\\atpc8\\appdata\\local\\programs\\python\\python37\\lib\\http\\client.py\", line 1016, in _send_output\n    self.send(msg)\n  File \"c:\\users\\atpc8\\appdata\\local\\programs\\python\\python37\\lib\\http\\client.py\", line 956, in send\n    self.connect()\n  File \"c:\\users\\atpc8\\appdata\\local\\programs\\python\\python37\\lib\\site-packages\\urllib3\\connection.py\", line 184, in connect\n    conn = self._new_conn()\n  File \"c:\\users\\atpc8\\appdata\\local\\programs\\python\\python37\\lib\\site-packages\\urllib3\\connection.py\", line 169, in _new_conn\n    self, \"Failed to establish a new connection: %s\" % e\nurllib3.exceptions.NewConnectionError: <urllib3.connection.HTTPConnection object at 0x000001FC4D284EB8>: Failed to establish a new connection: [Errno 11001] getaddrinfo failed\n\nDuring handling of the above exception, another exception occurred:\n\nTraceback (most recent call last):\n  File \"c:\\users\\atpc8\\appdata\\local\\programs\\python\\python37\\lib\\site-packages\\requests\\adapters.py\", line 449, in send\n    timeout=timeout\n  File \"c:\\users\\atpc8\\appdata\\local\\programs\\python\\python37\\lib\\site-packages\\urllib3\\connectionpool.py\", line 720, in urlopen\n    method, url, error=e, _pool=self, _stacktrace=sys.exc_info()[2]\n  File \"c:\\users\\atpc8\\appdata\\local\\programs\\python\\python37\\lib\\site-packages\\urllib3\\util\\retry.py\", line 436, in increment\n    raise MaxRetryError(_pool, url, error or ResponseError(cause))\nurllib3.exceptions.MaxRetryError: HTTPConnectionPool(host='api.dev.compareking.no', port=80): Max retries exceeded with url: /api/application (Caused by NewConnectionError('<urllib3.connection.HTTPConnection object at 0x000001FC4D284EB8>: Failed to establish a new connection: [Errno 11001] getaddrinfo failed'))\n\nDuring handling of the above exception, another exception occurred:\n\nTraceback (most recent call last):\n  File \"c:\\users\\atpc8\\appdata\\local\\programs\\python\\python37\\lib\\site-packages\\lemoncheesecake\\runner.py\", line 188, in run\n    self.test.callback(**test_func_params)\n  File \"C:\\Users\\atpc8\\sdlc\\lemontest\\suites\\secondsuite.py\", line 142, in req5\n    headers=authenticate, data=payload)\n  File \"c:\\users\\atpc8\\appdata\\local\\programs\\python\\python37\\lib\\site-packages\\requests\\api.py\", line 116, in post\n    return request('post', url, data=data, json=json, **kwargs)\n  File \"c:\\users\\atpc8\\appdata\\local\\programs\\python\\python37\\lib\\site-packages\\requests\\api.py\", line 60, in request\n    return session.request(method=method, url=url, **kwargs)\n  File \"c:\\users\\atpc8\\appdata\\local\\programs\\python\\python37\\lib\\site-packages\\requests\\sessions.py\", line 533, in request\n    resp = self.send(prep, **send_kwargs)\n  File \"c:\\users\\atpc8\\appdata\\local\\programs\\python\\python37\\lib\\site-packages\\requests\\sessions.py\", line 646, in send\n    r = adapter.send(request, **kwargs)\n  File \"c:\\users\\atpc8\\appdata\\local\\programs\\python\\python37\\lib\\site-packages\\requests\\adapters.py\", line 516, in send\n    raise ConnectionError(e, request=request)\nrequests.exceptions.ConnectionError: HTTPConnectionPool(host='api.dev.compareking.no', port=80): Max retries exceeded with url: /api/application (Caused by NewConnectionError('<urllib3.connection.HTTPConnection object at 0x000001FC4D284EB8>: Failed to establish a new connection: [Errno 11001] getaddrinfo failed'))\n", "time": "2020-03-14T16:30:07.150Z"}]}], "status": "failed", "status_details": null, "name": "req5", "description": "req5", "tags": [], "properties": {}, "links": []}, {"start_time": "2020-03-14T16:30:07.154Z", "end_time": "2020-03-14T16:30:07.480Z", "steps": [{"description": "glc_auth_test", "start_time": "2020-03-14T16:30:07.155Z", "end_time": "2020-03-14T16:30:07.480Z", "entries": [{"type": "check", "description": "Expect http code to be equal to 200", "is_successful": false, "details": "Got 401", "time": "2020-03-14T16:30:07.473Z"}, {"type": "log", "level": "info", "message": "Response\n{\n    \"timestamp\": \"2020-03-14 17:22:20\",\n    \"status\": 401,\n    \"error\": \"Unauthorized\",\n    \"message\": \"Unauthorized\",\n    \"path\": \"/api\"\n}", "time": "2020-03-14T16:30:07.479Z"}]}], "status": "failed", "status_details": null, "name": "glc_auth_test", "description": "glc_auth_test", "tags": ["glc"], "properties": {}, "links": []}], "suites": [], "name": "secondsuite", "description": "sec_suite", "tags": ["validation", "white labels"], "properties": {}, "links": []}, {"start_time": "2020-03-14T16:30:07.482Z", "end_time": "2020-03-14T16:30:07.527Z", "tests": [{"start_time": "2020-03-14T16:30:07.482Z", "end_time": "2020-03-14T16:30:07.490Z", "steps": [{"description": "Submit existing application or sent less than 3 months ago", "start_time": "2020-03-14T16:30:07.483Z", "end_time": "2020-03-14T16:30:07.490Z", "entries": [{"type": "log", "level": "error", "message": "Caught unexpected exception while running test: Traceback (most recent call last):\n  File \"c:\\users\\atpc8\\appdata\\local\\programs\\python\\python37\\lib\\site-packages\\urllib3\\connection.py\", line 157, in _new_conn\n    (self._dns_host, self.port), self.timeout, **extra_kw\n  File \"c:\\users\\atpc8\\appdata\\local\\programs\\python\\python37\\lib\\site-packages\\urllib3\\util\\connection.py\", line 61, in create_connection\n    for res in socket.getaddrinfo(host, port, family, socket.SOCK_STREAM):\n  File \"c:\\users\\atpc8\\appdata\\local\\programs\\python\\python37\\lib\\socket.py\", line 748, in getaddrinfo\n    for res in _socket.getaddrinfo(host, port, family, type, proto, flags):\nsocket.gaierror: [Errno 11001] getaddrinfo failed\n\nDuring handling of the above exception, another exception occurred:\n\nTraceback (most recent call last):\n  File \"c:\\users\\atpc8\\appdata\\local\\programs\\python\\python37\\lib\\site-packages\\urllib3\\connectionpool.py\", line 672, in urlopen\n    chunked=chunked,\n  File \"c:\\users\\atpc8\\appdata\\local\\programs\\python\\python37\\lib\\site-packages\\urllib3\\connectionpool.py\", line 387, in _make_request\n    conn.request(method, url, **httplib_request_kw)\n  File \"c:\\users\\atpc8\\appdata\\local\\programs\\python\\python37\\lib\\http\\client.py\", line 1229, in request\n    self._send_request(method, url, body, headers, encode_chunked)\n  File \"c:\\users\\atpc8\\appdata\\local\\programs\\python\\python37\\lib\\http\\client.py\", line 1275, in _send_request\n    self.endheaders(body, encode_chunked=encode_chunked)\n  File \"c:\\users\\atpc8\\appdata\\local\\programs\\python\\python37\\lib\\http\\client.py\", line 1224, in endheaders\n    self._send_output(message_body, encode_chunked=encode_chunked)\n  File \"c:\\users\\atpc8\\appdata\\local\\programs\\python\\python37\\lib\\http\\client.py\", line 1016, in _send_output\n    self.send(msg)\n  File \"c:\\users\\atpc8\\appdata\\local\\programs\\python\\python37\\lib\\http\\client.py\", line 956, in send\n    self.connect()\n  File \"c:\\users\\atpc8\\appdata\\local\\programs\\python\\python37\\lib\\site-packages\\urllib3\\connection.py\", line 184, in connect\n    conn = self._new_conn()\n  File \"c:\\users\\atpc8\\appdata\\local\\programs\\python\\python37\\lib\\site-packages\\urllib3\\connection.py\", line 169, in _new_conn\n    self, \"Failed to establish a new connection: %s\" % e\nurllib3.exceptions.NewConnectionError: <urllib3.connection.HTTPConnection object at 0x000001FC4D2D8358>: Failed to establish a new connection: [Errno 11001] getaddrinfo failed\n\nDuring handling of the above exception, another exception occurred:\n\nTraceback (most recent call last):\n  File \"c:\\users\\atpc8\\appdata\\local\\programs\\python\\python37\\lib\\site-packages\\requests\\adapters.py\", line 449, in send\n    timeout=timeout\n  File \"c:\\users\\atpc8\\appdata\\local\\programs\\python\\python37\\lib\\site-packages\\urllib3\\connectionpool.py\", line 720, in urlopen\n    method, url, error=e, _pool=self, _stacktrace=sys.exc_info()[2]\n  File \"c:\\users\\atpc8\\appdata\\local\\programs\\python\\python37\\lib\\site-packages\\urllib3\\util\\retry.py\", line 436, in increment\n    raise MaxRetryError(_pool, url, error or ResponseError(cause))\nurllib3.exceptions.MaxRetryError: HTTPConnectionPool(host='api.dev.compareking.no', port=80): Max retries exceeded with url: /api/application (Caused by NewConnectionError('<urllib3.connection.HTTPConnection object at 0x000001FC4D2D8358>: Failed to establish a new connection: [Errno 11001] getaddrinfo failed'))\n\nDuring handling of the above exception, another exception occurred:\n\nTraceback (most recent call last):\n  File \"c:\\users\\atpc8\\appdata\\local\\programs\\python\\python37\\lib\\site-packages\\lemoncheesecake\\runner.py\", line 188, in run\n    self.test.callback(**test_func_params)\n  File \"C:\\Users\\atpc8\\sdlc\\lemontest\\suites\\thirdsuite.py\", line 47, in req1\n    headers=auth_headers, data=payload)\n  File \"c:\\users\\atpc8\\appdata\\local\\programs\\python\\python37\\lib\\site-packages\\requests\\api.py\", line 116, in post\n    return request('post', url, data=data, json=json, **kwargs)\n  File \"c:\\users\\atpc8\\appdata\\local\\programs\\python\\python37\\lib\\site-packages\\requests\\api.py\", line 60, in request\n    return session.request(method=method, url=url, **kwargs)\n  File \"c:\\users\\atpc8\\appdata\\local\\programs\\python\\python37\\lib\\site-packages\\requests\\sessions.py\", line 533, in request\n    resp = self.send(prep, **send_kwargs)\n  File \"c:\\users\\atpc8\\appdata\\local\\programs\\python\\python37\\lib\\site-packages\\requests\\sessions.py\", line 646, in send\n    r = adapter.send(request, **kwargs)\n  File \"c:\\users\\atpc8\\appdata\\local\\programs\\python\\python37\\lib\\site-packages\\requests\\adapters.py\", line 516, in send\n    raise ConnectionError(e, request=request)\nrequests.exceptions.ConnectionError: HTTPConnectionPool(host='api.dev.compareking.no', port=80): Max retries exceeded with url: /api/application (Caused by NewConnectionError('<urllib3.connection.HTTPConnection object at 0x000001FC4D2D8358>: Failed to establish a new connection: [Errno 11001] getaddrinfo failed'))\n", "time": "2020-03-14T16:30:07.490Z"}]}], "status": "failed", "status_details": null, "name": "req1", "description": "Submit existing application or sent less than 3 months ago", "tags": [], "properties": {}, "links": []}, {"start_time": "2020-03-14T16:30:07.492Z", "end_time": "2020-03-14T16:30:07.500Z", "steps": [{"description": "Submit unfinished application with all required information", "start_time": "2020-03-14T16:30:07.492Z", "end_time": "2020-03-14T16:30:07.500Z", "entries": [{"type": "log", "level": "error", "message": "Caught unexpected exception while running test: Traceback (most recent call last):\n  File \"c:\\users\\atpc8\\appdata\\local\\programs\\python\\python37\\lib\\site-packages\\urllib3\\connection.py\", line 157, in _new_conn\n    (self._dns_host, self.port), self.timeout, **extra_kw\n  File \"c:\\users\\atpc8\\appdata\\local\\programs\\python\\python37\\lib\\site-packages\\urllib3\\util\\connection.py\", line 61, in create_connection\n    for res in socket.getaddrinfo(host, port, family, socket.SOCK_STREAM):\n  File \"c:\\users\\atpc8\\appdata\\local\\programs\\python\\python37\\lib\\socket.py\", line 748, in getaddrinfo\n    for res in _socket.getaddrinfo(host, port, family, type, proto, flags):\nsocket.gaierror: [Errno 11001] getaddrinfo failed\n\nDuring handling of the above exception, another exception occurred:\n\nTraceback (most recent call last):\n  File \"c:\\users\\atpc8\\appdata\\local\\programs\\python\\python37\\lib\\site-packages\\urllib3\\connectionpool.py\", line 672, in urlopen\n    chunked=chunked,\n  File \"c:\\users\\atpc8\\appdata\\local\\programs\\python\\python37\\lib\\site-packages\\urllib3\\connectionpool.py\", line 387, in _make_request\n    conn.request(method, url, **httplib_request_kw)\n  File \"c:\\users\\atpc8\\appdata\\local\\programs\\python\\python37\\lib\\http\\client.py\", line 1229, in request\n    self._send_request(method, url, body, headers, encode_chunked)\n  File \"c:\\users\\atpc8\\appdata\\local\\programs\\python\\python37\\lib\\http\\client.py\", line 1275, in _send_request\n    self.endheaders(body, encode_chunked=encode_chunked)\n  File \"c:\\users\\atpc8\\appdata\\local\\programs\\python\\python37\\lib\\http\\client.py\", line 1224, in endheaders\n    self._send_output(message_body, encode_chunked=encode_chunked)\n  File \"c:\\users\\atpc8\\appdata\\local\\programs\\python\\python37\\lib\\http\\client.py\", line 1016, in _send_output\n    self.send(msg)\n  File \"c:\\users\\atpc8\\appdata\\local\\programs\\python\\python37\\lib\\http\\client.py\", line 956, in send\n    self.connect()\n  File \"c:\\users\\atpc8\\appdata\\local\\programs\\python\\python37\\lib\\site-packages\\urllib3\\connection.py\", line 184, in connect\n    conn = self._new_conn()\n  File \"c:\\users\\atpc8\\appdata\\local\\programs\\python\\python37\\lib\\site-packages\\urllib3\\connection.py\", line 169, in _new_conn\n    self, \"Failed to establish a new connection: %s\" % e\nurllib3.exceptions.NewConnectionError: <urllib3.connection.HTTPConnection object at 0x000001FC4D2D8400>: Failed to establish a new connection: [Errno 11001] getaddrinfo failed\n\nDuring handling of the above exception, another exception occurred:\n\nTraceback (most recent call last):\n  File \"c:\\users\\atpc8\\appdata\\local\\programs\\python\\python37\\lib\\site-packages\\requests\\adapters.py\", line 449, in send\n    timeout=timeout\n  File \"c:\\users\\atpc8\\appdata\\local\\programs\\python\\python37\\lib\\site-packages\\urllib3\\connectionpool.py\", line 720, in urlopen\n    method, url, error=e, _pool=self, _stacktrace=sys.exc_info()[2]\n  File \"c:\\users\\atpc8\\appdata\\local\\programs\\python\\python37\\lib\\site-packages\\urllib3\\util\\retry.py\", line 436, in increment\n    raise MaxRetryError(_pool, url, error or ResponseError(cause))\nurllib3.exceptions.MaxRetryError: HTTPConnectionPool(host='api.dev.compareking.no', port=80): Max retries exceeded with url: /api/contact (Caused by NewConnectionError('<urllib3.connection.HTTPConnection object at 0x000001FC4D2D8400>: Failed to establish a new connection: [Errno 11001] getaddrinfo failed'))\n\nDuring handling of the above exception, another exception occurred:\n\nTraceback (most recent call last):\n  File \"c:\\users\\atpc8\\appdata\\local\\programs\\python\\python37\\lib\\site-packages\\lemoncheesecake\\runner.py\", line 188, in run\n    self.test.callback(**test_func_params)\n  File \"C:\\Users\\atpc8\\sdlc\\lemontest\\suites\\thirdsuite.py\", line 64, in req2\n    headers=auth_headers, json=payload)\n  File \"c:\\users\\atpc8\\appdata\\local\\programs\\python\\python37\\lib\\site-packages\\requests\\api.py\", line 116, in post\n    return request('post', url, data=data, json=json, **kwargs)\n  File \"c:\\users\\atpc8\\appdata\\local\\programs\\python\\python37\\lib\\site-packages\\requests\\api.py\", line 60, in request\n    return session.request(method=method, url=url, **kwargs)\n  File \"c:\\users\\atpc8\\appdata\\local\\programs\\python\\python37\\lib\\site-packages\\requests\\sessions.py\", line 533, in request\n    resp = self.send(prep, **send_kwargs)\n  File \"c:\\users\\atpc8\\appdata\\local\\programs\\python\\python37\\lib\\site-packages\\requests\\sessions.py\", line 646, in send\n    r = adapter.send(request, **kwargs)\n  File \"c:\\users\\atpc8\\appdata\\local\\programs\\python\\python37\\lib\\site-packages\\requests\\adapters.py\", line 516, in send\n    raise ConnectionError(e, request=request)\nrequests.exceptions.ConnectionError: HTTPConnectionPool(host='api.dev.compareking.no', port=80): Max retries exceeded with url: /api/contact (Caused by NewConnectionError('<urllib3.connection.HTTPConnection object at 0x000001FC4D2D8400>: Failed to establish a new connection: [Errno 11001] getaddrinfo failed'))\n", "time": "2020-03-14T16:30:07.500Z"}]}], "status": "failed", "status_details": null, "name": "req2", "description": "Submit unfinished application with all required information", "tags": [], "properties": {}, "links": []}, {"start_time": "2020-03-14T16:30:07.505Z", "end_time": "2020-03-14T16:30:07.517Z", "steps": [{"description": "Submit unfinished application with incomplete required info", "start_time": "2020-03-14T16:30:07.505Z", "end_time": "2020-03-14T16:30:07.517Z", "entries": [{"type": "log", "level": "error", "message": "Caught unexpected exception while running test: Traceback (most recent call last):\n  File \"c:\\users\\atpc8\\appdata\\local\\programs\\python\\python37\\lib\\site-packages\\urllib3\\connection.py\", line 157, in _new_conn\n    (self._dns_host, self.port), self.timeout, **extra_kw\n  File \"c:\\users\\atpc8\\appdata\\local\\programs\\python\\python37\\lib\\site-packages\\urllib3\\util\\connection.py\", line 61, in create_connection\n    for res in socket.getaddrinfo(host, port, family, socket.SOCK_STREAM):\n  File \"c:\\users\\atpc8\\appdata\\local\\programs\\python\\python37\\lib\\socket.py\", line 748, in getaddrinfo\n    for res in _socket.getaddrinfo(host, port, family, type, proto, flags):\nsocket.gaierror: [Errno 11001] getaddrinfo failed\n\nDuring handling of the above exception, another exception occurred:\n\nTraceback (most recent call last):\n  File \"c:\\users\\atpc8\\appdata\\local\\programs\\python\\python37\\lib\\site-packages\\urllib3\\connectionpool.py\", line 672, in urlopen\n    chunked=chunked,\n  File \"c:\\users\\atpc8\\appdata\\local\\programs\\python\\python37\\lib\\site-packages\\urllib3\\connectionpool.py\", line 387, in _make_request\n    conn.request(method, url, **httplib_request_kw)\n  File \"c:\\users\\atpc8\\appdata\\local\\programs\\python\\python37\\lib\\http\\client.py\", line 1229, in request\n    self._send_request(method, url, body, headers, encode_chunked)\n  File \"c:\\users\\atpc8\\appdata\\local\\programs\\python\\python37\\lib\\http\\client.py\", line 1275, in _send_request\n    self.endheaders(body, encode_chunked=encode_chunked)\n  File \"c:\\users\\atpc8\\appdata\\local\\programs\\python\\python37\\lib\\http\\client.py\", line 1224, in endheaders\n    self._send_output(message_body, encode_chunked=encode_chunked)\n  File \"c:\\users\\atpc8\\appdata\\local\\programs\\python\\python37\\lib\\http\\client.py\", line 1016, in _send_output\n    self.send(msg)\n  File \"c:\\users\\atpc8\\appdata\\local\\programs\\python\\python37\\lib\\http\\client.py\", line 956, in send\n    self.connect()\n  File \"c:\\users\\atpc8\\appdata\\local\\programs\\python\\python37\\lib\\site-packages\\urllib3\\connection.py\", line 184, in connect\n    conn = self._new_conn()\n  File \"c:\\users\\atpc8\\appdata\\local\\programs\\python\\python37\\lib\\site-packages\\urllib3\\connection.py\", line 169, in _new_conn\n    self, \"Failed to establish a new connection: %s\" % e\nurllib3.exceptions.NewConnectionError: <urllib3.connection.HTTPConnection object at 0x000001FC4D2D85F8>: Failed to establish a new connection: [Errno 11001] getaddrinfo failed\n\nDuring handling of the above exception, another exception occurred:\n\nTraceback (most recent call last):\n  File \"c:\\users\\atpc8\\appdata\\local\\programs\\python\\python37\\lib\\site-packages\\requests\\adapters.py\", line 449, in send\n    timeout=timeout\n  File \"c:\\users\\atpc8\\appdata\\local\\programs\\python\\python37\\lib\\site-packages\\urllib3\\connectionpool.py\", line 720, in urlopen\n    method, url, error=e, _pool=self, _stacktrace=sys.exc_info()[2]\n  File \"c:\\users\\atpc8\\appdata\\local\\programs\\python\\python37\\lib\\site-packages\\urllib3\\util\\retry.py\", line 436, in increment\n    raise MaxRetryError(_pool, url, error or ResponseError(cause))\nurllib3.exceptions.MaxRetryError: HTTPConnectionPool(host='api.dev.compareking.no', port=80): Max retries exceeded with url: /api/contact (Caused by NewConnectionError('<urllib3.connection.HTTPConnection object at 0x000001FC4D2D85F8>: Failed to establish a new connection: [Errno 11001] getaddrinfo failed'))\n\nDuring handling of the above exception, another exception occurred:\n\nTraceback (most recent call last):\n  File \"c:\\users\\atpc8\\appdata\\local\\programs\\python\\python37\\lib\\site-packages\\lemoncheesecake\\runner.py\", line 188, in run\n    self.test.callback(**test_func_params)\n  File \"C:\\Users\\atpc8\\sdlc\\lemontest\\suites\\thirdsuite.py\", line 81, in req3\n    headers=auth_headers, json=payload)\n  File \"c:\\users\\atpc8\\appdata\\local\\programs\\python\\python37\\lib\\site-packages\\requests\\api.py\", line 116, in post\n    return request('post', url, data=data, json=json, **kwargs)\n  File \"c:\\users\\atpc8\\appdata\\local\\programs\\python\\python37\\lib\\site-packages\\requests\\api.py\", line 60, in request\n    return session.request(method=method, url=url, **kwargs)\n  File \"c:\\users\\atpc8\\appdata\\local\\programs\\python\\python37\\lib\\site-packages\\requests\\sessions.py\", line 533, in request\n    resp = self.send(prep, **send_kwargs)\n  File \"c:\\users\\atpc8\\appdata\\local\\programs\\python\\python37\\lib\\site-packages\\requests\\sessions.py\", line 646, in send\n    r = adapter.send(request, **kwargs)\n  File \"c:\\users\\atpc8\\appdata\\local\\programs\\python\\python37\\lib\\site-packages\\requests\\adapters.py\", line 516, in send\n    raise ConnectionError(e, request=request)\nrequests.exceptions.ConnectionError: HTTPConnectionPool(host='api.dev.compareking.no', port=80): Max retries exceeded with url: /api/contact (Caused by NewConnectionError('<urllib3.connection.HTTPConnection object at 0x000001FC4D2D85F8>: Failed to establish a new connection: [Errno 11001] getaddrinfo failed'))\n", "time": "2020-03-14T16:30:07.516Z"}]}], "status": "failed", "status_details": null, "name": "req3", "description": "Submit unfinished application with incomplete required info", "tags": [], "properties": {}, "links": []}, {"start_time": "2020-03-14T16:30:07.517Z", "end_time": "2020-03-14T16:30:07.523Z", "steps": [{"description": "Submit unfinished application that already exists", "start_time": "2020-03-14T16:30:07.517Z", "end_time": "2020-03-14T16:30:07.523Z", "entries": [{"type": "log", "level": "error", "message": "Caught unexpected exception while running test: Traceback (most recent call last):\n  File \"c:\\users\\atpc8\\appdata\\local\\programs\\python\\python37\\lib\\site-packages\\urllib3\\connection.py\", line 157, in _new_conn\n    (self._dns_host, self.port), self.timeout, **extra_kw\n  File \"c:\\users\\atpc8\\appdata\\local\\programs\\python\\python37\\lib\\site-packages\\urllib3\\util\\connection.py\", line 61, in create_connection\n    for res in socket.getaddrinfo(host, port, family, socket.SOCK_STREAM):\n  File \"c:\\users\\atpc8\\appdata\\local\\programs\\python\\python37\\lib\\socket.py\", line 748, in getaddrinfo\n    for res in _socket.getaddrinfo(host, port, family, type, proto, flags):\nsocket.gaierror: [Errno 11001] getaddrinfo failed\n\nDuring handling of the above exception, another exception occurred:\n\nTraceback (most recent call last):\n  File \"c:\\users\\atpc8\\appdata\\local\\programs\\python\\python37\\lib\\site-packages\\urllib3\\connectionpool.py\", line 672, in urlopen\n    chunked=chunked,\n  File \"c:\\users\\atpc8\\appdata\\local\\programs\\python\\python37\\lib\\site-packages\\urllib3\\connectionpool.py\", line 387, in _make_request\n    conn.request(method, url, **httplib_request_kw)\n  File \"c:\\users\\atpc8\\appdata\\local\\programs\\python\\python37\\lib\\http\\client.py\", line 1229, in request\n    self._send_request(method, url, body, headers, encode_chunked)\n  File \"c:\\users\\atpc8\\appdata\\local\\programs\\python\\python37\\lib\\http\\client.py\", line 1275, in _send_request\n    self.endheaders(body, encode_chunked=encode_chunked)\n  File \"c:\\users\\atpc8\\appdata\\local\\programs\\python\\python37\\lib\\http\\client.py\", line 1224, in endheaders\n    self._send_output(message_body, encode_chunked=encode_chunked)\n  File \"c:\\users\\atpc8\\appdata\\local\\programs\\python\\python37\\lib\\http\\client.py\", line 1016, in _send_output\n    self.send(msg)\n  File \"c:\\users\\atpc8\\appdata\\local\\programs\\python\\python37\\lib\\http\\client.py\", line 956, in send\n    self.connect()\n  File \"c:\\users\\atpc8\\appdata\\local\\programs\\python\\python37\\lib\\site-packages\\urllib3\\connection.py\", line 184, in connect\n    conn = self._new_conn()\n  File \"c:\\users\\atpc8\\appdata\\local\\programs\\python\\python37\\lib\\site-packages\\urllib3\\connection.py\", line 169, in _new_conn\n    self, \"Failed to establish a new connection: %s\" % e\nurllib3.exceptions.NewConnectionError: <urllib3.connection.HTTPConnection object at 0x000001FC4D2D8780>: Failed to establish a new connection: [Errno 11001] getaddrinfo failed\n\nDuring handling of the above exception, another exception occurred:\n\nTraceback (most recent call last):\n  File \"c:\\users\\atpc8\\appdata\\local\\programs\\python\\python37\\lib\\site-packages\\requests\\adapters.py\", line 449, in send\n    timeout=timeout\n  File \"c:\\users\\atpc8\\appdata\\local\\programs\\python\\python37\\lib\\site-packages\\urllib3\\connectionpool.py\", line 720, in urlopen\n    method, url, error=e, _pool=self, _stacktrace=sys.exc_info()[2]\n  File \"c:\\users\\atpc8\\appdata\\local\\programs\\python\\python37\\lib\\site-packages\\urllib3\\util\\retry.py\", line 436, in increment\n    raise MaxRetryError(_pool, url, error or ResponseError(cause))\nurllib3.exceptions.MaxRetryError: HTTPConnectionPool(host='api.dev.compareking.no', port=80): Max retries exceeded with url: /api/contact (Caused by NewConnectionError('<urllib3.connection.HTTPConnection object at 0x000001FC4D2D8780>: Failed to establish a new connection: [Errno 11001] getaddrinfo failed'))\n\nDuring handling of the above exception, another exception occurred:\n\nTraceback (most recent call last):\n  File \"c:\\users\\atpc8\\appdata\\local\\programs\\python\\python37\\lib\\site-packages\\lemoncheesecake\\runner.py\", line 188, in run\n    self.test.callback(**test_func_params)\n  File \"C:\\Users\\atpc8\\sdlc\\lemontest\\suites\\thirdsuite.py\", line 97, in req4\n    headers=auth_headers, json=payload)\n  File \"c:\\users\\atpc8\\appdata\\local\\programs\\python\\python37\\lib\\site-packages\\requests\\api.py\", line 116, in post\n    return request('post', url, data=data, json=json, **kwargs)\n  File \"c:\\users\\atpc8\\appdata\\local\\programs\\python\\python37\\lib\\site-packages\\requests\\api.py\", line 60, in request\n    return session.request(method=method, url=url, **kwargs)\n  File \"c:\\users\\atpc8\\appdata\\local\\programs\\python\\python37\\lib\\site-packages\\requests\\sessions.py\", line 533, in request\n    resp = self.send(prep, **send_kwargs)\n  File \"c:\\users\\atpc8\\appdata\\local\\programs\\python\\python37\\lib\\site-packages\\requests\\sessions.py\", line 646, in send\n    r = adapter.send(request, **kwargs)\n  File \"c:\\users\\atpc8\\appdata\\local\\programs\\python\\python37\\lib\\site-packages\\requests\\adapters.py\", line 516, in send\n    raise ConnectionError(e, request=request)\nrequests.exceptions.ConnectionError: HTTPConnectionPool(host='api.dev.compareking.no', port=80): Max retries exceeded with url: /api/contact (Caused by NewConnectionError('<urllib3.connection.HTTPConnection object at 0x000001FC4D2D8780>: Failed to establish a new connection: [Errno 11001] getaddrinfo failed'))\n", "time": "2020-03-14T16:30:07.523Z"}]}], "status": "failed", "status_details": null, "name": "req4", "description": "Submit unfinished application that already exists", "tags": [], "properties": {}, "links": []}], "suites": [], "name": "thirdsuite", "description": "my_suite", "tags": [], "properties": {}, "links": []}, {"start_time": "2020-03-14T16:30:07.527Z", "end_time": "2020-03-14T16:30:07.889Z", "tests": [{"start_time": "2020-03-14T16:30:07.528Z", "end_time": "2020-03-14T16:30:07.887Z", "steps": [{"description": "glc_auth_test", "start_time": "2020-03-14T16:30:07.528Z", "end_time": "2020-03-14T16:30:07.887Z", "entries": [{"type": "check", "description": "Expect http code to be equal to 200", "is_successful": false, "details": "Got 401", "time": "2020-03-14T16:30:07.883Z"}, {"type": "log", "level": "info", "message": "Response\n{\n    \"timestamp\": \"2020-03-14 17:22:21\",\n    \"status\": 401,\n    \"error\": \"Unauthorized\",\n    \"message\": \"Unauthorized\",\n    \"path\": \"/api\"\n}", "time": "2020-03-14T16:30:07.887Z"}]}], "status": "failed", "status_details": null, "name": "glc_auth_test", "description": "glc_auth_test", "tags": ["glc"], "properties": {}, "links": []}], "suites": [], "name": "tuisuite", "description": "GLC test", "tags": [], "properties": {}, "links": []}]}