var reporting_data = {"lemoncheesecake_version": "1.3.1", "report_version": 1.1, "start_time": "2020-05-16T16:11:22.146Z", "end_time": "2020-05-16T16:11:25.033Z", "generation_time": "2020-05-16T16:11:25.044Z", "nb_threads": 1, "title": "Test Report", "info": [["Command line", "lcc run"]], "suites": [{"start_time": "2020-05-16T16:11:22.150Z", "end_time": "2020-05-16T16:11:22.931Z", "tests": [{"start_time": "2020-05-16T16:11:22.150Z", "end_time": "2020-05-16T16:11:22.150Z", "steps": [{"description": "test1", "start_time": "2020-05-16T16:11:22.150Z", "end_time": "2020-05-16T16:11:22.150Z", "entries": [{"type": "check", "description": "Expect value to be equal to 4.0", "is_successful": true, "details": "Got 4", "time": "2020-05-16T16:11:22.150Z"}]}], "status": "passed", "status_details": null, "name": "test1", "description": "test1", "tags": [], "properties": {}, "links": []}, {"start_time": "2020-05-16T16:11:22.150Z", "end_time": "2020-05-16T16:11:22.151Z", "steps": [], "status": "passed", "status_details": null, "name": "test2", "description": "test2", "tags": [], "properties": {}, "links": []}, {"start_time": "2020-05-16T16:11:22.151Z", "end_time": "2020-05-16T16:11:22.930Z", "steps": [{"description": "test3", "start_time": "2020-05-16T16:11:22.151Z", "end_time": "2020-05-16T16:11:22.930Z", "entries": [{"type": "check", "description": "Expect http code to be equal to 200", "is_successful": false, "details": "Got 406", "time": "2020-05-16T16:11:22.918Z"}, {"type": "log", "level": "error", "message": "Caught unexpected exception while running test: Traceback (most recent call last):\n  File \"c:\\users\\atpc8\\appdata\\local\\programs\\python\\python37\\lib\\site-packages\\lemoncheesecake\\runner.py\", line 188, in run\n    self.test.callback(**test_func_params)\n  File \"C:\\Users\\atpc8\\sdlc\\lemontest\\suites\\firstsuite.py\", line 25, in test3\n    resp = r.json()\n  File \"c:\\users\\atpc8\\appdata\\local\\programs\\python\\python37\\lib\\site-packages\\requests\\models.py\", line 897, in json\n    return complexjson.loads(self.text, **kwargs)\n  File \"c:\\users\\atpc8\\appdata\\local\\programs\\python\\python37\\lib\\json\\__init__.py\", line 348, in loads\n    return _default_decoder.decode(s)\n  File \"c:\\users\\atpc8\\appdata\\local\\programs\\python\\python37\\lib\\json\\decoder.py\", line 337, in decode\n    obj, end = self.raw_decode(s, idx=_w(s, 0).end())\n  File \"c:\\users\\atpc8\\appdata\\local\\programs\\python\\python37\\lib\\json\\decoder.py\", line 355, in raw_decode\n    raise JSONDecodeError(\"Expecting value\", s, err.value) from None\njson.decoder.JSONDecodeError: Expecting value: line 1 column 1 (char 0)\n", "time": "2020-05-16T16:11:22.930Z"}]}], "status": "failed", "status_details": null, "name": "test3", "description": "test3", "tags": ["equinix"], "properties": {}, "links": []}], "suites": [], "name": "firstsuite", "description": "my_suite", "tags": ["samples", "tutorials"], "properties": {}, "links": []}, {"start_time": "2020-05-16T16:11:22.931Z", "end_time": "2020-05-16T16:11:24.265Z", "tests": [{"start_time": "2020-05-16T16:11:22.931Z", "end_time": "2020-05-16T16:11:23.036Z", "steps": [{"description": "req1", "start_time": "2020-05-16T16:11:22.932Z", "end_time": "2020-05-16T16:11:23.036Z", "entries": [{"type": "url", "description": "This is first shoot in this suite!!!", "url": "http://api.dev.compareking.no/api/application/111", "time": "2020-05-16T16:11:22.932Z"}, {"type": "log", "level": "error", "message": "Caught unexpected exception while running test: Traceback (most recent call last):\n  File \"c:\\users\\atpc8\\appdata\\local\\programs\\python\\python37\\lib\\site-packages\\urllib3\\connection.py\", line 157, in _new_conn\n    (self._dns_host, self.port), self.timeout, **extra_kw\n  File \"c:\\users\\atpc8\\appdata\\local\\programs\\python\\python37\\lib\\site-packages\\urllib3\\util\\connection.py\", line 61, in create_connection\n    for res in socket.getaddrinfo(host, port, family, socket.SOCK_STREAM):\n  File \"c:\\users\\atpc8\\appdata\\local\\programs\\python\\python37\\lib\\socket.py\", line 748, in getaddrinfo\n    for res in _socket.getaddrinfo(host, port, family, type, proto, flags):\nsocket.gaierror: [Errno 11001] getaddrinfo failed\n\nDuring handling of the above exception, another exception occurred:\n\nTraceback (most recent call last):\n  File \"c:\\users\\atpc8\\appdata\\local\\programs\\python\\python37\\lib\\site-packages\\urllib3\\connectionpool.py\", line 672, in urlopen\n    chunked=chunked,\n  File \"c:\\users\\atpc8\\appdata\\local\\programs\\python\\python37\\lib\\site-packages\\urllib3\\connectionpool.py\", line 387, in _make_request\n    conn.request(method, url, **httplib_request_kw)\n  File \"c:\\users\\atpc8\\appdata\\local\\programs\\python\\python37\\lib\\http\\client.py\", line 1229, in request\n    self._send_request(method, url, body, headers, encode_chunked)\n  File \"c:\\users\\atpc8\\appdata\\local\\programs\\python\\python37\\lib\\http\\client.py\", line 1275, in _send_request\n    self.endheaders(body, encode_chunked=encode_chunked)\n  File \"c:\\users\\atpc8\\appdata\\local\\programs\\python\\python37\\lib\\http\\client.py\", line 1224, in endheaders\n    self._send_output(message_body, encode_chunked=encode_chunked)\n  File \"c:\\users\\atpc8\\appdata\\local\\programs\\python\\python37\\lib\\http\\client.py\", line 1016, in _send_output\n    self.send(msg)\n  File \"c:\\users\\atpc8\\appdata\\local\\programs\\python\\python37\\lib\\http\\client.py\", line 956, in send\n    self.connect()\n  File \"c:\\users\\atpc8\\appdata\\local\\programs\\python\\python37\\lib\\site-packages\\urllib3\\connection.py\", line 184, in connect\n    conn = self._new_conn()\n  File \"c:\\users\\atpc8\\appdata\\local\\programs\\python\\python37\\lib\\site-packages\\urllib3\\connection.py\", line 169, in _new_conn\n    self, \"Failed to establish a new connection: %s\" % e\nurllib3.exceptions.NewConnectionError: <urllib3.connection.HTTPConnection object at 0x000002081E4B1048>: Failed to establish a new connection: [Errno 11001] getaddrinfo failed\n\nDuring handling of the above exception, another exception occurred:\n\nTraceback (most recent call last):\n  File \"c:\\users\\atpc8\\appdata\\local\\programs\\python\\python37\\lib\\site-packages\\requests\\adapters.py\", line 449, in send\n    timeout=timeout\n  File \"c:\\users\\atpc8\\appdata\\local\\programs\\python\\python37\\lib\\site-packages\\urllib3\\connectionpool.py\", line 720, in urlopen\n    method, url, error=e, _pool=self, _stacktrace=sys.exc_info()[2]\n  File \"c:\\users\\atpc8\\appdata\\local\\programs\\python\\python37\\lib\\site-packages\\urllib3\\util\\retry.py\", line 436, in increment\n    raise MaxRetryError(_pool, url, error or ResponseError(cause))\nurllib3.exceptions.MaxRetryError: HTTPConnectionPool(host='api.dev.compareking.no', port=80): Max retries exceeded with url: /api/application/111 (Caused by NewConnectionError('<urllib3.connection.HTTPConnection object at 0x000002081E4B1048>: Failed to establish a new connection: [Errno 11001] getaddrinfo failed'))\n\nDuring handling of the above exception, another exception occurred:\n\nTraceback (most recent call last):\n  File \"c:\\users\\atpc8\\appdata\\local\\programs\\python\\python37\\lib\\site-packages\\lemoncheesecake\\runner.py\", line 188, in run\n    self.test.callback(**test_func_params)\n  File \"C:\\Users\\atpc8\\sdlc\\lemontest\\suites\\secondsuite.py\", line 17, in req1\n    headers=authenticate)\n  File \"c:\\users\\atpc8\\appdata\\local\\programs\\python\\python37\\lib\\site-packages\\requests\\api.py\", line 75, in get\n    return request('get', url, params=params, **kwargs)\n  File \"c:\\users\\atpc8\\appdata\\local\\programs\\python\\python37\\lib\\site-packages\\requests\\api.py\", line 60, in request\n    return session.request(method=method, url=url, **kwargs)\n  File \"c:\\users\\atpc8\\appdata\\local\\programs\\python\\python37\\lib\\site-packages\\requests\\sessions.py\", line 533, in request\n    resp = self.send(prep, **send_kwargs)\n  File \"c:\\users\\atpc8\\appdata\\local\\programs\\python\\python37\\lib\\site-packages\\requests\\sessions.py\", line 646, in send\n    r = adapter.send(request, **kwargs)\n  File \"c:\\users\\atpc8\\appdata\\local\\programs\\python\\python37\\lib\\site-packages\\requests\\adapters.py\", line 516, in send\n    raise ConnectionError(e, request=request)\nrequests.exceptions.ConnectionError: HTTPConnectionPool(host='api.dev.compareking.no', port=80): Max retries exceeded with url: /api/application/111 (Caused by NewConnectionError('<urllib3.connection.HTTPConnection object at 0x000002081E4B1048>: Failed to establish a new connection: [Errno 11001] getaddrinfo failed'))\n", "time": "2020-05-16T16:11:23.036Z"}]}], "status": "failed", "status_details": null, "name": "req1", "description": "req1", "tags": [], "properties": {}, "links": []}, {"start_time": "2020-05-16T16:11:23.038Z", "end_time": "2020-05-16T16:11:23.050Z", "steps": [{"description": "req2", "start_time": "2020-05-16T16:11:23.039Z", "end_time": "2020-05-16T16:11:23.050Z", "entries": [{"type": "log", "level": "error", "message": "Caught unexpected exception while running test: Traceback (most recent call last):\n  File \"c:\\users\\atpc8\\appdata\\local\\programs\\python\\python37\\lib\\site-packages\\urllib3\\connection.py\", line 157, in _new_conn\n    (self._dns_host, self.port), self.timeout, **extra_kw\n  File \"c:\\users\\atpc8\\appdata\\local\\programs\\python\\python37\\lib\\site-packages\\urllib3\\util\\connection.py\", line 61, in create_connection\n    for res in socket.getaddrinfo(host, port, family, socket.SOCK_STREAM):\n  File \"c:\\users\\atpc8\\appdata\\local\\programs\\python\\python37\\lib\\socket.py\", line 748, in getaddrinfo\n    for res in _socket.getaddrinfo(host, port, family, type, proto, flags):\nsocket.gaierror: [Errno 11001] getaddrinfo failed\n\nDuring handling of the above exception, another exception occurred:\n\nTraceback (most recent call last):\n  File \"c:\\users\\atpc8\\appdata\\local\\programs\\python\\python37\\lib\\site-packages\\urllib3\\connectionpool.py\", line 672, in urlopen\n    chunked=chunked,\n  File \"c:\\users\\atpc8\\appdata\\local\\programs\\python\\python37\\lib\\site-packages\\urllib3\\connectionpool.py\", line 387, in _make_request\n    conn.request(method, url, **httplib_request_kw)\n  File \"c:\\users\\atpc8\\appdata\\local\\programs\\python\\python37\\lib\\http\\client.py\", line 1229, in request\n    self._send_request(method, url, body, headers, encode_chunked)\n  File \"c:\\users\\atpc8\\appdata\\local\\programs\\python\\python37\\lib\\http\\client.py\", line 1275, in _send_request\n    self.endheaders(body, encode_chunked=encode_chunked)\n  File \"c:\\users\\atpc8\\appdata\\local\\programs\\python\\python37\\lib\\http\\client.py\", line 1224, in endheaders\n    self._send_output(message_body, encode_chunked=encode_chunked)\n  File \"c:\\users\\atpc8\\appdata\\local\\programs\\python\\python37\\lib\\http\\client.py\", line 1016, in _send_output\n    self.send(msg)\n  File \"c:\\users\\atpc8\\appdata\\local\\programs\\python\\python37\\lib\\http\\client.py\", line 956, in send\n    self.connect()\n  File \"c:\\users\\atpc8\\appdata\\local\\programs\\python\\python37\\lib\\site-packages\\urllib3\\connection.py\", line 184, in connect\n    conn = self._new_conn()\n  File \"c:\\users\\atpc8\\appdata\\local\\programs\\python\\python37\\lib\\site-packages\\urllib3\\connection.py\", line 169, in _new_conn\n    self, \"Failed to establish a new connection: %s\" % e\nurllib3.exceptions.NewConnectionError: <urllib3.connection.HTTPConnection object at 0x000002081E5038D0>: Failed to establish a new connection: [Errno 11001] getaddrinfo failed\n\nDuring handling of the above exception, another exception occurred:\n\nTraceback (most recent call last):\n  File \"c:\\users\\atpc8\\appdata\\local\\programs\\python\\python37\\lib\\site-packages\\requests\\adapters.py\", line 449, in send\n    timeout=timeout\n  File \"c:\\users\\atpc8\\appdata\\local\\programs\\python\\python37\\lib\\site-packages\\urllib3\\connectionpool.py\", line 720, in urlopen\n    method, url, error=e, _pool=self, _stacktrace=sys.exc_info()[2]\n  File \"c:\\users\\atpc8\\appdata\\local\\programs\\python\\python37\\lib\\site-packages\\urllib3\\util\\retry.py\", line 436, in increment\n    raise MaxRetryError(_pool, url, error or ResponseError(cause))\nurllib3.exceptions.MaxRetryError: HTTPConnectionPool(host='api.dev.compareking.no', port=80): Max retries exceeded with url: /api/application (Caused by NewConnectionError('<urllib3.connection.HTTPConnection object at 0x000002081E5038D0>: Failed to establish a new connection: [Errno 11001] getaddrinfo failed'))\n\nDuring handling of the above exception, another exception occurred:\n\nTraceback (most recent call last):\n  File \"c:\\users\\atpc8\\appdata\\local\\programs\\python\\python37\\lib\\site-packages\\lemoncheesecake\\runner.py\", line 188, in run\n    self.test.callback(**test_func_params)\n  File \"C:\\Users\\atpc8\\sdlc\\lemontest\\suites\\secondsuite.py\", line 25, in req2\n    headers=authenticate, data=throughput)\n  File \"c:\\users\\atpc8\\appdata\\local\\programs\\python\\python37\\lib\\site-packages\\requests\\api.py\", line 116, in post\n    return request('post', url, data=data, json=json, **kwargs)\n  File \"c:\\users\\atpc8\\appdata\\local\\programs\\python\\python37\\lib\\site-packages\\requests\\api.py\", line 60, in request\n    return session.request(method=method, url=url, **kwargs)\n  File \"c:\\users\\atpc8\\appdata\\local\\programs\\python\\python37\\lib\\site-packages\\requests\\sessions.py\", line 533, in request\n    resp = self.send(prep, **send_kwargs)\n  File \"c:\\users\\atpc8\\appdata\\local\\programs\\python\\python37\\lib\\site-packages\\requests\\sessions.py\", line 646, in send\n    r = adapter.send(request, **kwargs)\n  File \"c:\\users\\atpc8\\appdata\\local\\programs\\python\\python37\\lib\\site-packages\\requests\\adapters.py\", line 516, in send\n    raise ConnectionError(e, request=request)\nrequests.exceptions.ConnectionError: HTTPConnectionPool(host='api.dev.compareking.no', port=80): Max retries exceeded with url: /api/application (Caused by NewConnectionError('<urllib3.connection.HTTPConnection object at 0x000002081E5038D0>: Failed to establish a new connection: [Errno 11001] getaddrinfo failed'))\n", "time": "2020-05-16T16:11:23.050Z"}]}], "status": "failed", "status_details": null, "name": "req2", "description": "req2", "tags": [], "properties": {}, "links": []}, {"start_time": "2020-05-16T16:11:23.051Z", "end_time": "2020-05-16T16:11:23.059Z", "steps": [{"description": "req3", "start_time": "2020-05-16T16:11:23.052Z", "end_time": "2020-05-16T16:11:23.059Z", "entries": [{"type": "log", "level": "error", "message": "Caught unexpected exception while running test: Traceback (most recent call last):\n  File \"c:\\users\\atpc8\\appdata\\local\\programs\\python\\python37\\lib\\site-packages\\urllib3\\connection.py\", line 157, in _new_conn\n    (self._dns_host, self.port), self.timeout, **extra_kw\n  File \"c:\\users\\atpc8\\appdata\\local\\programs\\python\\python37\\lib\\site-packages\\urllib3\\util\\connection.py\", line 61, in create_connection\n    for res in socket.getaddrinfo(host, port, family, socket.SOCK_STREAM):\n  File \"c:\\users\\atpc8\\appdata\\local\\programs\\python\\python37\\lib\\socket.py\", line 748, in getaddrinfo\n    for res in _socket.getaddrinfo(host, port, family, type, proto, flags):\nsocket.gaierror: [Errno 11001] getaddrinfo failed\n\nDuring handling of the above exception, another exception occurred:\n\nTraceback (most recent call last):\n  File \"c:\\users\\atpc8\\appdata\\local\\programs\\python\\python37\\lib\\site-packages\\urllib3\\connectionpool.py\", line 672, in urlopen\n    chunked=chunked,\n  File \"c:\\users\\atpc8\\appdata\\local\\programs\\python\\python37\\lib\\site-packages\\urllib3\\connectionpool.py\", line 387, in _make_request\n    conn.request(method, url, **httplib_request_kw)\n  File \"c:\\users\\atpc8\\appdata\\local\\programs\\python\\python37\\lib\\http\\client.py\", line 1229, in request\n    self._send_request(method, url, body, headers, encode_chunked)\n  File \"c:\\users\\atpc8\\appdata\\local\\programs\\python\\python37\\lib\\http\\client.py\", line 1275, in _send_request\n    self.endheaders(body, encode_chunked=encode_chunked)\n  File \"c:\\users\\atpc8\\appdata\\local\\programs\\python\\python37\\lib\\http\\client.py\", line 1224, in endheaders\n    self._send_output(message_body, encode_chunked=encode_chunked)\n  File \"c:\\users\\atpc8\\appdata\\local\\programs\\python\\python37\\lib\\http\\client.py\", line 1016, in _send_output\n    self.send(msg)\n  File \"c:\\users\\atpc8\\appdata\\local\\programs\\python\\python37\\lib\\http\\client.py\", line 956, in send\n    self.connect()\n  File \"c:\\users\\atpc8\\appdata\\local\\programs\\python\\python37\\lib\\site-packages\\urllib3\\connection.py\", line 184, in connect\n    conn = self._new_conn()\n  File \"c:\\users\\atpc8\\appdata\\local\\programs\\python\\python37\\lib\\site-packages\\urllib3\\connection.py\", line 169, in _new_conn\n    self, \"Failed to establish a new connection: %s\" % e\nurllib3.exceptions.NewConnectionError: <urllib3.connection.HTTPConnection object at 0x000002081E503C18>: Failed to establish a new connection: [Errno 11001] getaddrinfo failed\n\nDuring handling of the above exception, another exception occurred:\n\nTraceback (most recent call last):\n  File \"c:\\users\\atpc8\\appdata\\local\\programs\\python\\python37\\lib\\site-packages\\requests\\adapters.py\", line 449, in send\n    timeout=timeout\n  File \"c:\\users\\atpc8\\appdata\\local\\programs\\python\\python37\\lib\\site-packages\\urllib3\\connectionpool.py\", line 720, in urlopen\n    method, url, error=e, _pool=self, _stacktrace=sys.exc_info()[2]\n  File \"c:\\users\\atpc8\\appdata\\local\\programs\\python\\python37\\lib\\site-packages\\urllib3\\util\\retry.py\", line 436, in increment\n    raise MaxRetryError(_pool, url, error or ResponseError(cause))\nurllib3.exceptions.MaxRetryError: HTTPConnectionPool(host='api.dev.compareking.no', port=80): Max retries exceeded with url: /api/application (Caused by NewConnectionError('<urllib3.connection.HTTPConnection object at 0x000002081E503C18>: Failed to establish a new connection: [Errno 11001] getaddrinfo failed'))\n\nDuring handling of the above exception, another exception occurred:\n\nTraceback (most recent call last):\n  File \"c:\\users\\atpc8\\appdata\\local\\programs\\python\\python37\\lib\\site-packages\\lemoncheesecake\\runner.py\", line 188, in run\n    self.test.callback(**test_func_params)\n  File \"C:\\Users\\atpc8\\sdlc\\lemontest\\suites\\secondsuite.py\", line 33, in req3\n    headers=authenticate, data=throughput)\n  File \"c:\\users\\atpc8\\appdata\\local\\programs\\python\\python37\\lib\\site-packages\\requests\\api.py\", line 116, in post\n    return request('post', url, data=data, json=json, **kwargs)\n  File \"c:\\users\\atpc8\\appdata\\local\\programs\\python\\python37\\lib\\site-packages\\requests\\api.py\", line 60, in request\n    return session.request(method=method, url=url, **kwargs)\n  File \"c:\\users\\atpc8\\appdata\\local\\programs\\python\\python37\\lib\\site-packages\\requests\\sessions.py\", line 533, in request\n    resp = self.send(prep, **send_kwargs)\n  File \"c:\\users\\atpc8\\appdata\\local\\programs\\python\\python37\\lib\\site-packages\\requests\\sessions.py\", line 646, in send\n    r = adapter.send(request, **kwargs)\n  File \"c:\\users\\atpc8\\appdata\\local\\programs\\python\\python37\\lib\\site-packages\\requests\\adapters.py\", line 516, in send\n    raise ConnectionError(e, request=request)\nrequests.exceptions.ConnectionError: HTTPConnectionPool(host='api.dev.compareking.no', port=80): Max retries exceeded with url: /api/application (Caused by NewConnectionError('<urllib3.connection.HTTPConnection object at 0x000002081E503C18>: Failed to establish a new connection: [Errno 11001] getaddrinfo failed'))\n", "time": "2020-05-16T16:11:23.059Z"}]}], "status": "failed", "status_details": null, "name": "req3", "description": "req3", "tags": [], "properties": {}, "links": []}, {"start_time": "2020-05-16T16:11:23.061Z", "end_time": "2020-05-16T16:11:23.077Z", "steps": [{"description": "req4", "start_time": "2020-05-16T16:11:23.061Z", "end_time": "2020-05-16T16:11:23.077Z", "entries": [{"type": "log", "level": "error", "message": "Caught unexpected exception while running test: Traceback (most recent call last):\n  File \"c:\\users\\atpc8\\appdata\\local\\programs\\python\\python37\\lib\\site-packages\\urllib3\\connection.py\", line 157, in _new_conn\n    (self._dns_host, self.port), self.timeout, **extra_kw\n  File \"c:\\users\\atpc8\\appdata\\local\\programs\\python\\python37\\lib\\site-packages\\urllib3\\util\\connection.py\", line 61, in create_connection\n    for res in socket.getaddrinfo(host, port, family, socket.SOCK_STREAM):\n  File \"c:\\users\\atpc8\\appdata\\local\\programs\\python\\python37\\lib\\socket.py\", line 748, in getaddrinfo\n    for res in _socket.getaddrinfo(host, port, family, type, proto, flags):\nsocket.gaierror: [Errno 11001] getaddrinfo failed\n\nDuring handling of the above exception, another exception occurred:\n\nTraceback (most recent call last):\n  File \"c:\\users\\atpc8\\appdata\\local\\programs\\python\\python37\\lib\\site-packages\\urllib3\\connectionpool.py\", line 672, in urlopen\n    chunked=chunked,\n  File \"c:\\users\\atpc8\\appdata\\local\\programs\\python\\python37\\lib\\site-packages\\urllib3\\connectionpool.py\", line 387, in _make_request\n    conn.request(method, url, **httplib_request_kw)\n  File \"c:\\users\\atpc8\\appdata\\local\\programs\\python\\python37\\lib\\http\\client.py\", line 1229, in request\n    self._send_request(method, url, body, headers, encode_chunked)\n  File \"c:\\users\\atpc8\\appdata\\local\\programs\\python\\python37\\lib\\http\\client.py\", line 1275, in _send_request\n    self.endheaders(body, encode_chunked=encode_chunked)\n  File \"c:\\users\\atpc8\\appdata\\local\\programs\\python\\python37\\lib\\http\\client.py\", line 1224, in endheaders\n    self._send_output(message_body, encode_chunked=encode_chunked)\n  File \"c:\\users\\atpc8\\appdata\\local\\programs\\python\\python37\\lib\\http\\client.py\", line 1016, in _send_output\n    self.send(msg)\n  File \"c:\\users\\atpc8\\appdata\\local\\programs\\python\\python37\\lib\\http\\client.py\", line 956, in send\n    self.connect()\n  File \"c:\\users\\atpc8\\appdata\\local\\programs\\python\\python37\\lib\\site-packages\\urllib3\\connection.py\", line 184, in connect\n    conn = self._new_conn()\n  File \"c:\\users\\atpc8\\appdata\\local\\programs\\python\\python37\\lib\\site-packages\\urllib3\\connection.py\", line 169, in _new_conn\n    self, \"Failed to establish a new connection: %s\" % e\nurllib3.exceptions.NewConnectionError: <urllib3.connection.HTTPConnection object at 0x000002081E503EB8>: Failed to establish a new connection: [Errno 11001] getaddrinfo failed\n\nDuring handling of the above exception, another exception occurred:\n\nTraceback (most recent call last):\n  File \"c:\\users\\atpc8\\appdata\\local\\programs\\python\\python37\\lib\\site-packages\\requests\\adapters.py\", line 449, in send\n    timeout=timeout\n  File \"c:\\users\\atpc8\\appdata\\local\\programs\\python\\python37\\lib\\site-packages\\urllib3\\connectionpool.py\", line 720, in urlopen\n    method, url, error=e, _pool=self, _stacktrace=sys.exc_info()[2]\n  File \"c:\\users\\atpc8\\appdata\\local\\programs\\python\\python37\\lib\\site-packages\\urllib3\\util\\retry.py\", line 436, in increment\n    raise MaxRetryError(_pool, url, error or ResponseError(cause))\nurllib3.exceptions.MaxRetryError: HTTPConnectionPool(host='api.dev.compareking.no', port=80): Max retries exceeded with url: /api/application (Caused by NewConnectionError('<urllib3.connection.HTTPConnection object at 0x000002081E503EB8>: Failed to establish a new connection: [Errno 11001] getaddrinfo failed'))\n\nDuring handling of the above exception, another exception occurred:\n\nTraceback (most recent call last):\n  File \"c:\\users\\atpc8\\appdata\\local\\programs\\python\\python37\\lib\\site-packages\\lemoncheesecake\\runner.py\", line 188, in run\n    self.test.callback(**test_func_params)\n  File \"C:\\Users\\atpc8\\sdlc\\lemontest\\suites\\secondsuite.py\", line 80, in req4\n    headers=authenticate, data=payload)\n  File \"c:\\users\\atpc8\\appdata\\local\\programs\\python\\python37\\lib\\site-packages\\requests\\api.py\", line 116, in post\n    return request('post', url, data=data, json=json, **kwargs)\n  File \"c:\\users\\atpc8\\appdata\\local\\programs\\python\\python37\\lib\\site-packages\\requests\\api.py\", line 60, in request\n    return session.request(method=method, url=url, **kwargs)\n  File \"c:\\users\\atpc8\\appdata\\local\\programs\\python\\python37\\lib\\site-packages\\requests\\sessions.py\", line 533, in request\n    resp = self.send(prep, **send_kwargs)\n  File \"c:\\users\\atpc8\\appdata\\local\\programs\\python\\python37\\lib\\site-packages\\requests\\sessions.py\", line 646, in send\n    r = adapter.send(request, **kwargs)\n  File \"c:\\users\\atpc8\\appdata\\local\\programs\\python\\python37\\lib\\site-packages\\requests\\adapters.py\", line 516, in send\n    raise ConnectionError(e, request=request)\nrequests.exceptions.ConnectionError: HTTPConnectionPool(host='api.dev.compareking.no', port=80): Max retries exceeded with url: /api/application (Caused by NewConnectionError('<urllib3.connection.HTTPConnection object at 0x000002081E503EB8>: Failed to establish a new connection: [Errno 11001] getaddrinfo failed'))\n", "time": "2020-05-16T16:11:23.076Z"}]}], "status": "failed", "status_details": null, "name": "req4", "description": "req4", "tags": [], "properties": {}, "links": []}, {"start_time": "2020-05-16T16:11:23.077Z", "end_time": "2020-05-16T16:11:23.087Z", "steps": [{"description": "req5", "start_time": "2020-05-16T16:11:23.078Z", "end_time": "2020-05-16T16:11:23.087Z", "entries": [{"type": "log", "level": "error", "message": "Caught unexpected exception while running test: Traceback (most recent call last):\n  File \"c:\\users\\atpc8\\appdata\\local\\programs\\python\\python37\\lib\\site-packages\\urllib3\\connection.py\", line 157, in _new_conn\n    (self._dns_host, self.port), self.timeout, **extra_kw\n  File \"c:\\users\\atpc8\\appdata\\local\\programs\\python\\python37\\lib\\site-packages\\urllib3\\util\\connection.py\", line 61, in create_connection\n    for res in socket.getaddrinfo(host, port, family, socket.SOCK_STREAM):\n  File \"c:\\users\\atpc8\\appdata\\local\\programs\\python\\python37\\lib\\socket.py\", line 748, in getaddrinfo\n    for res in _socket.getaddrinfo(host, port, family, type, proto, flags):\nsocket.gaierror: [Errno 11001] getaddrinfo failed\n\nDuring handling of the above exception, another exception occurred:\n\nTraceback (most recent call last):\n  File \"c:\\users\\atpc8\\appdata\\local\\programs\\python\\python37\\lib\\site-packages\\urllib3\\connectionpool.py\", line 672, in urlopen\n    chunked=chunked,\n  File \"c:\\users\\atpc8\\appdata\\local\\programs\\python\\python37\\lib\\site-packages\\urllib3\\connectionpool.py\", line 387, in _make_request\n    conn.request(method, url, **httplib_request_kw)\n  File \"c:\\users\\atpc8\\appdata\\local\\programs\\python\\python37\\lib\\http\\client.py\", line 1229, in request\n    self._send_request(method, url, body, headers, encode_chunked)\n  File \"c:\\users\\atpc8\\appdata\\local\\programs\\python\\python37\\lib\\http\\client.py\", line 1275, in _send_request\n    self.endheaders(body, encode_chunked=encode_chunked)\n  File \"c:\\users\\atpc8\\appdata\\local\\programs\\python\\python37\\lib\\http\\client.py\", line 1224, in endheaders\n    self._send_output(message_body, encode_chunked=encode_chunked)\n  File \"c:\\users\\atpc8\\appdata\\local\\programs\\python\\python37\\lib\\http\\client.py\", line 1016, in _send_output\n    self.send(msg)\n  File \"c:\\users\\atpc8\\appdata\\local\\programs\\python\\python37\\lib\\http\\client.py\", line 956, in send\n    self.connect()\n  File \"c:\\users\\atpc8\\appdata\\local\\programs\\python\\python37\\lib\\site-packages\\urllib3\\connection.py\", line 184, in connect\n    conn = self._new_conn()\n  File \"c:\\users\\atpc8\\appdata\\local\\programs\\python\\python37\\lib\\site-packages\\urllib3\\connection.py\", line 169, in _new_conn\n    self, \"Failed to establish a new connection: %s\" % e\nurllib3.exceptions.NewConnectionError: <urllib3.connection.HTTPConnection object at 0x000002081E503FD0>: Failed to establish a new connection: [Errno 11001] getaddrinfo failed\n\nDuring handling of the above exception, another exception occurred:\n\nTraceback (most recent call last):\n  File \"c:\\users\\atpc8\\appdata\\local\\programs\\python\\python37\\lib\\site-packages\\requests\\adapters.py\", line 449, in send\n    timeout=timeout\n  File \"c:\\users\\atpc8\\appdata\\local\\programs\\python\\python37\\lib\\site-packages\\urllib3\\connectionpool.py\", line 720, in urlopen\n    method, url, error=e, _pool=self, _stacktrace=sys.exc_info()[2]\n  File \"c:\\users\\atpc8\\appdata\\local\\programs\\python\\python37\\lib\\site-packages\\urllib3\\util\\retry.py\", line 436, in increment\n    raise MaxRetryError(_pool, url, error or ResponseError(cause))\nurllib3.exceptions.MaxRetryError: HTTPConnectionPool(host='api.dev.compareking.no', port=80): Max retries exceeded with url: /api/application (Caused by NewConnectionError('<urllib3.connection.HTTPConnection object at 0x000002081E503FD0>: Failed to establish a new connection: [Errno 11001] getaddrinfo failed'))\n\nDuring handling of the above exception, another exception occurred:\n\nTraceback (most recent call last):\n  File \"c:\\users\\atpc8\\appdata\\local\\programs\\python\\python37\\lib\\site-packages\\lemoncheesecake\\runner.py\", line 188, in run\n    self.test.callback(**test_func_params)\n  File \"C:\\Users\\atpc8\\sdlc\\lemontest\\suites\\secondsuite.py\", line 142, in req5\n    headers=authenticate, data=payload)\n  File \"c:\\users\\atpc8\\appdata\\local\\programs\\python\\python37\\lib\\site-packages\\requests\\api.py\", line 116, in post\n    return request('post', url, data=data, json=json, **kwargs)\n  File \"c:\\users\\atpc8\\appdata\\local\\programs\\python\\python37\\lib\\site-packages\\requests\\api.py\", line 60, in request\n    return session.request(method=method, url=url, **kwargs)\n  File \"c:\\users\\atpc8\\appdata\\local\\programs\\python\\python37\\lib\\site-packages\\requests\\sessions.py\", line 533, in request\n    resp = self.send(prep, **send_kwargs)\n  File \"c:\\users\\atpc8\\appdata\\local\\programs\\python\\python37\\lib\\site-packages\\requests\\sessions.py\", line 646, in send\n    r = adapter.send(request, **kwargs)\n  File \"c:\\users\\atpc8\\appdata\\local\\programs\\python\\python37\\lib\\site-packages\\requests\\adapters.py\", line 516, in send\n    raise ConnectionError(e, request=request)\nrequests.exceptions.ConnectionError: HTTPConnectionPool(host='api.dev.compareking.no', port=80): Max retries exceeded with url: /api/application (Caused by NewConnectionError('<urllib3.connection.HTTPConnection object at 0x000002081E503FD0>: Failed to establish a new connection: [Errno 11001] getaddrinfo failed'))\n", "time": "2020-05-16T16:11:23.087Z"}]}], "status": "failed", "status_details": null, "name": "req5", "description": "req5", "tags": [], "properties": {}, "links": []}, {"start_time": "2020-05-16T16:11:23.090Z", "end_time": "2020-05-16T16:11:24.265Z", "steps": [{"description": "glc_auth_test", "start_time": "2020-05-16T16:11:23.090Z", "end_time": "2020-05-16T16:11:24.265Z", "entries": [{"type": "check", "description": "Expect http code to be equal to 200", "is_successful": false, "details": "Got 406", "time": "2020-05-16T16:11:24.258Z"}, {"type": "log", "level": "error", "message": "Caught unexpected exception while running test: Traceback (most recent call last):\n  File \"c:\\users\\atpc8\\appdata\\local\\programs\\python\\python37\\lib\\site-packages\\lemoncheesecake\\runner.py\", line 188, in run\n    self.test.callback(**test_func_params)\n  File \"C:\\Users\\atpc8\\sdlc\\lemontest\\suites\\secondsuite.py\", line 156, in glc_auth_test\n    resp1 = r.json()\n  File \"c:\\users\\atpc8\\appdata\\local\\programs\\python\\python37\\lib\\site-packages\\requests\\models.py\", line 897, in json\n    return complexjson.loads(self.text, **kwargs)\n  File \"c:\\users\\atpc8\\appdata\\local\\programs\\python\\python37\\lib\\json\\__init__.py\", line 348, in loads\n    return _default_decoder.decode(s)\n  File \"c:\\users\\atpc8\\appdata\\local\\programs\\python\\python37\\lib\\json\\decoder.py\", line 337, in decode\n    obj, end = self.raw_decode(s, idx=_w(s, 0).end())\n  File \"c:\\users\\atpc8\\appdata\\local\\programs\\python\\python37\\lib\\json\\decoder.py\", line 355, in raw_decode\n    raise JSONDecodeError(\"Expecting value\", s, err.value) from None\njson.decoder.JSONDecodeError: Expecting value: line 1 column 1 (char 0)\n", "time": "2020-05-16T16:11:24.265Z"}]}], "status": "failed", "status_details": null, "name": "glc_auth_test", "description": "glc_auth_test", "tags": ["glc"], "properties": {}, "links": []}], "suites": [], "name": "secondsuite", "description": "sec_suite", "tags": ["validation", "white labels"], "properties": {}, "links": []}, {"start_time": "2020-05-16T16:11:24.266Z", "end_time": "2020-05-16T16:11:24.290Z", "tests": [{"start_time": "2020-05-16T16:11:24.266Z", "end_time": "2020-05-16T16:11:24.273Z", "steps": [{"description": "Submit existing application or sent less than 3 months ago", "start_time": "2020-05-16T16:11:24.267Z", "end_time": "2020-05-16T16:11:24.273Z", "entries": [{"type": "log", "level": "error", "message": "Caught unexpected exception while running test: Traceback (most recent call last):\n  File \"c:\\users\\atpc8\\appdata\\local\\programs\\python\\python37\\lib\\site-packages\\urllib3\\connection.py\", line 157, in _new_conn\n    (self._dns_host, self.port), self.timeout, **extra_kw\n  File \"c:\\users\\atpc8\\appdata\\local\\programs\\python\\python37\\lib\\site-packages\\urllib3\\util\\connection.py\", line 61, in create_connection\n    for res in socket.getaddrinfo(host, port, family, socket.SOCK_STREAM):\n  File \"c:\\users\\atpc8\\appdata\\local\\programs\\python\\python37\\lib\\socket.py\", line 748, in getaddrinfo\n    for res in _socket.getaddrinfo(host, port, family, type, proto, flags):\nsocket.gaierror: [Errno 11001] getaddrinfo failed\n\nDuring handling of the above exception, another exception occurred:\n\nTraceback (most recent call last):\n  File \"c:\\users\\atpc8\\appdata\\local\\programs\\python\\python37\\lib\\site-packages\\urllib3\\connectionpool.py\", line 672, in urlopen\n    chunked=chunked,\n  File \"c:\\users\\atpc8\\appdata\\local\\programs\\python\\python37\\lib\\site-packages\\urllib3\\connectionpool.py\", line 387, in _make_request\n    conn.request(method, url, **httplib_request_kw)\n  File \"c:\\users\\atpc8\\appdata\\local\\programs\\python\\python37\\lib\\http\\client.py\", line 1229, in request\n    self._send_request(method, url, body, headers, encode_chunked)\n  File \"c:\\users\\atpc8\\appdata\\local\\programs\\python\\python37\\lib\\http\\client.py\", line 1275, in _send_request\n    self.endheaders(body, encode_chunked=encode_chunked)\n  File \"c:\\users\\atpc8\\appdata\\local\\programs\\python\\python37\\lib\\http\\client.py\", line 1224, in endheaders\n    self._send_output(message_body, encode_chunked=encode_chunked)\n  File \"c:\\users\\atpc8\\appdata\\local\\programs\\python\\python37\\lib\\http\\client.py\", line 1016, in _send_output\n    self.send(msg)\n  File \"c:\\users\\atpc8\\appdata\\local\\programs\\python\\python37\\lib\\http\\client.py\", line 956, in send\n    self.connect()\n  File \"c:\\users\\atpc8\\appdata\\local\\programs\\python\\python37\\lib\\site-packages\\urllib3\\connection.py\", line 184, in connect\n    conn = self._new_conn()\n  File \"c:\\users\\atpc8\\appdata\\local\\programs\\python\\python37\\lib\\site-packages\\urllib3\\connection.py\", line 169, in _new_conn\n    self, \"Failed to establish a new connection: %s\" % e\nurllib3.exceptions.NewConnectionError: <urllib3.connection.HTTPConnection object at 0x000002081E574748>: Failed to establish a new connection: [Errno 11001] getaddrinfo failed\n\nDuring handling of the above exception, another exception occurred:\n\nTraceback (most recent call last):\n  File \"c:\\users\\atpc8\\appdata\\local\\programs\\python\\python37\\lib\\site-packages\\requests\\adapters.py\", line 449, in send\n    timeout=timeout\n  File \"c:\\users\\atpc8\\appdata\\local\\programs\\python\\python37\\lib\\site-packages\\urllib3\\connectionpool.py\", line 720, in urlopen\n    method, url, error=e, _pool=self, _stacktrace=sys.exc_info()[2]\n  File \"c:\\users\\atpc8\\appdata\\local\\programs\\python\\python37\\lib\\site-packages\\urllib3\\util\\retry.py\", line 436, in increment\n    raise MaxRetryError(_pool, url, error or ResponseError(cause))\nurllib3.exceptions.MaxRetryError: HTTPConnectionPool(host='api.dev.compareking.no', port=80): Max retries exceeded with url: /api/application (Caused by NewConnectionError('<urllib3.connection.HTTPConnection object at 0x000002081E574748>: Failed to establish a new connection: [Errno 11001] getaddrinfo failed'))\n\nDuring handling of the above exception, another exception occurred:\n\nTraceback (most recent call last):\n  File \"c:\\users\\atpc8\\appdata\\local\\programs\\python\\python37\\lib\\site-packages\\lemoncheesecake\\runner.py\", line 188, in run\n    self.test.callback(**test_func_params)\n  File \"C:\\Users\\atpc8\\sdlc\\lemontest\\suites\\thirdsuite.py\", line 47, in req1\n    headers=auth_headers, data=payload)\n  File \"c:\\users\\atpc8\\appdata\\local\\programs\\python\\python37\\lib\\site-packages\\requests\\api.py\", line 116, in post\n    return request('post', url, data=data, json=json, **kwargs)\n  File \"c:\\users\\atpc8\\appdata\\local\\programs\\python\\python37\\lib\\site-packages\\requests\\api.py\", line 60, in request\n    return session.request(method=method, url=url, **kwargs)\n  File \"c:\\users\\atpc8\\appdata\\local\\programs\\python\\python37\\lib\\site-packages\\requests\\sessions.py\", line 533, in request\n    resp = self.send(prep, **send_kwargs)\n  File \"c:\\users\\atpc8\\appdata\\local\\programs\\python\\python37\\lib\\site-packages\\requests\\sessions.py\", line 646, in send\n    r = adapter.send(request, **kwargs)\n  File \"c:\\users\\atpc8\\appdata\\local\\programs\\python\\python37\\lib\\site-packages\\requests\\adapters.py\", line 516, in send\n    raise ConnectionError(e, request=request)\nrequests.exceptions.ConnectionError: HTTPConnectionPool(host='api.dev.compareking.no', port=80): Max retries exceeded with url: /api/application (Caused by NewConnectionError('<urllib3.connection.HTTPConnection object at 0x000002081E574748>: Failed to establish a new connection: [Errno 11001] getaddrinfo failed'))\n", "time": "2020-05-16T16:11:24.273Z"}]}], "status": "failed", "status_details": null, "name": "req1", "description": "Submit existing application or sent less than 3 months ago", "tags": [], "properties": {}, "links": []}, {"start_time": "2020-05-16T16:11:24.273Z", "end_time": "2020-05-16T16:11:24.279Z", "steps": [{"description": "Submit unfinished application with all required information", "start_time": "2020-05-16T16:11:24.274Z", "end_time": "2020-05-16T16:11:24.279Z", "entries": [{"type": "log", "level": "error", "message": "Caught unexpected exception while running test: Traceback (most recent call last):\n  File \"c:\\users\\atpc8\\appdata\\local\\programs\\python\\python37\\lib\\site-packages\\urllib3\\connection.py\", line 157, in _new_conn\n    (self._dns_host, self.port), self.timeout, **extra_kw\n  File \"c:\\users\\atpc8\\appdata\\local\\programs\\python\\python37\\lib\\site-packages\\urllib3\\util\\connection.py\", line 61, in create_connection\n    for res in socket.getaddrinfo(host, port, family, socket.SOCK_STREAM):\n  File \"c:\\users\\atpc8\\appdata\\local\\programs\\python\\python37\\lib\\socket.py\", line 748, in getaddrinfo\n    for res in _socket.getaddrinfo(host, port, family, type, proto, flags):\nsocket.gaierror: [Errno 11001] getaddrinfo failed\n\nDuring handling of the above exception, another exception occurred:\n\nTraceback (most recent call last):\n  File \"c:\\users\\atpc8\\appdata\\local\\programs\\python\\python37\\lib\\site-packages\\urllib3\\connectionpool.py\", line 672, in urlopen\n    chunked=chunked,\n  File \"c:\\users\\atpc8\\appdata\\local\\programs\\python\\python37\\lib\\site-packages\\urllib3\\connectionpool.py\", line 387, in _make_request\n    conn.request(method, url, **httplib_request_kw)\n  File \"c:\\users\\atpc8\\appdata\\local\\programs\\python\\python37\\lib\\http\\client.py\", line 1229, in request\n    self._send_request(method, url, body, headers, encode_chunked)\n  File \"c:\\users\\atpc8\\appdata\\local\\programs\\python\\python37\\lib\\http\\client.py\", line 1275, in _send_request\n    self.endheaders(body, encode_chunked=encode_chunked)\n  File \"c:\\users\\atpc8\\appdata\\local\\programs\\python\\python37\\lib\\http\\client.py\", line 1224, in endheaders\n    self._send_output(message_body, encode_chunked=encode_chunked)\n  File \"c:\\users\\atpc8\\appdata\\local\\programs\\python\\python37\\lib\\http\\client.py\", line 1016, in _send_output\n    self.send(msg)\n  File \"c:\\users\\atpc8\\appdata\\local\\programs\\python\\python37\\lib\\http\\client.py\", line 956, in send\n    self.connect()\n  File \"c:\\users\\atpc8\\appdata\\local\\programs\\python\\python37\\lib\\site-packages\\urllib3\\connection.py\", line 184, in connect\n    conn = self._new_conn()\n  File \"c:\\users\\atpc8\\appdata\\local\\programs\\python\\python37\\lib\\site-packages\\urllib3\\connection.py\", line 169, in _new_conn\n    self, \"Failed to establish a new connection: %s\" % e\nurllib3.exceptions.NewConnectionError: <urllib3.connection.HTTPConnection object at 0x000002081E5745C0>: Failed to establish a new connection: [Errno 11001] getaddrinfo failed\n\nDuring handling of the above exception, another exception occurred:\n\nTraceback (most recent call last):\n  File \"c:\\users\\atpc8\\appdata\\local\\programs\\python\\python37\\lib\\site-packages\\requests\\adapters.py\", line 449, in send\n    timeout=timeout\n  File \"c:\\users\\atpc8\\appdata\\local\\programs\\python\\python37\\lib\\site-packages\\urllib3\\connectionpool.py\", line 720, in urlopen\n    method, url, error=e, _pool=self, _stacktrace=sys.exc_info()[2]\n  File \"c:\\users\\atpc8\\appdata\\local\\programs\\python\\python37\\lib\\site-packages\\urllib3\\util\\retry.py\", line 436, in increment\n    raise MaxRetryError(_pool, url, error or ResponseError(cause))\nurllib3.exceptions.MaxRetryError: HTTPConnectionPool(host='api.dev.compareking.no', port=80): Max retries exceeded with url: /api/contact (Caused by NewConnectionError('<urllib3.connection.HTTPConnection object at 0x000002081E5745C0>: Failed to establish a new connection: [Errno 11001] getaddrinfo failed'))\n\nDuring handling of the above exception, another exception occurred:\n\nTraceback (most recent call last):\n  File \"c:\\users\\atpc8\\appdata\\local\\programs\\python\\python37\\lib\\site-packages\\lemoncheesecake\\runner.py\", line 188, in run\n    self.test.callback(**test_func_params)\n  File \"C:\\Users\\atpc8\\sdlc\\lemontest\\suites\\thirdsuite.py\", line 64, in req2\n    headers=auth_headers, json=payload)\n  File \"c:\\users\\atpc8\\appdata\\local\\programs\\python\\python37\\lib\\site-packages\\requests\\api.py\", line 116, in post\n    return request('post', url, data=data, json=json, **kwargs)\n  File \"c:\\users\\atpc8\\appdata\\local\\programs\\python\\python37\\lib\\site-packages\\requests\\api.py\", line 60, in request\n    return session.request(method=method, url=url, **kwargs)\n  File \"c:\\users\\atpc8\\appdata\\local\\programs\\python\\python37\\lib\\site-packages\\requests\\sessions.py\", line 533, in request\n    resp = self.send(prep, **send_kwargs)\n  File \"c:\\users\\atpc8\\appdata\\local\\programs\\python\\python37\\lib\\site-packages\\requests\\sessions.py\", line 646, in send\n    r = adapter.send(request, **kwargs)\n  File \"c:\\users\\atpc8\\appdata\\local\\programs\\python\\python37\\lib\\site-packages\\requests\\adapters.py\", line 516, in send\n    raise ConnectionError(e, request=request)\nrequests.exceptions.ConnectionError: HTTPConnectionPool(host='api.dev.compareking.no', port=80): Max retries exceeded with url: /api/contact (Caused by NewConnectionError('<urllib3.connection.HTTPConnection object at 0x000002081E5745C0>: Failed to establish a new connection: [Errno 11001] getaddrinfo failed'))\n", "time": "2020-05-16T16:11:24.279Z"}]}], "status": "failed", "status_details": null, "name": "req2", "description": "Submit unfinished application with all required information", "tags": [], "properties": {}, "links": []}, {"start_time": "2020-05-16T16:11:24.279Z", "end_time": "2020-05-16T16:11:24.286Z", "steps": [{"description": "Submit unfinished application with incomplete required info", "start_time": "2020-05-16T16:11:24.280Z", "end_time": "2020-05-16T16:11:24.286Z", "entries": [{"type": "log", "level": "error", "message": "Caught unexpected exception while running test: Traceback (most recent call last):\n  File \"c:\\users\\atpc8\\appdata\\local\\programs\\python\\python37\\lib\\site-packages\\urllib3\\connection.py\", line 157, in _new_conn\n    (self._dns_host, self.port), self.timeout, **extra_kw\n  File \"c:\\users\\atpc8\\appdata\\local\\programs\\python\\python37\\lib\\site-packages\\urllib3\\util\\connection.py\", line 61, in create_connection\n    for res in socket.getaddrinfo(host, port, family, socket.SOCK_STREAM):\n  File \"c:\\users\\atpc8\\appdata\\local\\programs\\python\\python37\\lib\\socket.py\", line 748, in getaddrinfo\n    for res in _socket.getaddrinfo(host, port, family, type, proto, flags):\nsocket.gaierror: [Errno 11001] getaddrinfo failed\n\nDuring handling of the above exception, another exception occurred:\n\nTraceback (most recent call last):\n  File \"c:\\users\\atpc8\\appdata\\local\\programs\\python\\python37\\lib\\site-packages\\urllib3\\connectionpool.py\", line 672, in urlopen\n    chunked=chunked,\n  File \"c:\\users\\atpc8\\appdata\\local\\programs\\python\\python37\\lib\\site-packages\\urllib3\\connectionpool.py\", line 387, in _make_request\n    conn.request(method, url, **httplib_request_kw)\n  File \"c:\\users\\atpc8\\appdata\\local\\programs\\python\\python37\\lib\\http\\client.py\", line 1229, in request\n    self._send_request(method, url, body, headers, encode_chunked)\n  File \"c:\\users\\atpc8\\appdata\\local\\programs\\python\\python37\\lib\\http\\client.py\", line 1275, in _send_request\n    self.endheaders(body, encode_chunked=encode_chunked)\n  File \"c:\\users\\atpc8\\appdata\\local\\programs\\python\\python37\\lib\\http\\client.py\", line 1224, in endheaders\n    self._send_output(message_body, encode_chunked=encode_chunked)\n  File \"c:\\users\\atpc8\\appdata\\local\\programs\\python\\python37\\lib\\http\\client.py\", line 1016, in _send_output\n    self.send(msg)\n  File \"c:\\users\\atpc8\\appdata\\local\\programs\\python\\python37\\lib\\http\\client.py\", line 956, in send\n    self.connect()\n  File \"c:\\users\\atpc8\\appdata\\local\\programs\\python\\python37\\lib\\site-packages\\urllib3\\connection.py\", line 184, in connect\n    conn = self._new_conn()\n  File \"c:\\users\\atpc8\\appdata\\local\\programs\\python\\python37\\lib\\site-packages\\urllib3\\connection.py\", line 169, in _new_conn\n    self, \"Failed to establish a new connection: %s\" % e\nurllib3.exceptions.NewConnectionError: <urllib3.connection.HTTPConnection object at 0x000002081E574128>: Failed to establish a new connection: [Errno 11001] getaddrinfo failed\n\nDuring handling of the above exception, another exception occurred:\n\nTraceback (most recent call last):\n  File \"c:\\users\\atpc8\\appdata\\local\\programs\\python\\python37\\lib\\site-packages\\requests\\adapters.py\", line 449, in send\n    timeout=timeout\n  File \"c:\\users\\atpc8\\appdata\\local\\programs\\python\\python37\\lib\\site-packages\\urllib3\\connectionpool.py\", line 720, in urlopen\n    method, url, error=e, _pool=self, _stacktrace=sys.exc_info()[2]\n  File \"c:\\users\\atpc8\\appdata\\local\\programs\\python\\python37\\lib\\site-packages\\urllib3\\util\\retry.py\", line 436, in increment\n    raise MaxRetryError(_pool, url, error or ResponseError(cause))\nurllib3.exceptions.MaxRetryError: HTTPConnectionPool(host='api.dev.compareking.no', port=80): Max retries exceeded with url: /api/contact (Caused by NewConnectionError('<urllib3.connection.HTTPConnection object at 0x000002081E574128>: Failed to establish a new connection: [Errno 11001] getaddrinfo failed'))\n\nDuring handling of the above exception, another exception occurred:\n\nTraceback (most recent call last):\n  File \"c:\\users\\atpc8\\appdata\\local\\programs\\python\\python37\\lib\\site-packages\\lemoncheesecake\\runner.py\", line 188, in run\n    self.test.callback(**test_func_params)\n  File \"C:\\Users\\atpc8\\sdlc\\lemontest\\suites\\thirdsuite.py\", line 81, in req3\n    headers=auth_headers, json=payload)\n  File \"c:\\users\\atpc8\\appdata\\local\\programs\\python\\python37\\lib\\site-packages\\requests\\api.py\", line 116, in post\n    return request('post', url, data=data, json=json, **kwargs)\n  File \"c:\\users\\atpc8\\appdata\\local\\programs\\python\\python37\\lib\\site-packages\\requests\\api.py\", line 60, in request\n    return session.request(method=method, url=url, **kwargs)\n  File \"c:\\users\\atpc8\\appdata\\local\\programs\\python\\python37\\lib\\site-packages\\requests\\sessions.py\", line 533, in request\n    resp = self.send(prep, **send_kwargs)\n  File \"c:\\users\\atpc8\\appdata\\local\\programs\\python\\python37\\lib\\site-packages\\requests\\sessions.py\", line 646, in send\n    r = adapter.send(request, **kwargs)\n  File \"c:\\users\\atpc8\\appdata\\local\\programs\\python\\python37\\lib\\site-packages\\requests\\adapters.py\", line 516, in send\n    raise ConnectionError(e, request=request)\nrequests.exceptions.ConnectionError: HTTPConnectionPool(host='api.dev.compareking.no', port=80): Max retries exceeded with url: /api/contact (Caused by NewConnectionError('<urllib3.connection.HTTPConnection object at 0x000002081E574128>: Failed to establish a new connection: [Errno 11001] getaddrinfo failed'))\n", "time": "2020-05-16T16:11:24.286Z"}]}], "status": "failed", "status_details": null, "name": "req3", "description": "Submit unfinished application with incomplete required info", "tags": [], "properties": {}, "links": []}, {"start_time": "2020-05-16T16:11:24.286Z", "end_time": "2020-05-16T16:11:24.290Z", "steps": [{"description": "Submit unfinished application that already exists", "start_time": "2020-05-16T16:11:24.286Z", "end_time": "2020-05-16T16:11:24.290Z", "entries": [{"type": "log", "level": "error", "message": "Caught unexpected exception while running test: Traceback (most recent call last):\n  File \"c:\\users\\atpc8\\appdata\\local\\programs\\python\\python37\\lib\\site-packages\\urllib3\\connection.py\", line 157, in _new_conn\n    (self._dns_host, self.port), self.timeout, **extra_kw\n  File \"c:\\users\\atpc8\\appdata\\local\\programs\\python\\python37\\lib\\site-packages\\urllib3\\util\\connection.py\", line 61, in create_connection\n    for res in socket.getaddrinfo(host, port, family, socket.SOCK_STREAM):\n  File \"c:\\users\\atpc8\\appdata\\local\\programs\\python\\python37\\lib\\socket.py\", line 748, in getaddrinfo\n    for res in _socket.getaddrinfo(host, port, family, type, proto, flags):\nsocket.gaierror: [Errno 11001] getaddrinfo failed\n\nDuring handling of the above exception, another exception occurred:\n\nTraceback (most recent call last):\n  File \"c:\\users\\atpc8\\appdata\\local\\programs\\python\\python37\\lib\\site-packages\\urllib3\\connectionpool.py\", line 672, in urlopen\n    chunked=chunked,\n  File \"c:\\users\\atpc8\\appdata\\local\\programs\\python\\python37\\lib\\site-packages\\urllib3\\connectionpool.py\", line 387, in _make_request\n    conn.request(method, url, **httplib_request_kw)\n  File \"c:\\users\\atpc8\\appdata\\local\\programs\\python\\python37\\lib\\http\\client.py\", line 1229, in request\n    self._send_request(method, url, body, headers, encode_chunked)\n  File \"c:\\users\\atpc8\\appdata\\local\\programs\\python\\python37\\lib\\http\\client.py\", line 1275, in _send_request\n    self.endheaders(body, encode_chunked=encode_chunked)\n  File \"c:\\users\\atpc8\\appdata\\local\\programs\\python\\python37\\lib\\http\\client.py\", line 1224, in endheaders\n    self._send_output(message_body, encode_chunked=encode_chunked)\n  File \"c:\\users\\atpc8\\appdata\\local\\programs\\python\\python37\\lib\\http\\client.py\", line 1016, in _send_output\n    self.send(msg)\n  File \"c:\\users\\atpc8\\appdata\\local\\programs\\python\\python37\\lib\\http\\client.py\", line 956, in send\n    self.connect()\n  File \"c:\\users\\atpc8\\appdata\\local\\programs\\python\\python37\\lib\\site-packages\\urllib3\\connection.py\", line 184, in connect\n    conn = self._new_conn()\n  File \"c:\\users\\atpc8\\appdata\\local\\programs\\python\\python37\\lib\\site-packages\\urllib3\\connection.py\", line 169, in _new_conn\n    self, \"Failed to establish a new connection: %s\" % e\nurllib3.exceptions.NewConnectionError: <urllib3.connection.HTTPConnection object at 0x000002081E574CC0>: Failed to establish a new connection: [Errno 11001] getaddrinfo failed\n\nDuring handling of the above exception, another exception occurred:\n\nTraceback (most recent call last):\n  File \"c:\\users\\atpc8\\appdata\\local\\programs\\python\\python37\\lib\\site-packages\\requests\\adapters.py\", line 449, in send\n    timeout=timeout\n  File \"c:\\users\\atpc8\\appdata\\local\\programs\\python\\python37\\lib\\site-packages\\urllib3\\connectionpool.py\", line 720, in urlopen\n    method, url, error=e, _pool=self, _stacktrace=sys.exc_info()[2]\n  File \"c:\\users\\atpc8\\appdata\\local\\programs\\python\\python37\\lib\\site-packages\\urllib3\\util\\retry.py\", line 436, in increment\n    raise MaxRetryError(_pool, url, error or ResponseError(cause))\nurllib3.exceptions.MaxRetryError: HTTPConnectionPool(host='api.dev.compareking.no', port=80): Max retries exceeded with url: /api/contact (Caused by NewConnectionError('<urllib3.connection.HTTPConnection object at 0x000002081E574CC0>: Failed to establish a new connection: [Errno 11001] getaddrinfo failed'))\n\nDuring handling of the above exception, another exception occurred:\n\nTraceback (most recent call last):\n  File \"c:\\users\\atpc8\\appdata\\local\\programs\\python\\python37\\lib\\site-packages\\lemoncheesecake\\runner.py\", line 188, in run\n    self.test.callback(**test_func_params)\n  File \"C:\\Users\\atpc8\\sdlc\\lemontest\\suites\\thirdsuite.py\", line 97, in req4\n    headers=auth_headers, json=payload)\n  File \"c:\\users\\atpc8\\appdata\\local\\programs\\python\\python37\\lib\\site-packages\\requests\\api.py\", line 116, in post\n    return request('post', url, data=data, json=json, **kwargs)\n  File \"c:\\users\\atpc8\\appdata\\local\\programs\\python\\python37\\lib\\site-packages\\requests\\api.py\", line 60, in request\n    return session.request(method=method, url=url, **kwargs)\n  File \"c:\\users\\atpc8\\appdata\\local\\programs\\python\\python37\\lib\\site-packages\\requests\\sessions.py\", line 533, in request\n    resp = self.send(prep, **send_kwargs)\n  File \"c:\\users\\atpc8\\appdata\\local\\programs\\python\\python37\\lib\\site-packages\\requests\\sessions.py\", line 646, in send\n    r = adapter.send(request, **kwargs)\n  File \"c:\\users\\atpc8\\appdata\\local\\programs\\python\\python37\\lib\\site-packages\\requests\\adapters.py\", line 516, in send\n    raise ConnectionError(e, request=request)\nrequests.exceptions.ConnectionError: HTTPConnectionPool(host='api.dev.compareking.no', port=80): Max retries exceeded with url: /api/contact (Caused by NewConnectionError('<urllib3.connection.HTTPConnection object at 0x000002081E574CC0>: Failed to establish a new connection: [Errno 11001] getaddrinfo failed'))\n", "time": "2020-05-16T16:11:24.290Z"}]}], "status": "failed", "status_details": null, "name": "req4", "description": "Submit unfinished application that already exists", "tags": [], "properties": {}, "links": []}], "suites": [], "name": "thirdsuite", "description": "my_suite", "tags": [], "properties": {}, "links": []}, {"start_time": "2020-05-16T16:11:24.290Z", "end_time": "2020-05-16T16:11:25.033Z", "tests": [{"start_time": "2020-05-16T16:11:24.290Z", "end_time": "2020-05-16T16:11:25.033Z", "steps": [{"description": "glc_auth_test", "start_time": "2020-05-16T16:11:24.291Z", "end_time": "2020-05-16T16:11:25.033Z", "entries": [{"type": "check", "description": "Expect http code to be equal to 200", "is_successful": false, "details": "Got 406", "time": "2020-05-16T16:11:25.018Z"}, {"type": "log", "level": "error", "message": "Caught unexpected exception while running test: Traceback (most recent call last):\n  File \"c:\\users\\atpc8\\appdata\\local\\programs\\python\\python37\\lib\\site-packages\\lemoncheesecake\\runner.py\", line 188, in run\n    self.test.callback(**test_func_params)\n  File \"C:\\Users\\atpc8\\sdlc\\lemontest\\suites\\tuisuite.py\", line 20, in glc_auth_test\n    resp1 = r.json()\n  File \"c:\\users\\atpc8\\appdata\\local\\programs\\python\\python37\\lib\\site-packages\\requests\\models.py\", line 897, in json\n    return complexjson.loads(self.text, **kwargs)\n  File \"c:\\users\\atpc8\\appdata\\local\\programs\\python\\python37\\lib\\json\\__init__.py\", line 348, in loads\n    return _default_decoder.decode(s)\n  File \"c:\\users\\atpc8\\appdata\\local\\programs\\python\\python37\\lib\\json\\decoder.py\", line 337, in decode\n    obj, end = self.raw_decode(s, idx=_w(s, 0).end())\n  File \"c:\\users\\atpc8\\appdata\\local\\programs\\python\\python37\\lib\\json\\decoder.py\", line 355, in raw_decode\n    raise JSONDecodeError(\"Expecting value\", s, err.value) from None\njson.decoder.JSONDecodeError: Expecting value: line 1 column 1 (char 0)\n", "time": "2020-05-16T16:11:25.032Z"}]}], "status": "failed", "status_details": null, "name": "glc_auth_test", "description": "glc_auth_test", "tags": ["glc"], "properties": {}, "links": []}], "suites": [], "name": "tuisuite", "description": "GLC test", "tags": [], "properties": {}, "links": []}]}