var reporting_data = {"lemoncheesecake_version": "1.3.1", "report_version": 1.1, "start_time": "2020-05-06T08:34:28.803Z", "end_time": "2020-05-06T08:34:39.958Z", "generation_time": "2020-05-06T08:34:40.080Z", "nb_threads": 1, "title": "Test Report", "info": [["Command line", "lcc run"]], "suites": [{"start_time": "2020-05-06T08:34:28.809Z", "end_time": "2020-05-06T08:34:39.876Z", "tests": [{"start_time": "2020-05-06T08:34:28.809Z", "end_time": "2020-05-06T08:34:28.809Z", "steps": [{"description": "test1", "start_time": "2020-05-06T08:34:28.809Z", "end_time": "2020-05-06T08:34:28.809Z", "entries": [{"type": "check", "description": "Expect value to be equal to 4.0", "is_successful": true, "details": "Got 4", "time": "2020-05-06T08:34:28.809Z"}]}], "status": "passed", "status_details": null, "name": "test1", "description": "test1", "tags": [], "properties": {}, "links": []}, {"start_time": "2020-05-06T08:34:28.809Z", "end_time": "2020-05-06T08:34:28.810Z", "steps": [], "status": "passed", "status_details": null, "name": "test2", "description": "test2", "tags": [], "properties": {}, "links": []}, {"start_time": "2020-05-06T08:34:28.810Z", "end_time": "2020-05-06T08:34:39.876Z", "steps": [{"description": "test3", "start_time": "2020-05-06T08:34:28.810Z", "end_time": "2020-05-06T08:34:39.876Z", "entries": [{"type": "log", "level": "error", "message": "Caught unexpected exception while running test: Traceback (most recent call last):\n  File \"c:\\users\\atpc8\\appdata\\local\\programs\\python\\python37\\lib\\site-packages\\urllib3\\connection.py\", line 157, in _new_conn\n    (self._dns_host, self.port), self.timeout, **extra_kw\n  File \"c:\\users\\atpc8\\appdata\\local\\programs\\python\\python37\\lib\\site-packages\\urllib3\\util\\connection.py\", line 61, in create_connection\n    for res in socket.getaddrinfo(host, port, family, socket.SOCK_STREAM):\n  File \"c:\\users\\atpc8\\appdata\\local\\programs\\python\\python37\\lib\\socket.py\", line 748, in getaddrinfo\n    for res in _socket.getaddrinfo(host, port, family, type, proto, flags):\nsocket.gaierror: [Errno 11001] getaddrinfo failed\n\nDuring handling of the above exception, another exception occurred:\n\nTraceback (most recent call last):\n  File \"c:\\users\\atpc8\\appdata\\local\\programs\\python\\python37\\lib\\site-packages\\urllib3\\connectionpool.py\", line 672, in urlopen\n    chunked=chunked,\n  File \"c:\\users\\atpc8\\appdata\\local\\programs\\python\\python37\\lib\\site-packages\\urllib3\\connectionpool.py\", line 376, in _make_request\n    self._validate_conn(conn)\n  File \"c:\\users\\atpc8\\appdata\\local\\programs\\python\\python37\\lib\\site-packages\\urllib3\\connectionpool.py\", line 994, in _validate_conn\n    conn.connect()\n  File \"c:\\users\\atpc8\\appdata\\local\\programs\\python\\python37\\lib\\site-packages\\urllib3\\connection.py\", line 334, in connect\n    conn = self._new_conn()\n  File \"c:\\users\\atpc8\\appdata\\local\\programs\\python\\python37\\lib\\site-packages\\urllib3\\connection.py\", line 169, in _new_conn\n    self, \"Failed to establish a new connection: %s\" % e\nurllib3.exceptions.NewConnectionError: <urllib3.connection.VerifiedHTTPSConnection object at 0x0000024D84C8EA58>: Failed to establish a new connection: [Errno 11001] getaddrinfo failed\n\nDuring handling of the above exception, another exception occurred:\n\nTraceback (most recent call last):\n  File \"c:\\users\\atpc8\\appdata\\local\\programs\\python\\python37\\lib\\site-packages\\requests\\adapters.py\", line 449, in send\n    timeout=timeout\n  File \"c:\\users\\atpc8\\appdata\\local\\programs\\python\\python37\\lib\\site-packages\\urllib3\\connectionpool.py\", line 720, in urlopen\n    method, url, error=e, _pool=self, _stacktrace=sys.exc_info()[2]\n  File \"c:\\users\\atpc8\\appdata\\local\\programs\\python\\python37\\lib\\site-packages\\urllib3\\util\\retry.py\", line 436, in increment\n    raise MaxRetryError(_pool, url, error or ResponseError(cause))\nurllib3.exceptions.MaxRetryError: HTTPSConnectionPool(host='jsonplaceholder.typicode.com', port=443): Max retries exceeded with url: / (Caused by NewConnectionError('<urllib3.connection.VerifiedHTTPSConnection object at 0x0000024D84C8EA58>: Failed to establish a new connection: [Errno 11001] getaddrinfo failed'))\n\nDuring handling of the above exception, another exception occurred:\n\nTraceback (most recent call last):\n  File \"c:\\users\\atpc8\\appdata\\local\\programs\\python\\python37\\lib\\site-packages\\lemoncheesecake\\runner.py\", line 188, in run\n    self.test.callback(**test_func_params)\n  File \"C:\\Users\\atpc8\\sdlc\\lemontest\\suites\\firstsuite.py\", line 21, in test3\n    r = requests.get('https://jsonplaceholder.typicode.com')\n  File \"c:\\users\\atpc8\\appdata\\local\\programs\\python\\python37\\lib\\site-packages\\requests\\api.py\", line 75, in get\n    return request('get', url, params=params, **kwargs)\n  File \"c:\\users\\atpc8\\appdata\\local\\programs\\python\\python37\\lib\\site-packages\\requests\\api.py\", line 60, in request\n    return session.request(method=method, url=url, **kwargs)\n  File \"c:\\users\\atpc8\\appdata\\local\\programs\\python\\python37\\lib\\site-packages\\requests\\sessions.py\", line 533, in request\n    resp = self.send(prep, **send_kwargs)\n  File \"c:\\users\\atpc8\\appdata\\local\\programs\\python\\python37\\lib\\site-packages\\requests\\sessions.py\", line 646, in send\n    r = adapter.send(request, **kwargs)\n  File \"c:\\users\\atpc8\\appdata\\local\\programs\\python\\python37\\lib\\site-packages\\requests\\adapters.py\", line 516, in send\n    raise ConnectionError(e, request=request)\nrequests.exceptions.ConnectionError: HTTPSConnectionPool(host='jsonplaceholder.typicode.com', port=443): Max retries exceeded with url: / (Caused by NewConnectionError('<urllib3.connection.VerifiedHTTPSConnection object at 0x0000024D84C8EA58>: Failed to establish a new connection: [Errno 11001] getaddrinfo failed'))\n", "time": "2020-05-06T08:34:39.875Z"}]}], "status": "failed", "status_details": null, "name": "test3", "description": "test3", "tags": [], "properties": {}, "links": []}], "suites": [], "name": "firstsuite", "description": "my_suite", "tags": ["samples", "tutorials"], "properties": {}, "links": []}, {"start_time": "2020-05-06T08:34:39.876Z", "end_time": "2020-05-06T08:34:39.914Z", "tests": [{"start_time": "2020-05-06T08:34:39.876Z", "end_time": "2020-05-06T08:34:39.882Z", "steps": [{"description": "req1", "start_time": "2020-05-06T08:34:39.876Z", "end_time": "2020-05-06T08:34:39.882Z", "entries": [{"type": "url", "description": "This is first shoot in this suite!!!", "url": "http://api.dev.compareking.no/api/application/111", "time": "2020-05-06T08:34:39.876Z"}, {"type": "log", "level": "error", "message": "Caught unexpected exception while running test: Traceback (most recent call last):\n  File \"c:\\users\\atpc8\\appdata\\local\\programs\\python\\python37\\lib\\site-packages\\urllib3\\connection.py\", line 157, in _new_conn\n    (self._dns_host, self.port), self.timeout, **extra_kw\n  File \"c:\\users\\atpc8\\appdata\\local\\programs\\python\\python37\\lib\\site-packages\\urllib3\\util\\connection.py\", line 61, in create_connection\n    for res in socket.getaddrinfo(host, port, family, socket.SOCK_STREAM):\n  File \"c:\\users\\atpc8\\appdata\\local\\programs\\python\\python37\\lib\\socket.py\", line 748, in getaddrinfo\n    for res in _socket.getaddrinfo(host, port, family, type, proto, flags):\nsocket.gaierror: [Errno 11001] getaddrinfo failed\n\nDuring handling of the above exception, another exception occurred:\n\nTraceback (most recent call last):\n  File \"c:\\users\\atpc8\\appdata\\local\\programs\\python\\python37\\lib\\site-packages\\urllib3\\connectionpool.py\", line 672, in urlopen\n    chunked=chunked,\n  File \"c:\\users\\atpc8\\appdata\\local\\programs\\python\\python37\\lib\\site-packages\\urllib3\\connectionpool.py\", line 387, in _make_request\n    conn.request(method, url, **httplib_request_kw)\n  File \"c:\\users\\atpc8\\appdata\\local\\programs\\python\\python37\\lib\\http\\client.py\", line 1229, in request\n    self._send_request(method, url, body, headers, encode_chunked)\n  File \"c:\\users\\atpc8\\appdata\\local\\programs\\python\\python37\\lib\\http\\client.py\", line 1275, in _send_request\n    self.endheaders(body, encode_chunked=encode_chunked)\n  File \"c:\\users\\atpc8\\appdata\\local\\programs\\python\\python37\\lib\\http\\client.py\", line 1224, in endheaders\n    self._send_output(message_body, encode_chunked=encode_chunked)\n  File \"c:\\users\\atpc8\\appdata\\local\\programs\\python\\python37\\lib\\http\\client.py\", line 1016, in _send_output\n    self.send(msg)\n  File \"c:\\users\\atpc8\\appdata\\local\\programs\\python\\python37\\lib\\http\\client.py\", line 956, in send\n    self.connect()\n  File \"c:\\users\\atpc8\\appdata\\local\\programs\\python\\python37\\lib\\site-packages\\urllib3\\connection.py\", line 184, in connect\n    conn = self._new_conn()\n  File \"c:\\users\\atpc8\\appdata\\local\\programs\\python\\python37\\lib\\site-packages\\urllib3\\connection.py\", line 169, in _new_conn\n    self, \"Failed to establish a new connection: %s\" % e\nurllib3.exceptions.NewConnectionError: <urllib3.connection.HTTPConnection object at 0x0000024D84CB9BA8>: Failed to establish a new connection: [Errno 11001] getaddrinfo failed\n\nDuring handling of the above exception, another exception occurred:\n\nTraceback (most recent call last):\n  File \"c:\\users\\atpc8\\appdata\\local\\programs\\python\\python37\\lib\\site-packages\\requests\\adapters.py\", line 449, in send\n    timeout=timeout\n  File \"c:\\users\\atpc8\\appdata\\local\\programs\\python\\python37\\lib\\site-packages\\urllib3\\connectionpool.py\", line 720, in urlopen\n    method, url, error=e, _pool=self, _stacktrace=sys.exc_info()[2]\n  File \"c:\\users\\atpc8\\appdata\\local\\programs\\python\\python37\\lib\\site-packages\\urllib3\\util\\retry.py\", line 436, in increment\n    raise MaxRetryError(_pool, url, error or ResponseError(cause))\nurllib3.exceptions.MaxRetryError: HTTPConnectionPool(host='api.dev.compareking.no', port=80): Max retries exceeded with url: /api/application/111 (Caused by NewConnectionError('<urllib3.connection.HTTPConnection object at 0x0000024D84CB9BA8>: Failed to establish a new connection: [Errno 11001] getaddrinfo failed'))\n\nDuring handling of the above exception, another exception occurred:\n\nTraceback (most recent call last):\n  File \"c:\\users\\atpc8\\appdata\\local\\programs\\python\\python37\\lib\\site-packages\\lemoncheesecake\\runner.py\", line 188, in run\n    self.test.callback(**test_func_params)\n  File \"C:\\Users\\atpc8\\sdlc\\lemontest\\suites\\secondsuite.py\", line 17, in req1\n    headers=authenticate)\n  File \"c:\\users\\atpc8\\appdata\\local\\programs\\python\\python37\\lib\\site-packages\\requests\\api.py\", line 75, in get\n    return request('get', url, params=params, **kwargs)\n  File \"c:\\users\\atpc8\\appdata\\local\\programs\\python\\python37\\lib\\site-packages\\requests\\api.py\", line 60, in request\n    return session.request(method=method, url=url, **kwargs)\n  File \"c:\\users\\atpc8\\appdata\\local\\programs\\python\\python37\\lib\\site-packages\\requests\\sessions.py\", line 533, in request\n    resp = self.send(prep, **send_kwargs)\n  File \"c:\\users\\atpc8\\appdata\\local\\programs\\python\\python37\\lib\\site-packages\\requests\\sessions.py\", line 646, in send\n    r = adapter.send(request, **kwargs)\n  File \"c:\\users\\atpc8\\appdata\\local\\programs\\python\\python37\\lib\\site-packages\\requests\\adapters.py\", line 516, in send\n    raise ConnectionError(e, request=request)\nrequests.exceptions.ConnectionError: HTTPConnectionPool(host='api.dev.compareking.no', port=80): Max retries exceeded with url: /api/application/111 (Caused by NewConnectionError('<urllib3.connection.HTTPConnection object at 0x0000024D84CB9BA8>: Failed to establish a new connection: [Errno 11001] getaddrinfo failed'))\n", "time": "2020-05-06T08:34:39.882Z"}]}], "status": "failed", "status_details": null, "name": "req1", "description": "req1", "tags": [], "properties": {}, "links": []}, {"start_time": "2020-05-06T08:34:39.883Z", "end_time": "2020-05-06T08:34:39.888Z", "steps": [{"description": "req2", "start_time": "2020-05-06T08:34:39.883Z", "end_time": "2020-05-06T08:34:39.888Z", "entries": [{"type": "log", "level": "error", "message": "Caught unexpected exception while running test: Traceback (most recent call last):\n  File \"c:\\users\\atpc8\\appdata\\local\\programs\\python\\python37\\lib\\site-packages\\urllib3\\connection.py\", line 157, in _new_conn\n    (self._dns_host, self.port), self.timeout, **extra_kw\n  File \"c:\\users\\atpc8\\appdata\\local\\programs\\python\\python37\\lib\\site-packages\\urllib3\\util\\connection.py\", line 61, in create_connection\n    for res in socket.getaddrinfo(host, port, family, socket.SOCK_STREAM):\n  File \"c:\\users\\atpc8\\appdata\\local\\programs\\python\\python37\\lib\\socket.py\", line 748, in getaddrinfo\n    for res in _socket.getaddrinfo(host, port, family, type, proto, flags):\nsocket.gaierror: [Errno 11001] getaddrinfo failed\n\nDuring handling of the above exception, another exception occurred:\n\nTraceback (most recent call last):\n  File \"c:\\users\\atpc8\\appdata\\local\\programs\\python\\python37\\lib\\site-packages\\urllib3\\connectionpool.py\", line 672, in urlopen\n    chunked=chunked,\n  File \"c:\\users\\atpc8\\appdata\\local\\programs\\python\\python37\\lib\\site-packages\\urllib3\\connectionpool.py\", line 387, in _make_request\n    conn.request(method, url, **httplib_request_kw)\n  File \"c:\\users\\atpc8\\appdata\\local\\programs\\python\\python37\\lib\\http\\client.py\", line 1229, in request\n    self._send_request(method, url, body, headers, encode_chunked)\n  File \"c:\\users\\atpc8\\appdata\\local\\programs\\python\\python37\\lib\\http\\client.py\", line 1275, in _send_request\n    self.endheaders(body, encode_chunked=encode_chunked)\n  File \"c:\\users\\atpc8\\appdata\\local\\programs\\python\\python37\\lib\\http\\client.py\", line 1224, in endheaders\n    self._send_output(message_body, encode_chunked=encode_chunked)\n  File \"c:\\users\\atpc8\\appdata\\local\\programs\\python\\python37\\lib\\http\\client.py\", line 1016, in _send_output\n    self.send(msg)\n  File \"c:\\users\\atpc8\\appdata\\local\\programs\\python\\python37\\lib\\http\\client.py\", line 956, in send\n    self.connect()\n  File \"c:\\users\\atpc8\\appdata\\local\\programs\\python\\python37\\lib\\site-packages\\urllib3\\connection.py\", line 184, in connect\n    conn = self._new_conn()\n  File \"c:\\users\\atpc8\\appdata\\local\\programs\\python\\python37\\lib\\site-packages\\urllib3\\connection.py\", line 169, in _new_conn\n    self, \"Failed to establish a new connection: %s\" % e\nurllib3.exceptions.NewConnectionError: <urllib3.connection.HTTPConnection object at 0x0000024D84D27390>: Failed to establish a new connection: [Errno 11001] getaddrinfo failed\n\nDuring handling of the above exception, another exception occurred:\n\nTraceback (most recent call last):\n  File \"c:\\users\\atpc8\\appdata\\local\\programs\\python\\python37\\lib\\site-packages\\requests\\adapters.py\", line 449, in send\n    timeout=timeout\n  File \"c:\\users\\atpc8\\appdata\\local\\programs\\python\\python37\\lib\\site-packages\\urllib3\\connectionpool.py\", line 720, in urlopen\n    method, url, error=e, _pool=self, _stacktrace=sys.exc_info()[2]\n  File \"c:\\users\\atpc8\\appdata\\local\\programs\\python\\python37\\lib\\site-packages\\urllib3\\util\\retry.py\", line 436, in increment\n    raise MaxRetryError(_pool, url, error or ResponseError(cause))\nurllib3.exceptions.MaxRetryError: HTTPConnectionPool(host='api.dev.compareking.no', port=80): Max retries exceeded with url: /api/application (Caused by NewConnectionError('<urllib3.connection.HTTPConnection object at 0x0000024D84D27390>: Failed to establish a new connection: [Errno 11001] getaddrinfo failed'))\n\nDuring handling of the above exception, another exception occurred:\n\nTraceback (most recent call last):\n  File \"c:\\users\\atpc8\\appdata\\local\\programs\\python\\python37\\lib\\site-packages\\lemoncheesecake\\runner.py\", line 188, in run\n    self.test.callback(**test_func_params)\n  File \"C:\\Users\\atpc8\\sdlc\\lemontest\\suites\\secondsuite.py\", line 25, in req2\n    headers=authenticate, data=throughput)\n  File \"c:\\users\\atpc8\\appdata\\local\\programs\\python\\python37\\lib\\site-packages\\requests\\api.py\", line 116, in post\n    return request('post', url, data=data, json=json, **kwargs)\n  File \"c:\\users\\atpc8\\appdata\\local\\programs\\python\\python37\\lib\\site-packages\\requests\\api.py\", line 60, in request\n    return session.request(method=method, url=url, **kwargs)\n  File \"c:\\users\\atpc8\\appdata\\local\\programs\\python\\python37\\lib\\site-packages\\requests\\sessions.py\", line 533, in request\n    resp = self.send(prep, **send_kwargs)\n  File \"c:\\users\\atpc8\\appdata\\local\\programs\\python\\python37\\lib\\site-packages\\requests\\sessions.py\", line 646, in send\n    r = adapter.send(request, **kwargs)\n  File \"c:\\users\\atpc8\\appdata\\local\\programs\\python\\python37\\lib\\site-packages\\requests\\adapters.py\", line 516, in send\n    raise ConnectionError(e, request=request)\nrequests.exceptions.ConnectionError: HTTPConnectionPool(host='api.dev.compareking.no', port=80): Max retries exceeded with url: /api/application (Caused by NewConnectionError('<urllib3.connection.HTTPConnection object at 0x0000024D84D27390>: Failed to establish a new connection: [Errno 11001] getaddrinfo failed'))\n", "time": "2020-05-06T08:34:39.888Z"}]}], "status": "failed", "status_details": null, "name": "req2", "description": "req2", "tags": [], "properties": {}, "links": []}, {"start_time": "2020-05-06T08:34:39.888Z", "end_time": "2020-05-06T08:34:39.895Z", "steps": [{"description": "req3", "start_time": "2020-05-06T08:34:39.888Z", "end_time": "2020-05-06T08:34:39.895Z", "entries": [{"type": "log", "level": "error", "message": "Caught unexpected exception while running test: Traceback (most recent call last):\n  File \"c:\\users\\atpc8\\appdata\\local\\programs\\python\\python37\\lib\\site-packages\\urllib3\\connection.py\", line 157, in _new_conn\n    (self._dns_host, self.port), self.timeout, **extra_kw\n  File \"c:\\users\\atpc8\\appdata\\local\\programs\\python\\python37\\lib\\site-packages\\urllib3\\util\\connection.py\", line 61, in create_connection\n    for res in socket.getaddrinfo(host, port, family, socket.SOCK_STREAM):\n  File \"c:\\users\\atpc8\\appdata\\local\\programs\\python\\python37\\lib\\socket.py\", line 748, in getaddrinfo\n    for res in _socket.getaddrinfo(host, port, family, type, proto, flags):\nsocket.gaierror: [Errno 11001] getaddrinfo failed\n\nDuring handling of the above exception, another exception occurred:\n\nTraceback (most recent call last):\n  File \"c:\\users\\atpc8\\appdata\\local\\programs\\python\\python37\\lib\\site-packages\\urllib3\\connectionpool.py\", line 672, in urlopen\n    chunked=chunked,\n  File \"c:\\users\\atpc8\\appdata\\local\\programs\\python\\python37\\lib\\site-packages\\urllib3\\connectionpool.py\", line 387, in _make_request\n    conn.request(method, url, **httplib_request_kw)\n  File \"c:\\users\\atpc8\\appdata\\local\\programs\\python\\python37\\lib\\http\\client.py\", line 1229, in request\n    self._send_request(method, url, body, headers, encode_chunked)\n  File \"c:\\users\\atpc8\\appdata\\local\\programs\\python\\python37\\lib\\http\\client.py\", line 1275, in _send_request\n    self.endheaders(body, encode_chunked=encode_chunked)\n  File \"c:\\users\\atpc8\\appdata\\local\\programs\\python\\python37\\lib\\http\\client.py\", line 1224, in endheaders\n    self._send_output(message_body, encode_chunked=encode_chunked)\n  File \"c:\\users\\atpc8\\appdata\\local\\programs\\python\\python37\\lib\\http\\client.py\", line 1016, in _send_output\n    self.send(msg)\n  File \"c:\\users\\atpc8\\appdata\\local\\programs\\python\\python37\\lib\\http\\client.py\", line 956, in send\n    self.connect()\n  File \"c:\\users\\atpc8\\appdata\\local\\programs\\python\\python37\\lib\\site-packages\\urllib3\\connection.py\", line 184, in connect\n    conn = self._new_conn()\n  File \"c:\\users\\atpc8\\appdata\\local\\programs\\python\\python37\\lib\\site-packages\\urllib3\\connection.py\", line 169, in _new_conn\n    self, \"Failed to establish a new connection: %s\" % e\nurllib3.exceptions.NewConnectionError: <urllib3.connection.HTTPConnection object at 0x0000024D84D27550>: Failed to establish a new connection: [Errno 11001] getaddrinfo failed\n\nDuring handling of the above exception, another exception occurred:\n\nTraceback (most recent call last):\n  File \"c:\\users\\atpc8\\appdata\\local\\programs\\python\\python37\\lib\\site-packages\\requests\\adapters.py\", line 449, in send\n    timeout=timeout\n  File \"c:\\users\\atpc8\\appdata\\local\\programs\\python\\python37\\lib\\site-packages\\urllib3\\connectionpool.py\", line 720, in urlopen\n    method, url, error=e, _pool=self, _stacktrace=sys.exc_info()[2]\n  File \"c:\\users\\atpc8\\appdata\\local\\programs\\python\\python37\\lib\\site-packages\\urllib3\\util\\retry.py\", line 436, in increment\n    raise MaxRetryError(_pool, url, error or ResponseError(cause))\nurllib3.exceptions.MaxRetryError: HTTPConnectionPool(host='api.dev.compareking.no', port=80): Max retries exceeded with url: /api/application (Caused by NewConnectionError('<urllib3.connection.HTTPConnection object at 0x0000024D84D27550>: Failed to establish a new connection: [Errno 11001] getaddrinfo failed'))\n\nDuring handling of the above exception, another exception occurred:\n\nTraceback (most recent call last):\n  File \"c:\\users\\atpc8\\appdata\\local\\programs\\python\\python37\\lib\\site-packages\\lemoncheesecake\\runner.py\", line 188, in run\n    self.test.callback(**test_func_params)\n  File \"C:\\Users\\atpc8\\sdlc\\lemontest\\suites\\secondsuite.py\", line 33, in req3\n    headers=authenticate, data=throughput)\n  File \"c:\\users\\atpc8\\appdata\\local\\programs\\python\\python37\\lib\\site-packages\\requests\\api.py\", line 116, in post\n    return request('post', url, data=data, json=json, **kwargs)\n  File \"c:\\users\\atpc8\\appdata\\local\\programs\\python\\python37\\lib\\site-packages\\requests\\api.py\", line 60, in request\n    return session.request(method=method, url=url, **kwargs)\n  File \"c:\\users\\atpc8\\appdata\\local\\programs\\python\\python37\\lib\\site-packages\\requests\\sessions.py\", line 533, in request\n    resp = self.send(prep, **send_kwargs)\n  File \"c:\\users\\atpc8\\appdata\\local\\programs\\python\\python37\\lib\\site-packages\\requests\\sessions.py\", line 646, in send\n    r = adapter.send(request, **kwargs)\n  File \"c:\\users\\atpc8\\appdata\\local\\programs\\python\\python37\\lib\\site-packages\\requests\\adapters.py\", line 516, in send\n    raise ConnectionError(e, request=request)\nrequests.exceptions.ConnectionError: HTTPConnectionPool(host='api.dev.compareking.no', port=80): Max retries exceeded with url: /api/application (Caused by NewConnectionError('<urllib3.connection.HTTPConnection object at 0x0000024D84D27550>: Failed to establish a new connection: [Errno 11001] getaddrinfo failed'))\n", "time": "2020-05-06T08:34:39.895Z"}]}], "status": "failed", "status_details": null, "name": "req3", "description": "req3", "tags": [], "properties": {}, "links": []}, {"start_time": "2020-05-06T08:34:39.897Z", "end_time": "2020-05-06T08:34:39.904Z", "steps": [{"description": "req4", "start_time": "2020-05-06T08:34:39.897Z", "end_time": "2020-05-06T08:34:39.904Z", "entries": [{"type": "log", "level": "error", "message": "Caught unexpected exception while running test: Traceback (most recent call last):\n  File \"c:\\users\\atpc8\\appdata\\local\\programs\\python\\python37\\lib\\site-packages\\urllib3\\connection.py\", line 157, in _new_conn\n    (self._dns_host, self.port), self.timeout, **extra_kw\n  File \"c:\\users\\atpc8\\appdata\\local\\programs\\python\\python37\\lib\\site-packages\\urllib3\\util\\connection.py\", line 61, in create_connection\n    for res in socket.getaddrinfo(host, port, family, socket.SOCK_STREAM):\n  File \"c:\\users\\atpc8\\appdata\\local\\programs\\python\\python37\\lib\\socket.py\", line 748, in getaddrinfo\n    for res in _socket.getaddrinfo(host, port, family, type, proto, flags):\nsocket.gaierror: [Errno 11001] getaddrinfo failed\n\nDuring handling of the above exception, another exception occurred:\n\nTraceback (most recent call last):\n  File \"c:\\users\\atpc8\\appdata\\local\\programs\\python\\python37\\lib\\site-packages\\urllib3\\connectionpool.py\", line 672, in urlopen\n    chunked=chunked,\n  File \"c:\\users\\atpc8\\appdata\\local\\programs\\python\\python37\\lib\\site-packages\\urllib3\\connectionpool.py\", line 387, in _make_request\n    conn.request(method, url, **httplib_request_kw)\n  File \"c:\\users\\atpc8\\appdata\\local\\programs\\python\\python37\\lib\\http\\client.py\", line 1229, in request\n    self._send_request(method, url, body, headers, encode_chunked)\n  File \"c:\\users\\atpc8\\appdata\\local\\programs\\python\\python37\\lib\\http\\client.py\", line 1275, in _send_request\n    self.endheaders(body, encode_chunked=encode_chunked)\n  File \"c:\\users\\atpc8\\appdata\\local\\programs\\python\\python37\\lib\\http\\client.py\", line 1224, in endheaders\n    self._send_output(message_body, encode_chunked=encode_chunked)\n  File \"c:\\users\\atpc8\\appdata\\local\\programs\\python\\python37\\lib\\http\\client.py\", line 1016, in _send_output\n    self.send(msg)\n  File \"c:\\users\\atpc8\\appdata\\local\\programs\\python\\python37\\lib\\http\\client.py\", line 956, in send\n    self.connect()\n  File \"c:\\users\\atpc8\\appdata\\local\\programs\\python\\python37\\lib\\site-packages\\urllib3\\connection.py\", line 184, in connect\n    conn = self._new_conn()\n  File \"c:\\users\\atpc8\\appdata\\local\\programs\\python\\python37\\lib\\site-packages\\urllib3\\connection.py\", line 169, in _new_conn\n    self, \"Failed to establish a new connection: %s\" % e\nurllib3.exceptions.NewConnectionError: <urllib3.connection.HTTPConnection object at 0x0000024D84D27390>: Failed to establish a new connection: [Errno 11001] getaddrinfo failed\n\nDuring handling of the above exception, another exception occurred:\n\nTraceback (most recent call last):\n  File \"c:\\users\\atpc8\\appdata\\local\\programs\\python\\python37\\lib\\site-packages\\requests\\adapters.py\", line 449, in send\n    timeout=timeout\n  File \"c:\\users\\atpc8\\appdata\\local\\programs\\python\\python37\\lib\\site-packages\\urllib3\\connectionpool.py\", line 720, in urlopen\n    method, url, error=e, _pool=self, _stacktrace=sys.exc_info()[2]\n  File \"c:\\users\\atpc8\\appdata\\local\\programs\\python\\python37\\lib\\site-packages\\urllib3\\util\\retry.py\", line 436, in increment\n    raise MaxRetryError(_pool, url, error or ResponseError(cause))\nurllib3.exceptions.MaxRetryError: HTTPConnectionPool(host='api.dev.compareking.no', port=80): Max retries exceeded with url: /api/application (Caused by NewConnectionError('<urllib3.connection.HTTPConnection object at 0x0000024D84D27390>: Failed to establish a new connection: [Errno 11001] getaddrinfo failed'))\n\nDuring handling of the above exception, another exception occurred:\n\nTraceback (most recent call last):\n  File \"c:\\users\\atpc8\\appdata\\local\\programs\\python\\python37\\lib\\site-packages\\lemoncheesecake\\runner.py\", line 188, in run\n    self.test.callback(**test_func_params)\n  File \"C:\\Users\\atpc8\\sdlc\\lemontest\\suites\\secondsuite.py\", line 80, in req4\n    headers=authenticate, data=payload)\n  File \"c:\\users\\atpc8\\appdata\\local\\programs\\python\\python37\\lib\\site-packages\\requests\\api.py\", line 116, in post\n    return request('post', url, data=data, json=json, **kwargs)\n  File \"c:\\users\\atpc8\\appdata\\local\\programs\\python\\python37\\lib\\site-packages\\requests\\api.py\", line 60, in request\n    return session.request(method=method, url=url, **kwargs)\n  File \"c:\\users\\atpc8\\appdata\\local\\programs\\python\\python37\\lib\\site-packages\\requests\\sessions.py\", line 533, in request\n    resp = self.send(prep, **send_kwargs)\n  File \"c:\\users\\atpc8\\appdata\\local\\programs\\python\\python37\\lib\\site-packages\\requests\\sessions.py\", line 646, in send\n    r = adapter.send(request, **kwargs)\n  File \"c:\\users\\atpc8\\appdata\\local\\programs\\python\\python37\\lib\\site-packages\\requests\\adapters.py\", line 516, in send\n    raise ConnectionError(e, request=request)\nrequests.exceptions.ConnectionError: HTTPConnectionPool(host='api.dev.compareking.no', port=80): Max retries exceeded with url: /api/application (Caused by NewConnectionError('<urllib3.connection.HTTPConnection object at 0x0000024D84D27390>: Failed to establish a new connection: [Errno 11001] getaddrinfo failed'))\n", "time": "2020-05-06T08:34:39.904Z"}]}], "status": "failed", "status_details": null, "name": "req4", "description": "req4", "tags": [], "properties": {}, "links": []}, {"start_time": "2020-05-06T08:34:39.904Z", "end_time": "2020-05-06T08:34:39.908Z", "steps": [{"description": "req5", "start_time": "2020-05-06T08:34:39.904Z", "end_time": "2020-05-06T08:34:39.908Z", "entries": [{"type": "log", "level": "error", "message": "Caught unexpected exception while running test: Traceback (most recent call last):\n  File \"c:\\users\\atpc8\\appdata\\local\\programs\\python\\python37\\lib\\site-packages\\urllib3\\connection.py\", line 157, in _new_conn\n    (self._dns_host, self.port), self.timeout, **extra_kw\n  File \"c:\\users\\atpc8\\appdata\\local\\programs\\python\\python37\\lib\\site-packages\\urllib3\\util\\connection.py\", line 61, in create_connection\n    for res in socket.getaddrinfo(host, port, family, socket.SOCK_STREAM):\n  File \"c:\\users\\atpc8\\appdata\\local\\programs\\python\\python37\\lib\\socket.py\", line 748, in getaddrinfo\n    for res in _socket.getaddrinfo(host, port, family, type, proto, flags):\nsocket.gaierror: [Errno 11001] getaddrinfo failed\n\nDuring handling of the above exception, another exception occurred:\n\nTraceback (most recent call last):\n  File \"c:\\users\\atpc8\\appdata\\local\\programs\\python\\python37\\lib\\site-packages\\urllib3\\connectionpool.py\", line 672, in urlopen\n    chunked=chunked,\n  File \"c:\\users\\atpc8\\appdata\\local\\programs\\python\\python37\\lib\\site-packages\\urllib3\\connectionpool.py\", line 387, in _make_request\n    conn.request(method, url, **httplib_request_kw)\n  File \"c:\\users\\atpc8\\appdata\\local\\programs\\python\\python37\\lib\\http\\client.py\", line 1229, in request\n    self._send_request(method, url, body, headers, encode_chunked)\n  File \"c:\\users\\atpc8\\appdata\\local\\programs\\python\\python37\\lib\\http\\client.py\", line 1275, in _send_request\n    self.endheaders(body, encode_chunked=encode_chunked)\n  File \"c:\\users\\atpc8\\appdata\\local\\programs\\python\\python37\\lib\\http\\client.py\", line 1224, in endheaders\n    self._send_output(message_body, encode_chunked=encode_chunked)\n  File \"c:\\users\\atpc8\\appdata\\local\\programs\\python\\python37\\lib\\http\\client.py\", line 1016, in _send_output\n    self.send(msg)\n  File \"c:\\users\\atpc8\\appdata\\local\\programs\\python\\python37\\lib\\http\\client.py\", line 956, in send\n    self.connect()\n  File \"c:\\users\\atpc8\\appdata\\local\\programs\\python\\python37\\lib\\site-packages\\urllib3\\connection.py\", line 184, in connect\n    conn = self._new_conn()\n  File \"c:\\users\\atpc8\\appdata\\local\\programs\\python\\python37\\lib\\site-packages\\urllib3\\connection.py\", line 169, in _new_conn\n    self, \"Failed to establish a new connection: %s\" % e\nurllib3.exceptions.NewConnectionError: <urllib3.connection.HTTPConnection object at 0x0000024D84D27978>: Failed to establish a new connection: [Errno 11001] getaddrinfo failed\n\nDuring handling of the above exception, another exception occurred:\n\nTraceback (most recent call last):\n  File \"c:\\users\\atpc8\\appdata\\local\\programs\\python\\python37\\lib\\site-packages\\requests\\adapters.py\", line 449, in send\n    timeout=timeout\n  File \"c:\\users\\atpc8\\appdata\\local\\programs\\python\\python37\\lib\\site-packages\\urllib3\\connectionpool.py\", line 720, in urlopen\n    method, url, error=e, _pool=self, _stacktrace=sys.exc_info()[2]\n  File \"c:\\users\\atpc8\\appdata\\local\\programs\\python\\python37\\lib\\site-packages\\urllib3\\util\\retry.py\", line 436, in increment\n    raise MaxRetryError(_pool, url, error or ResponseError(cause))\nurllib3.exceptions.MaxRetryError: HTTPConnectionPool(host='api.dev.compareking.no', port=80): Max retries exceeded with url: /api/application (Caused by NewConnectionError('<urllib3.connection.HTTPConnection object at 0x0000024D84D27978>: Failed to establish a new connection: [Errno 11001] getaddrinfo failed'))\n\nDuring handling of the above exception, another exception occurred:\n\nTraceback (most recent call last):\n  File \"c:\\users\\atpc8\\appdata\\local\\programs\\python\\python37\\lib\\site-packages\\lemoncheesecake\\runner.py\", line 188, in run\n    self.test.callback(**test_func_params)\n  File \"C:\\Users\\atpc8\\sdlc\\lemontest\\suites\\secondsuite.py\", line 142, in req5\n    headers=authenticate, data=payload)\n  File \"c:\\users\\atpc8\\appdata\\local\\programs\\python\\python37\\lib\\site-packages\\requests\\api.py\", line 116, in post\n    return request('post', url, data=data, json=json, **kwargs)\n  File \"c:\\users\\atpc8\\appdata\\local\\programs\\python\\python37\\lib\\site-packages\\requests\\api.py\", line 60, in request\n    return session.request(method=method, url=url, **kwargs)\n  File \"c:\\users\\atpc8\\appdata\\local\\programs\\python\\python37\\lib\\site-packages\\requests\\sessions.py\", line 533, in request\n    resp = self.send(prep, **send_kwargs)\n  File \"c:\\users\\atpc8\\appdata\\local\\programs\\python\\python37\\lib\\site-packages\\requests\\sessions.py\", line 646, in send\n    r = adapter.send(request, **kwargs)\n  File \"c:\\users\\atpc8\\appdata\\local\\programs\\python\\python37\\lib\\site-packages\\requests\\adapters.py\", line 516, in send\n    raise ConnectionError(e, request=request)\nrequests.exceptions.ConnectionError: HTTPConnectionPool(host='api.dev.compareking.no', port=80): Max retries exceeded with url: /api/application (Caused by NewConnectionError('<urllib3.connection.HTTPConnection object at 0x0000024D84D27978>: Failed to establish a new connection: [Errno 11001] getaddrinfo failed'))\n", "time": "2020-05-06T08:34:39.908Z"}]}], "status": "failed", "status_details": null, "name": "req5", "description": "req5", "tags": [], "properties": {}, "links": []}, {"start_time": "2020-05-06T08:34:39.909Z", "end_time": "2020-05-06T08:34:39.913Z", "steps": [{"description": "glc_auth_test", "start_time": "2020-05-06T08:34:39.909Z", "end_time": "2020-05-06T08:34:39.913Z", "entries": [{"type": "log", "level": "error", "message": "Caught unexpected exception while running test: Traceback (most recent call last):\n  File \"c:\\users\\atpc8\\appdata\\local\\programs\\python\\python37\\lib\\site-packages\\urllib3\\connection.py\", line 157, in _new_conn\n    (self._dns_host, self.port), self.timeout, **extra_kw\n  File \"c:\\users\\atpc8\\appdata\\local\\programs\\python\\python37\\lib\\site-packages\\urllib3\\util\\connection.py\", line 61, in create_connection\n    for res in socket.getaddrinfo(host, port, family, socket.SOCK_STREAM):\n  File \"c:\\users\\atpc8\\appdata\\local\\programs\\python\\python37\\lib\\socket.py\", line 748, in getaddrinfo\n    for res in _socket.getaddrinfo(host, port, family, type, proto, flags):\nsocket.gaierror: [Errno 11001] getaddrinfo failed\n\nDuring handling of the above exception, another exception occurred:\n\nTraceback (most recent call last):\n  File \"c:\\users\\atpc8\\appdata\\local\\programs\\python\\python37\\lib\\site-packages\\urllib3\\connectionpool.py\", line 672, in urlopen\n    chunked=chunked,\n  File \"c:\\users\\atpc8\\appdata\\local\\programs\\python\\python37\\lib\\site-packages\\urllib3\\connectionpool.py\", line 376, in _make_request\n    self._validate_conn(conn)\n  File \"c:\\users\\atpc8\\appdata\\local\\programs\\python\\python37\\lib\\site-packages\\urllib3\\connectionpool.py\", line 994, in _validate_conn\n    conn.connect()\n  File \"c:\\users\\atpc8\\appdata\\local\\programs\\python\\python37\\lib\\site-packages\\urllib3\\connection.py\", line 334, in connect\n    conn = self._new_conn()\n  File \"c:\\users\\atpc8\\appdata\\local\\programs\\python\\python37\\lib\\site-packages\\urllib3\\connection.py\", line 169, in _new_conn\n    self, \"Failed to establish a new connection: %s\" % e\nurllib3.exceptions.NewConnectionError: <urllib3.connection.VerifiedHTTPSConnection object at 0x0000024D84D27AC8>: Failed to establish a new connection: [Errno 11001] getaddrinfo failed\n\nDuring handling of the above exception, another exception occurred:\n\nTraceback (most recent call last):\n  File \"c:\\users\\atpc8\\appdata\\local\\programs\\python\\python37\\lib\\site-packages\\requests\\adapters.py\", line 449, in send\n    timeout=timeout\n  File \"c:\\users\\atpc8\\appdata\\local\\programs\\python\\python37\\lib\\site-packages\\urllib3\\connectionpool.py\", line 720, in urlopen\n    method, url, error=e, _pool=self, _stacktrace=sys.exc_info()[2]\n  File \"c:\\users\\atpc8\\appdata\\local\\programs\\python\\python37\\lib\\site-packages\\urllib3\\util\\retry.py\", line 436, in increment\n    raise MaxRetryError(_pool, url, error or ResponseError(cause))\nurllib3.exceptions.MaxRetryError: HTTPSConnectionPool(host='ctest-main.irisplus.tui.de', port=443): Max retries exceeded with url: /ipl360/api (Caused by NewConnectionError('<urllib3.connection.VerifiedHTTPSConnection object at 0x0000024D84D27AC8>: Failed to establish a new connection: [Errno 11001] getaddrinfo failed'))\n\nDuring handling of the above exception, another exception occurred:\n\nTraceback (most recent call last):\n  File \"c:\\users\\atpc8\\appdata\\local\\programs\\python\\python37\\lib\\site-packages\\lemoncheesecake\\runner.py\", line 188, in run\n    self.test.callback(**test_func_params)\n  File \"C:\\Users\\atpc8\\sdlc\\lemontest\\suites\\secondsuite.py\", line 150, in glc_auth_test\n    r = requests.get(glc_url, headers=glc_auth)\n  File \"c:\\users\\atpc8\\appdata\\local\\programs\\python\\python37\\lib\\site-packages\\requests\\api.py\", line 75, in get\n    return request('get', url, params=params, **kwargs)\n  File \"c:\\users\\atpc8\\appdata\\local\\programs\\python\\python37\\lib\\site-packages\\requests\\api.py\", line 60, in request\n    return session.request(method=method, url=url, **kwargs)\n  File \"c:\\users\\atpc8\\appdata\\local\\programs\\python\\python37\\lib\\site-packages\\requests\\sessions.py\", line 533, in request\n    resp = self.send(prep, **send_kwargs)\n  File \"c:\\users\\atpc8\\appdata\\local\\programs\\python\\python37\\lib\\site-packages\\requests\\sessions.py\", line 646, in send\n    r = adapter.send(request, **kwargs)\n  File \"c:\\users\\atpc8\\appdata\\local\\programs\\python\\python37\\lib\\site-packages\\requests\\adapters.py\", line 516, in send\n    raise ConnectionError(e, request=request)\nrequests.exceptions.ConnectionError: HTTPSConnectionPool(host='ctest-main.irisplus.tui.de', port=443): Max retries exceeded with url: /ipl360/api (Caused by NewConnectionError('<urllib3.connection.VerifiedHTTPSConnection object at 0x0000024D84D27AC8>: Failed to establish a new connection: [Errno 11001] getaddrinfo failed'))\n", "time": "2020-05-06T08:34:39.913Z"}]}], "status": "failed", "status_details": null, "name": "glc_auth_test", "description": "glc_auth_test", "tags": ["glc"], "properties": {}, "links": []}], "suites": [], "name": "secondsuite", "description": "sec_suite", "tags": ["validation", "white labels"], "properties": {}, "links": []}, {"start_time": "2020-05-06T08:34:39.914Z", "end_time": "2020-05-06T08:34:39.945Z", "tests": [{"start_time": "2020-05-06T08:34:39.914Z", "end_time": "2020-05-06T08:34:39.925Z", "steps": [{"description": "Submit existing application or sent less than 3 months ago", "start_time": "2020-05-06T08:34:39.914Z", "end_time": "2020-05-06T08:34:39.925Z", "entries": [{"type": "log", "level": "error", "message": "Caught unexpected exception while running test: Traceback (most recent call last):\n  File \"c:\\users\\atpc8\\appdata\\local\\programs\\python\\python37\\lib\\site-packages\\urllib3\\connection.py\", line 157, in _new_conn\n    (self._dns_host, self.port), self.timeout, **extra_kw\n  File \"c:\\users\\atpc8\\appdata\\local\\programs\\python\\python37\\lib\\site-packages\\urllib3\\util\\connection.py\", line 61, in create_connection\n    for res in socket.getaddrinfo(host, port, family, socket.SOCK_STREAM):\n  File \"c:\\users\\atpc8\\appdata\\local\\programs\\python\\python37\\lib\\socket.py\", line 748, in getaddrinfo\n    for res in _socket.getaddrinfo(host, port, family, type, proto, flags):\nsocket.gaierror: [Errno 11001] getaddrinfo failed\n\nDuring handling of the above exception, another exception occurred:\n\nTraceback (most recent call last):\n  File \"c:\\users\\atpc8\\appdata\\local\\programs\\python\\python37\\lib\\site-packages\\urllib3\\connectionpool.py\", line 672, in urlopen\n    chunked=chunked,\n  File \"c:\\users\\atpc8\\appdata\\local\\programs\\python\\python37\\lib\\site-packages\\urllib3\\connectionpool.py\", line 387, in _make_request\n    conn.request(method, url, **httplib_request_kw)\n  File \"c:\\users\\atpc8\\appdata\\local\\programs\\python\\python37\\lib\\http\\client.py\", line 1229, in request\n    self._send_request(method, url, body, headers, encode_chunked)\n  File \"c:\\users\\atpc8\\appdata\\local\\programs\\python\\python37\\lib\\http\\client.py\", line 1275, in _send_request\n    self.endheaders(body, encode_chunked=encode_chunked)\n  File \"c:\\users\\atpc8\\appdata\\local\\programs\\python\\python37\\lib\\http\\client.py\", line 1224, in endheaders\n    self._send_output(message_body, encode_chunked=encode_chunked)\n  File \"c:\\users\\atpc8\\appdata\\local\\programs\\python\\python37\\lib\\http\\client.py\", line 1016, in _send_output\n    self.send(msg)\n  File \"c:\\users\\atpc8\\appdata\\local\\programs\\python\\python37\\lib\\http\\client.py\", line 956, in send\n    self.connect()\n  File \"c:\\users\\atpc8\\appdata\\local\\programs\\python\\python37\\lib\\site-packages\\urllib3\\connection.py\", line 184, in connect\n    conn = self._new_conn()\n  File \"c:\\users\\atpc8\\appdata\\local\\programs\\python\\python37\\lib\\site-packages\\urllib3\\connection.py\", line 169, in _new_conn\n    self, \"Failed to establish a new connection: %s\" % e\nurllib3.exceptions.NewConnectionError: <urllib3.connection.HTTPConnection object at 0x0000024D84D27C50>: Failed to establish a new connection: [Errno 11001] getaddrinfo failed\n\nDuring handling of the above exception, another exception occurred:\n\nTraceback (most recent call last):\n  File \"c:\\users\\atpc8\\appdata\\local\\programs\\python\\python37\\lib\\site-packages\\requests\\adapters.py\", line 449, in send\n    timeout=timeout\n  File \"c:\\users\\atpc8\\appdata\\local\\programs\\python\\python37\\lib\\site-packages\\urllib3\\connectionpool.py\", line 720, in urlopen\n    method, url, error=e, _pool=self, _stacktrace=sys.exc_info()[2]\n  File \"c:\\users\\atpc8\\appdata\\local\\programs\\python\\python37\\lib\\site-packages\\urllib3\\util\\retry.py\", line 436, in increment\n    raise MaxRetryError(_pool, url, error or ResponseError(cause))\nurllib3.exceptions.MaxRetryError: HTTPConnectionPool(host='api.dev.compareking.no', port=80): Max retries exceeded with url: /api/application (Caused by NewConnectionError('<urllib3.connection.HTTPConnection object at 0x0000024D84D27C50>: Failed to establish a new connection: [Errno 11001] getaddrinfo failed'))\n\nDuring handling of the above exception, another exception occurred:\n\nTraceback (most recent call last):\n  File \"c:\\users\\atpc8\\appdata\\local\\programs\\python\\python37\\lib\\site-packages\\lemoncheesecake\\runner.py\", line 188, in run\n    self.test.callback(**test_func_params)\n  File \"C:\\Users\\atpc8\\sdlc\\lemontest\\suites\\thirdsuite.py\", line 47, in req1\n    headers=auth_headers, data=payload)\n  File \"c:\\users\\atpc8\\appdata\\local\\programs\\python\\python37\\lib\\site-packages\\requests\\api.py\", line 116, in post\n    return request('post', url, data=data, json=json, **kwargs)\n  File \"c:\\users\\atpc8\\appdata\\local\\programs\\python\\python37\\lib\\site-packages\\requests\\api.py\", line 60, in request\n    return session.request(method=method, url=url, **kwargs)\n  File \"c:\\users\\atpc8\\appdata\\local\\programs\\python\\python37\\lib\\site-packages\\requests\\sessions.py\", line 533, in request\n    resp = self.send(prep, **send_kwargs)\n  File \"c:\\users\\atpc8\\appdata\\local\\programs\\python\\python37\\lib\\site-packages\\requests\\sessions.py\", line 646, in send\n    r = adapter.send(request, **kwargs)\n  File \"c:\\users\\atpc8\\appdata\\local\\programs\\python\\python37\\lib\\site-packages\\requests\\adapters.py\", line 516, in send\n    raise ConnectionError(e, request=request)\nrequests.exceptions.ConnectionError: HTTPConnectionPool(host='api.dev.compareking.no', port=80): Max retries exceeded with url: /api/application (Caused by NewConnectionError('<urllib3.connection.HTTPConnection object at 0x0000024D84D27C50>: Failed to establish a new connection: [Errno 11001] getaddrinfo failed'))\n", "time": "2020-05-06T08:34:39.925Z"}]}], "status": "failed", "status_details": null, "name": "req1", "description": "Submit existing application or sent less than 3 months ago", "tags": [], "properties": {}, "links": []}, {"start_time": "2020-05-06T08:34:39.926Z", "end_time": "2020-05-06T08:34:39.937Z", "steps": [{"description": "Submit unfinished application with all required information", "start_time": "2020-05-06T08:34:39.926Z", "end_time": "2020-05-06T08:34:39.937Z", "entries": [{"type": "log", "level": "error", "message": "Caught unexpected exception while running test: Traceback (most recent call last):\n  File \"c:\\users\\atpc8\\appdata\\local\\programs\\python\\python37\\lib\\site-packages\\urllib3\\connection.py\", line 157, in _new_conn\n    (self._dns_host, self.port), self.timeout, **extra_kw\n  File \"c:\\users\\atpc8\\appdata\\local\\programs\\python\\python37\\lib\\site-packages\\urllib3\\util\\connection.py\", line 61, in create_connection\n    for res in socket.getaddrinfo(host, port, family, socket.SOCK_STREAM):\n  File \"c:\\users\\atpc8\\appdata\\local\\programs\\python\\python37\\lib\\socket.py\", line 748, in getaddrinfo\n    for res in _socket.getaddrinfo(host, port, family, type, proto, flags):\nsocket.gaierror: [Errno 11001] getaddrinfo failed\n\nDuring handling of the above exception, another exception occurred:\n\nTraceback (most recent call last):\n  File \"c:\\users\\atpc8\\appdata\\local\\programs\\python\\python37\\lib\\site-packages\\urllib3\\connectionpool.py\", line 672, in urlopen\n    chunked=chunked,\n  File \"c:\\users\\atpc8\\appdata\\local\\programs\\python\\python37\\lib\\site-packages\\urllib3\\connectionpool.py\", line 387, in _make_request\n    conn.request(method, url, **httplib_request_kw)\n  File \"c:\\users\\atpc8\\appdata\\local\\programs\\python\\python37\\lib\\http\\client.py\", line 1229, in request\n    self._send_request(method, url, body, headers, encode_chunked)\n  File \"c:\\users\\atpc8\\appdata\\local\\programs\\python\\python37\\lib\\http\\client.py\", line 1275, in _send_request\n    self.endheaders(body, encode_chunked=encode_chunked)\n  File \"c:\\users\\atpc8\\appdata\\local\\programs\\python\\python37\\lib\\http\\client.py\", line 1224, in endheaders\n    self._send_output(message_body, encode_chunked=encode_chunked)\n  File \"c:\\users\\atpc8\\appdata\\local\\programs\\python\\python37\\lib\\http\\client.py\", line 1016, in _send_output\n    self.send(msg)\n  File \"c:\\users\\atpc8\\appdata\\local\\programs\\python\\python37\\lib\\http\\client.py\", line 956, in send\n    self.connect()\n  File \"c:\\users\\atpc8\\appdata\\local\\programs\\python\\python37\\lib\\site-packages\\urllib3\\connection.py\", line 184, in connect\n    conn = self._new_conn()\n  File \"c:\\users\\atpc8\\appdata\\local\\programs\\python\\python37\\lib\\site-packages\\urllib3\\connection.py\", line 169, in _new_conn\n    self, \"Failed to establish a new connection: %s\" % e\nurllib3.exceptions.NewConnectionError: <urllib3.connection.HTTPConnection object at 0x0000024D84D27EF0>: Failed to establish a new connection: [Errno 11001] getaddrinfo failed\n\nDuring handling of the above exception, another exception occurred:\n\nTraceback (most recent call last):\n  File \"c:\\users\\atpc8\\appdata\\local\\programs\\python\\python37\\lib\\site-packages\\requests\\adapters.py\", line 449, in send\n    timeout=timeout\n  File \"c:\\users\\atpc8\\appdata\\local\\programs\\python\\python37\\lib\\site-packages\\urllib3\\connectionpool.py\", line 720, in urlopen\n    method, url, error=e, _pool=self, _stacktrace=sys.exc_info()[2]\n  File \"c:\\users\\atpc8\\appdata\\local\\programs\\python\\python37\\lib\\site-packages\\urllib3\\util\\retry.py\", line 436, in increment\n    raise MaxRetryError(_pool, url, error or ResponseError(cause))\nurllib3.exceptions.MaxRetryError: HTTPConnectionPool(host='api.dev.compareking.no', port=80): Max retries exceeded with url: /api/contact (Caused by NewConnectionError('<urllib3.connection.HTTPConnection object at 0x0000024D84D27EF0>: Failed to establish a new connection: [Errno 11001] getaddrinfo failed'))\n\nDuring handling of the above exception, another exception occurred:\n\nTraceback (most recent call last):\n  File \"c:\\users\\atpc8\\appdata\\local\\programs\\python\\python37\\lib\\site-packages\\lemoncheesecake\\runner.py\", line 188, in run\n    self.test.callback(**test_func_params)\n  File \"C:\\Users\\atpc8\\sdlc\\lemontest\\suites\\thirdsuite.py\", line 64, in req2\n    headers=auth_headers, json=payload)\n  File \"c:\\users\\atpc8\\appdata\\local\\programs\\python\\python37\\lib\\site-packages\\requests\\api.py\", line 116, in post\n    return request('post', url, data=data, json=json, **kwargs)\n  File \"c:\\users\\atpc8\\appdata\\local\\programs\\python\\python37\\lib\\site-packages\\requests\\api.py\", line 60, in request\n    return session.request(method=method, url=url, **kwargs)\n  File \"c:\\users\\atpc8\\appdata\\local\\programs\\python\\python37\\lib\\site-packages\\requests\\sessions.py\", line 533, in request\n    resp = self.send(prep, **send_kwargs)\n  File \"c:\\users\\atpc8\\appdata\\local\\programs\\python\\python37\\lib\\site-packages\\requests\\sessions.py\", line 646, in send\n    r = adapter.send(request, **kwargs)\n  File \"c:\\users\\atpc8\\appdata\\local\\programs\\python\\python37\\lib\\site-packages\\requests\\adapters.py\", line 516, in send\n    raise ConnectionError(e, request=request)\nrequests.exceptions.ConnectionError: HTTPConnectionPool(host='api.dev.compareking.no', port=80): Max retries exceeded with url: /api/contact (Caused by NewConnectionError('<urllib3.connection.HTTPConnection object at 0x0000024D84D27EF0>: Failed to establish a new connection: [Errno 11001] getaddrinfo failed'))\n", "time": "2020-05-06T08:34:39.937Z"}]}], "status": "failed", "status_details": null, "name": "req2", "description": "Submit unfinished application with all required information", "tags": [], "properties": {}, "links": []}, {"start_time": "2020-05-06T08:34:39.937Z", "end_time": "2020-05-06T08:34:39.940Z", "steps": [{"description": "Submit unfinished application with incomplete required info", "start_time": "2020-05-06T08:34:39.937Z", "end_time": "2020-05-06T08:34:39.940Z", "entries": [{"type": "log", "level": "error", "message": "Caught unexpected exception while running test: Traceback (most recent call last):\n  File \"c:\\users\\atpc8\\appdata\\local\\programs\\python\\python37\\lib\\site-packages\\urllib3\\connection.py\", line 157, in _new_conn\n    (self._dns_host, self.port), self.timeout, **extra_kw\n  File \"c:\\users\\atpc8\\appdata\\local\\programs\\python\\python37\\lib\\site-packages\\urllib3\\util\\connection.py\", line 61, in create_connection\n    for res in socket.getaddrinfo(host, port, family, socket.SOCK_STREAM):\n  File \"c:\\users\\atpc8\\appdata\\local\\programs\\python\\python37\\lib\\socket.py\", line 748, in getaddrinfo\n    for res in _socket.getaddrinfo(host, port, family, type, proto, flags):\nsocket.gaierror: [Errno 11001] getaddrinfo failed\n\nDuring handling of the above exception, another exception occurred:\n\nTraceback (most recent call last):\n  File \"c:\\users\\atpc8\\appdata\\local\\programs\\python\\python37\\lib\\site-packages\\urllib3\\connectionpool.py\", line 672, in urlopen\n    chunked=chunked,\n  File \"c:\\users\\atpc8\\appdata\\local\\programs\\python\\python37\\lib\\site-packages\\urllib3\\connectionpool.py\", line 387, in _make_request\n    conn.request(method, url, **httplib_request_kw)\n  File \"c:\\users\\atpc8\\appdata\\local\\programs\\python\\python37\\lib\\http\\client.py\", line 1229, in request\n    self._send_request(method, url, body, headers, encode_chunked)\n  File \"c:\\users\\atpc8\\appdata\\local\\programs\\python\\python37\\lib\\http\\client.py\", line 1275, in _send_request\n    self.endheaders(body, encode_chunked=encode_chunked)\n  File \"c:\\users\\atpc8\\appdata\\local\\programs\\python\\python37\\lib\\http\\client.py\", line 1224, in endheaders\n    self._send_output(message_body, encode_chunked=encode_chunked)\n  File \"c:\\users\\atpc8\\appdata\\local\\programs\\python\\python37\\lib\\http\\client.py\", line 1016, in _send_output\n    self.send(msg)\n  File \"c:\\users\\atpc8\\appdata\\local\\programs\\python\\python37\\lib\\http\\client.py\", line 956, in send\n    self.connect()\n  File \"c:\\users\\atpc8\\appdata\\local\\programs\\python\\python37\\lib\\site-packages\\urllib3\\connection.py\", line 184, in connect\n    conn = self._new_conn()\n  File \"c:\\users\\atpc8\\appdata\\local\\programs\\python\\python37\\lib\\site-packages\\urllib3\\connection.py\", line 169, in _new_conn\n    self, \"Failed to establish a new connection: %s\" % e\nurllib3.exceptions.NewConnectionError: <urllib3.connection.HTTPConnection object at 0x0000024D84D27F98>: Failed to establish a new connection: [Errno 11001] getaddrinfo failed\n\nDuring handling of the above exception, another exception occurred:\n\nTraceback (most recent call last):\n  File \"c:\\users\\atpc8\\appdata\\local\\programs\\python\\python37\\lib\\site-packages\\requests\\adapters.py\", line 449, in send\n    timeout=timeout\n  File \"c:\\users\\atpc8\\appdata\\local\\programs\\python\\python37\\lib\\site-packages\\urllib3\\connectionpool.py\", line 720, in urlopen\n    method, url, error=e, _pool=self, _stacktrace=sys.exc_info()[2]\n  File \"c:\\users\\atpc8\\appdata\\local\\programs\\python\\python37\\lib\\site-packages\\urllib3\\util\\retry.py\", line 436, in increment\n    raise MaxRetryError(_pool, url, error or ResponseError(cause))\nurllib3.exceptions.MaxRetryError: HTTPConnectionPool(host='api.dev.compareking.no', port=80): Max retries exceeded with url: /api/contact (Caused by NewConnectionError('<urllib3.connection.HTTPConnection object at 0x0000024D84D27F98>: Failed to establish a new connection: [Errno 11001] getaddrinfo failed'))\n\nDuring handling of the above exception, another exception occurred:\n\nTraceback (most recent call last):\n  File \"c:\\users\\atpc8\\appdata\\local\\programs\\python\\python37\\lib\\site-packages\\lemoncheesecake\\runner.py\", line 188, in run\n    self.test.callback(**test_func_params)\n  File \"C:\\Users\\atpc8\\sdlc\\lemontest\\suites\\thirdsuite.py\", line 81, in req3\n    headers=auth_headers, json=payload)\n  File \"c:\\users\\atpc8\\appdata\\local\\programs\\python\\python37\\lib\\site-packages\\requests\\api.py\", line 116, in post\n    return request('post', url, data=data, json=json, **kwargs)\n  File \"c:\\users\\atpc8\\appdata\\local\\programs\\python\\python37\\lib\\site-packages\\requests\\api.py\", line 60, in request\n    return session.request(method=method, url=url, **kwargs)\n  File \"c:\\users\\atpc8\\appdata\\local\\programs\\python\\python37\\lib\\site-packages\\requests\\sessions.py\", line 533, in request\n    resp = self.send(prep, **send_kwargs)\n  File \"c:\\users\\atpc8\\appdata\\local\\programs\\python\\python37\\lib\\site-packages\\requests\\sessions.py\", line 646, in send\n    r = adapter.send(request, **kwargs)\n  File \"c:\\users\\atpc8\\appdata\\local\\programs\\python\\python37\\lib\\site-packages\\requests\\adapters.py\", line 516, in send\n    raise ConnectionError(e, request=request)\nrequests.exceptions.ConnectionError: HTTPConnectionPool(host='api.dev.compareking.no', port=80): Max retries exceeded with url: /api/contact (Caused by NewConnectionError('<urllib3.connection.HTTPConnection object at 0x0000024D84D27F98>: Failed to establish a new connection: [Errno 11001] getaddrinfo failed'))\n", "time": "2020-05-06T08:34:39.940Z"}]}], "status": "failed", "status_details": null, "name": "req3", "description": "Submit unfinished application with incomplete required info", "tags": [], "properties": {}, "links": []}, {"start_time": "2020-05-06T08:34:39.941Z", "end_time": "2020-05-06T08:34:39.945Z", "steps": [{"description": "Submit unfinished application that already exists", "start_time": "2020-05-06T08:34:39.941Z", "end_time": "2020-05-06T08:34:39.945Z", "entries": [{"type": "log", "level": "error", "message": "Caught unexpected exception while running test: Traceback (most recent call last):\n  File \"c:\\users\\atpc8\\appdata\\local\\programs\\python\\python37\\lib\\site-packages\\urllib3\\connection.py\", line 157, in _new_conn\n    (self._dns_host, self.port), self.timeout, **extra_kw\n  File \"c:\\users\\atpc8\\appdata\\local\\programs\\python\\python37\\lib\\site-packages\\urllib3\\util\\connection.py\", line 61, in create_connection\n    for res in socket.getaddrinfo(host, port, family, socket.SOCK_STREAM):\n  File \"c:\\users\\atpc8\\appdata\\local\\programs\\python\\python37\\lib\\socket.py\", line 748, in getaddrinfo\n    for res in _socket.getaddrinfo(host, port, family, type, proto, flags):\nsocket.gaierror: [Errno 11001] getaddrinfo failed\n\nDuring handling of the above exception, another exception occurred:\n\nTraceback (most recent call last):\n  File \"c:\\users\\atpc8\\appdata\\local\\programs\\python\\python37\\lib\\site-packages\\urllib3\\connectionpool.py\", line 672, in urlopen\n    chunked=chunked,\n  File \"c:\\users\\atpc8\\appdata\\local\\programs\\python\\python37\\lib\\site-packages\\urllib3\\connectionpool.py\", line 387, in _make_request\n    conn.request(method, url, **httplib_request_kw)\n  File \"c:\\users\\atpc8\\appdata\\local\\programs\\python\\python37\\lib\\http\\client.py\", line 1229, in request\n    self._send_request(method, url, body, headers, encode_chunked)\n  File \"c:\\users\\atpc8\\appdata\\local\\programs\\python\\python37\\lib\\http\\client.py\", line 1275, in _send_request\n    self.endheaders(body, encode_chunked=encode_chunked)\n  File \"c:\\users\\atpc8\\appdata\\local\\programs\\python\\python37\\lib\\http\\client.py\", line 1224, in endheaders\n    self._send_output(message_body, encode_chunked=encode_chunked)\n  File \"c:\\users\\atpc8\\appdata\\local\\programs\\python\\python37\\lib\\http\\client.py\", line 1016, in _send_output\n    self.send(msg)\n  File \"c:\\users\\atpc8\\appdata\\local\\programs\\python\\python37\\lib\\http\\client.py\", line 956, in send\n    self.connect()\n  File \"c:\\users\\atpc8\\appdata\\local\\programs\\python\\python37\\lib\\site-packages\\urllib3\\connection.py\", line 184, in connect\n    conn = self._new_conn()\n  File \"c:\\users\\atpc8\\appdata\\local\\programs\\python\\python37\\lib\\site-packages\\urllib3\\connection.py\", line 169, in _new_conn\n    self, \"Failed to establish a new connection: %s\" % e\nurllib3.exceptions.NewConnectionError: <urllib3.connection.HTTPConnection object at 0x0000024D84D50080>: Failed to establish a new connection: [Errno 11001] getaddrinfo failed\n\nDuring handling of the above exception, another exception occurred:\n\nTraceback (most recent call last):\n  File \"c:\\users\\atpc8\\appdata\\local\\programs\\python\\python37\\lib\\site-packages\\requests\\adapters.py\", line 449, in send\n    timeout=timeout\n  File \"c:\\users\\atpc8\\appdata\\local\\programs\\python\\python37\\lib\\site-packages\\urllib3\\connectionpool.py\", line 720, in urlopen\n    method, url, error=e, _pool=self, _stacktrace=sys.exc_info()[2]\n  File \"c:\\users\\atpc8\\appdata\\local\\programs\\python\\python37\\lib\\site-packages\\urllib3\\util\\retry.py\", line 436, in increment\n    raise MaxRetryError(_pool, url, error or ResponseError(cause))\nurllib3.exceptions.MaxRetryError: HTTPConnectionPool(host='api.dev.compareking.no', port=80): Max retries exceeded with url: /api/contact (Caused by NewConnectionError('<urllib3.connection.HTTPConnection object at 0x0000024D84D50080>: Failed to establish a new connection: [Errno 11001] getaddrinfo failed'))\n\nDuring handling of the above exception, another exception occurred:\n\nTraceback (most recent call last):\n  File \"c:\\users\\atpc8\\appdata\\local\\programs\\python\\python37\\lib\\site-packages\\lemoncheesecake\\runner.py\", line 188, in run\n    self.test.callback(**test_func_params)\n  File \"C:\\Users\\atpc8\\sdlc\\lemontest\\suites\\thirdsuite.py\", line 97, in req4\n    headers=auth_headers, json=payload)\n  File \"c:\\users\\atpc8\\appdata\\local\\programs\\python\\python37\\lib\\site-packages\\requests\\api.py\", line 116, in post\n    return request('post', url, data=data, json=json, **kwargs)\n  File \"c:\\users\\atpc8\\appdata\\local\\programs\\python\\python37\\lib\\site-packages\\requests\\api.py\", line 60, in request\n    return session.request(method=method, url=url, **kwargs)\n  File \"c:\\users\\atpc8\\appdata\\local\\programs\\python\\python37\\lib\\site-packages\\requests\\sessions.py\", line 533, in request\n    resp = self.send(prep, **send_kwargs)\n  File \"c:\\users\\atpc8\\appdata\\local\\programs\\python\\python37\\lib\\site-packages\\requests\\sessions.py\", line 646, in send\n    r = adapter.send(request, **kwargs)\n  File \"c:\\users\\atpc8\\appdata\\local\\programs\\python\\python37\\lib\\site-packages\\requests\\adapters.py\", line 516, in send\n    raise ConnectionError(e, request=request)\nrequests.exceptions.ConnectionError: HTTPConnectionPool(host='api.dev.compareking.no', port=80): Max retries exceeded with url: /api/contact (Caused by NewConnectionError('<urllib3.connection.HTTPConnection object at 0x0000024D84D50080>: Failed to establish a new connection: [Errno 11001] getaddrinfo failed'))\n", "time": "2020-05-06T08:34:39.945Z"}]}], "status": "failed", "status_details": null, "name": "req4", "description": "Submit unfinished application that already exists", "tags": [], "properties": {}, "links": []}], "suites": [], "name": "thirdsuite", "description": "my_suite", "tags": [], "properties": {}, "links": []}, {"start_time": "2020-05-06T08:34:39.946Z", "end_time": "2020-05-06T08:34:39.958Z", "tests": [{"start_time": "2020-05-06T08:34:39.946Z", "end_time": "2020-05-06T08:34:39.957Z", "steps": [{"description": "glc_auth_test", "start_time": "2020-05-06T08:34:39.946Z", "end_time": "2020-05-06T08:34:39.957Z", "entries": [{"type": "log", "level": "error", "message": "Caught unexpected exception while running test: Traceback (most recent call last):\n  File \"c:\\users\\atpc8\\appdata\\local\\programs\\python\\python37\\lib\\site-packages\\urllib3\\connection.py\", line 157, in _new_conn\n    (self._dns_host, self.port), self.timeout, **extra_kw\n  File \"c:\\users\\atpc8\\appdata\\local\\programs\\python\\python37\\lib\\site-packages\\urllib3\\util\\connection.py\", line 61, in create_connection\n    for res in socket.getaddrinfo(host, port, family, socket.SOCK_STREAM):\n  File \"c:\\users\\atpc8\\appdata\\local\\programs\\python\\python37\\lib\\socket.py\", line 748, in getaddrinfo\n    for res in _socket.getaddrinfo(host, port, family, type, proto, flags):\nsocket.gaierror: [Errno 11001] getaddrinfo failed\n\nDuring handling of the above exception, another exception occurred:\n\nTraceback (most recent call last):\n  File \"c:\\users\\atpc8\\appdata\\local\\programs\\python\\python37\\lib\\site-packages\\urllib3\\connectionpool.py\", line 672, in urlopen\n    chunked=chunked,\n  File \"c:\\users\\atpc8\\appdata\\local\\programs\\python\\python37\\lib\\site-packages\\urllib3\\connectionpool.py\", line 376, in _make_request\n    self._validate_conn(conn)\n  File \"c:\\users\\atpc8\\appdata\\local\\programs\\python\\python37\\lib\\site-packages\\urllib3\\connectionpool.py\", line 994, in _validate_conn\n    conn.connect()\n  File \"c:\\users\\atpc8\\appdata\\local\\programs\\python\\python37\\lib\\site-packages\\urllib3\\connection.py\", line 334, in connect\n    conn = self._new_conn()\n  File \"c:\\users\\atpc8\\appdata\\local\\programs\\python\\python37\\lib\\site-packages\\urllib3\\connection.py\", line 169, in _new_conn\n    self, \"Failed to establish a new connection: %s\" % e\nurllib3.exceptions.NewConnectionError: <urllib3.connection.VerifiedHTTPSConnection object at 0x0000024D84D51048>: Failed to establish a new connection: [Errno 11001] getaddrinfo failed\n\nDuring handling of the above exception, another exception occurred:\n\nTraceback (most recent call last):\n  File \"c:\\users\\atpc8\\appdata\\local\\programs\\python\\python37\\lib\\site-packages\\requests\\adapters.py\", line 449, in send\n    timeout=timeout\n  File \"c:\\users\\atpc8\\appdata\\local\\programs\\python\\python37\\lib\\site-packages\\urllib3\\connectionpool.py\", line 720, in urlopen\n    method, url, error=e, _pool=self, _stacktrace=sys.exc_info()[2]\n  File \"c:\\users\\atpc8\\appdata\\local\\programs\\python\\python37\\lib\\site-packages\\urllib3\\util\\retry.py\", line 436, in increment\n    raise MaxRetryError(_pool, url, error or ResponseError(cause))\nurllib3.exceptions.MaxRetryError: HTTPSConnectionPool(host='ctest-main.irisplus.tui.de', port=443): Max retries exceeded with url: /ipl360/api (Caused by NewConnectionError('<urllib3.connection.VerifiedHTTPSConnection object at 0x0000024D84D51048>: Failed to establish a new connection: [Errno 11001] getaddrinfo failed'))\n\nDuring handling of the above exception, another exception occurred:\n\nTraceback (most recent call last):\n  File \"c:\\users\\atpc8\\appdata\\local\\programs\\python\\python37\\lib\\site-packages\\lemoncheesecake\\runner.py\", line 188, in run\n    self.test.callback(**test_func_params)\n  File \"C:\\Users\\atpc8\\sdlc\\lemontest\\suites\\tuisuite.py\", line 14, in glc_auth_test\n    r = requests.get(glc_url, headers=glc_auth)\n  File \"c:\\users\\atpc8\\appdata\\local\\programs\\python\\python37\\lib\\site-packages\\requests\\api.py\", line 75, in get\n    return request('get', url, params=params, **kwargs)\n  File \"c:\\users\\atpc8\\appdata\\local\\programs\\python\\python37\\lib\\site-packages\\requests\\api.py\", line 60, in request\n    return session.request(method=method, url=url, **kwargs)\n  File \"c:\\users\\atpc8\\appdata\\local\\programs\\python\\python37\\lib\\site-packages\\requests\\sessions.py\", line 533, in request\n    resp = self.send(prep, **send_kwargs)\n  File \"c:\\users\\atpc8\\appdata\\local\\programs\\python\\python37\\lib\\site-packages\\requests\\sessions.py\", line 646, in send\n    r = adapter.send(request, **kwargs)\n  File \"c:\\users\\atpc8\\appdata\\local\\programs\\python\\python37\\lib\\site-packages\\requests\\adapters.py\", line 516, in send\n    raise ConnectionError(e, request=request)\nrequests.exceptions.ConnectionError: HTTPSConnectionPool(host='ctest-main.irisplus.tui.de', port=443): Max retries exceeded with url: /ipl360/api (Caused by NewConnectionError('<urllib3.connection.VerifiedHTTPSConnection object at 0x0000024D84D51048>: Failed to establish a new connection: [Errno 11001] getaddrinfo failed'))\n", "time": "2020-05-06T08:34:39.957Z"}]}], "status": "failed", "status_details": null, "name": "glc_auth_test", "description": "glc_auth_test", "tags": ["glc"], "properties": {}, "links": []}], "suites": [], "name": "tuisuite", "description": "GLC test", "tags": [], "properties": {}, "links": []}]}